Qubicle Exchange Format
Version 0.2
www.minddesk.com
16 16 16
2
0.721569 0.972549 0.094118
1.000000 1.000000 1.000000
0 0 6 1 94
0 0 7 1 30
0 0 8 1 30
0 0 9 1 62
4 0 6 1 94
4 0 7 1 30
4 0 8 1 30
4 0 9 1 62
4 3 7 1 92
4 3 8 1 60
5 2 6 1 92
5 2 7 1 20
5 2 8 1 20
5 2 9 1 60
5 3 7 0 64
5 3 8 0 32
5 4 7 0 78
5 4 8 0 46
6 0 5 0 86
6 0 6 0 20
6 0 7 0 20
6 0 8 0 20
6 0 9 0 20
6 0 10 0 54
6 1 5 0 78
6 1 6 0 6
6 1 7 0 4
6 1 8 0 4
6 1 9 0 6
6 1 10 0 46
6 2 6 0 74
6 2 7 0 2
6 2 8 0 2
6 2 9 0 42
6 3 7 0 74
6 3 8 0 42
7 0 6 0 90
7 0 7 0 18
7 0 8 0 18
7 0 9 0 58
7 1 7 0 74
7 1 8 0 42
