Qubicle Exchange Format
Version 0.2
www.minddesk.com
16 16 16
3
0.000000 0.407843 0.000000
0.721569 0.972549 0.094118
1.000000 1.000000 1.000000
0 6 5 1 84
0 6 6 1 20
0 6 7 1 20
0 6 8 1 20
0 6 9 1 20
0 6 10 1 52
0 7 5 1 76
0 7 6 1 4
0 7 7 1 4
0 7 8 1 4
0 7 9 1 4
0 7 10 1 44
0 8 6 1 76
0 8 7 1 12
0 8 8 1 12
0 8 9 1 44
0 15 7 2 94
0 15 8 2 62
1 4 5 2 118
1 4 7 2 86
1 4 8 2 54
1 4 10 2 118
1 5 4 2 86
1 5 5 2 38
1 5 7 2 70
1 5 8 2 38
1 5 10 2 70
1 5 11 2 54
1 6 4 1 68
1 6 5 1 0
1 6 6 1 16
1 6 7 1 0
1 6 8 1 0
1 6 9 1 16
1 6 10 1 0
1 6 11 1 36
1 7 4 1 68
1 7 5 1 0
1 7 6 1 0
1 7 7 1 0
1 7 8 1 0
1 7 9 1 0
1 7 10 1 0
1 7 11 1 36
1 8 4 0 76
1 8 5 0 12
1 8 6 0 0
1 8 7 0 0
1 8 8 0 0
1 8 9 0 0
1 8 10 0 12
1 8 11 0 44
1 9 6 1 76
1 9 7 1 12
1 9 8 1 12
1 9 9 1 44
1 14 7 2 94
1 14 8 2 62
2 6 4 1 82
2 6 5 1 18
2 6 6 1 18
2 6 7 1 18
2 6 8 1 18
2 6 9 1 18
2 6 10 1 18
2 6 11 1 50
2 7 4 1 66
2 7 5 1 2
2 7 6 1 2
2 7 7 1 2
2 7 8 1 2
2 7 9 1 2
2 7 10 1 2
2 7 11 1 34
2 8 4 1 72
2 8 5 1 0
2 8 6 1 0
2 8 7 1 0
2 8 8 1 0
2 8 9 1 0
2 8 10 1 0
2 8 11 1 40
2 9 5 1 76
2 9 6 1 8
2 9 7 1 8
2 9 8 1 8
2 9 9 1 8
2 9 10 1 44
2 12 7 2 84
2 12 8 2 52
2 13 7 2 76
2 13 8 2 44
3 8 4 1 80
3 8 5 1 18
3 8 6 1 16
3 8 7 1 18
3 8 8 1 18
3 8 9 1 16
3 8 10 1 18
3 8 11 1 48
3 9 4 1 76
3 9 5 1 0
3 9 6 1 0
3 9 7 1 0
3 9 8 1 0
3 9 9 1 0
3 9 10 1 0
3 9 11 1 44
3 10 5 1 76
3 10 6 1 12
3 10 7 2 4
3 10 8 2 4
3 10 9 1 12
3 10 10 1 44
3 11 7 2 68
3 11 8 2 36
3 12 7 2 64
3 12 8 2 32
3 13 7 2 74
3 13 8 2 42
4 4 5 1 86
4 4 6 1 30
4 4 7 1 22
4 4 8 1 22
4 4 9 1 30
4 4 10 1 54
4 5 5 2 108
4 5 7 2 76
4 5 8 2 44
4 5 10 2 108
4 8 4 2 114
4 8 6 2 114
4 8 9 2 114
4 8 11 2 114
4 9 4 1 66
4 9 5 1 18
4 9 6 1 2
4 9 7 1 18
4 9 8 1 18
4 9 9 1 2
4 9 10 1 18
4 9 11 1 34
4 10 4 1 76
4 10 5 1 0
4 10 6 1 0
4 10 7 1 0
4 10 8 1 0
4 10 9 1 0
4 10 10 1 0
4 10 11 1 44
4 11 5 1 76
4 11 6 1 12
4 11 7 2 0
4 11 8 1 0
4 11 9 1 12
4 11 10 1 44
4 12 7 2 72
4 12 8 2 40
5 5 5 1 82
5 5 6 1 22
5 5 7 1 18
5 5 8 1 18
5 5 9 1 22
5 5 10 1 50
5 6 5 1 76
5 6 6 1 12
5 6 7 1 12
5 6 8 1 12
5 6 9 1 12
5 6 10 1 44
5 10 4 1 80
5 10 5 1 16
5 10 6 1 16
5 10 7 1 16
5 10 8 1 16
5 10 9 1 16
5 10 10 1 16
5 10 11 1 48
5 11 4 0 76
5 11 5 0 0
5 11 6 0 0
5 11 7 0 0
5 11 8 0 0
5 11 9 0 0
5 11 10 0 0
5 11 11 0 44
5 12 5 1 76
5 12 6 1 12
5 12 7 1 0
5 12 8 1 0
5 12 9 1 12
5 12 10 1 44
5 13 7 1 76
5 13 8 1 44
6 0 7 2 92
6 0 8 2 60
6 6 5 1 80
6 6 6 1 16
6 6 7 1 16
6 6 8 1 16
6 6 9 1 16
6 6 10 1 48
6 7 4 1 84
6 7 5 1 4
6 7 6 1 4
6 7 7 1 4
6 7 8 1 4
6 7 9 1 4
6 7 10 1 4
6 7 11 1 52
6 8 4 1 76
6 8 5 1 12
6 8 6 1 12
6 8 7 1 12
6 8 8 1 12
6 8 9 1 12
6 8 10 1 12
6 8 11 1 44
6 10 4 1 80
6 10 5 1 16
6 10 6 1 16
6 10 7 1 16
6 10 8 1 16
6 10 9 1 16
6 10 10 1 16
6 10 11 1 48
6 11 4 2 64
6 11 5 2 0
6 11 6 2 0
6 11 7 2 0
6 11 8 2 0
6 11 9 2 0
6 11 10 2 0
6 11 11 2 32
6 12 4 2 76
6 12 5 2 8
6 12 6 2 0
6 12 7 2 0
6 12 8 2 0
6 12 9 2 0
6 12 10 2 8
6 12 11 2 44
6 13 6 1 76
6 13 7 1 8
6 13 8 1 8
6 13 9 1 44
7 0 6 2 92
7 0 7 2 16
7 0 8 2 16
7 0 9 2 60
7 1 7 0 76
7 1 8 0 44
7 6 4 1 84
7 6 5 1 16
7 6 6 1 16
7 6 7 1 16
7 6 8 1 16
7 6 9 1 16
7 6 10 1 16
7 6 11 1 52
7 7 4 1 64
7 7 5 1 0
7 7 6 1 0
7 7 7 1 0
7 7 8 1 0
7 7 9 1 0
7 7 10 1 0
7 7 11 1 32
7 8 4 1 64
7 8 5 1 0
7 8 6 1 0
7 8 7 1 0
7 8 8 1 0
7 8 9 1 0
7 8 10 1 0
7 8 11 1 32
7 9 4 1 68
7 9 5 1 4
7 9 6 1 4
7 9 7 1 4
7 9 8 1 4
7 9 9 1 4
7 9 10 1 4
7 9 11 1 36
7 10 4 1 64
7 10 5 1 0
7 10 6 1 0
7 10 7 1 0
7 10 8 1 0
7 10 9 1 0
7 10 10 1 0
7 10 11 1 32
7 11 4 1 64
7 11 5 1 0
7 11 6 1 0
7 11 7 1 0
7 11 8 1 0
7 11 9 1 0
7 11 10 1 0
7 11 11 1 32
7 12 4 2 72
7 12 5 2 0
7 12 6 2 0
7 12 7 2 0
7 12 8 2 0
7 12 9 2 0
7 12 10 2 0
7 12 11 2 40
7 13 5 1 76
7 13 6 1 8
7 13 7 1 8
7 13 8 1 8
7 13 9 1 8
7 13 10 1 44
8 0 6 1 80
8 0 7 1 16
8 0 8 1 16
8 0 9 1 48
8 1 6 0 68
8 1 7 0 0
8 1 8 0 0
8 1 9 0 36
8 2 6 2 68
8 2 7 2 4
8 2 8 2 4
8 2 9 2 36
8 3 6 0 68
8 3 7 0 4
8 3 8 0 4
8 3 9 0 36
8 4 6 2 68
8 4 7 2 4
8 4 8 2 4
8 4 9 2 36
8 5 6 0 68
8 5 7 0 4
8 5 8 0 4
8 5 9 0 36
8 6 4 2 80
8 6 5 2 16
8 6 6 2 0
8 6 7 2 0
8 6 8 2 0
8 6 9 2 0
8 6 10 2 16
8 6 11 2 48
8 7 4 0 64
8 7 5 0 0
8 7 6 0 0
8 7 7 0 0
8 7 8 0 0
8 7 9 0 0
8 7 10 0 0
8 7 11 0 32
8 8 4 1 64
8 8 5 1 0
8 8 6 1 0
8 8 7 1 0
8 8 8 1 0
8 8 9 1 0
8 8 10 1 0
8 8 11 1 32
8 9 4 1 64
8 9 5 1 0
8 9 6 1 0
8 9 7 1 0
8 9 8 1 0
8 9 9 1 0
8 9 10 1 0
8 9 11 1 32
8 10 4 1 64
8 10 5 1 0
8 10 6 1 0
8 10 7 1 0
8 10 8 1 0
8 10 9 1 0
8 10 10 1 0
8 10 11 1 32
8 11 4 1 64
8 11 5 1 0
8 11 6 1 0
8 11 7 1 0
8 11 8 1 0
8 11 9 1 0
8 11 10 1 0
8 11 11 1 32
8 12 4 1 72
8 12 5 1 0
8 12 6 1 0
8 12 7 1 0
8 12 8 1 0
8 12 9 1 0
8 12 10 1 0
8 12 11 1 40
8 13 5 1 72
8 13 6 1 8
8 13 7 1 8
8 13 8 1 8
8 13 9 1 8
8 13 10 1 40
9 0 5 1 84
9 0 6 1 16
9 0 7 1 16
9 0 8 1 16
9 0 9 1 16
9 0 10 1 52
9 1 5 1 68
9 1 6 1 0
9 1 7 1 0
9 1 8 1 0
9 1 9 1 0
9 1 10 1 36
9 2 5 1 68
9 2 6 1 0
9 2 7 1 0
9 2 8 1 0
9 2 9 1 0
9 2 10 1 36
9 3 5 0 68
9 3 6 0 0
9 3 7 0 0
9 3 8 0 0
9 3 9 0 0
9 3 10 0 36
9 4 5 2 68
9 4 6 2 0
9 4 7 2 0
9 4 8 2 0
9 4 9 2 0
9 4 10 2 36
9 5 5 0 68
9 5 6 0 0
9 5 7 0 0
9 5 8 0 0
9 5 9 0 0
9 5 10 0 36
9 6 4 1 80
9 6 5 1 0
9 6 6 1 0
9 6 7 1 0
9 6 8 1 0
9 6 9 1 0
9 6 10 1 0
9 6 11 1 48
9 7 4 1 64
9 7 5 1 0
9 7 6 1 0
9 7 7 1 0
9 7 8 1 0
9 7 9 1 0
9 7 10 1 0
9 7 11 1 32
9 8 4 1 64
9 8 5 1 0
9 8 6 1 0
9 8 7 1 0
9 8 8 1 0
9 8 9 1 0
9 8 10 1 0
9 8 11 1 32
9 9 4 1 64
9 9 5 1 0
9 9 6 1 0
9 9 7 1 0
9 9 8 1 0
9 9 9 1 0
9 9 10 1 0
9 9 11 1 32
9 10 4 1 64
9 10 5 1 0
9 10 6 1 0
9 10 7 1 0
9 10 8 1 0
9 10 9 1 0
9 10 10 1 0
9 10 11 1 32
9 11 4 1 64
9 11 5 1 0
9 11 6 1 0
9 11 7 1 0
9 11 8 1 0
9 11 9 1 0
9 11 10 1 0
9 11 11 1 32
9 12 4 1 64
9 12 5 1 0
9 12 6 1 0
9 12 7 1 0
9 12 8 1 0
9 12 9 1 0
9 12 10 1 0
9 12 11 1 32
9 13 4 1 76
9 13 5 1 8
9 13 6 1 0
9 13 7 1 0
9 13 8 1 0
9 13 9 1 0
9 13 10 1 0
9 13 11 1 44
9 14 6 1 76
9 14 7 1 12
9 14 8 1 12
9 14 9 1 12
9 14 10 1 44
10 0 4 1 86
10 0 5 1 16
10 0 6 1 16
10 0 7 1 16
10 0 8 1 16
10 0 9 1 16
10 0 10 1 16
10 0 11 1 54
10 1 4 1 70
10 1 5 1 0
10 1 6 1 0
10 1 7 1 0
10 1 8 1 0
10 1 9 1 0
10 1 10 1 0
10 1 11 1 38
10 2 4 1 70
10 2 5 1 0
10 2 6 1 0
10 2 7 1 0
10 2 8 1 0
10 2 9 1 0
10 2 10 1 0
10 2 11 1 38
10 3 4 1 70
10 3 5 1 0
10 3 6 1 0
10 3 7 1 0
10 3 8 1 0
10 3 9 1 0
10 3 10 1 0
10 3 11 1 38
10 4 4 1 70
10 4 5 1 0
10 4 6 1 0
10 4 7 1 0
10 4 8 1 0
10 4 9 1 0
10 4 10 1 0
10 4 11 1 38
10 5 4 1 70
10 5 5 1 0
10 5 6 1 0
10 5 7 1 0
10 5 8 1 0
10 5 9 1 0
10 5 10 1 0
10 5 11 1 38
10 6 4 1 64
10 6 5 1 0
10 6 6 1 0
10 6 7 1 0
10 6 8 1 0
10 6 9 1 0
10 6 10 1 0
10 6 11 1 32
10 7 4 1 64
10 7 5 1 0
10 7 6 1 0
10 7 7 1 0
10 7 8 1 0
10 7 9 1 0
10 7 10 1 0
10 7 11 1 32
10 8 4 1 64
10 8 5 1 0
10 8 6 1 0
10 8 7 1 0
10 8 8 1 0
10 8 9 1 0
10 8 10 1 0
10 8 11 1 32
10 9 4 1 64
10 9 5 1 0
10 9 6 1 0
10 9 7 1 0
10 9 8 1 0
10 9 9 1 0
10 9 10 1 0
10 9 11 1 32
10 10 4 1 64
10 10 5 1 0
10 10 6 1 0
10 10 7 1 0
10 10 8 1 0
10 10 9 1 0
10 10 10 1 0
10 10 11 1 32
10 11 4 1 66
10 11 5 1 0
10 11 6 1 0
10 11 7 1 0
10 11 8 1 0
10 11 9 1 0
10 11 10 1 0
10 11 11 1 34
10 12 4 0 66
10 12 5 0 2
10 12 6 0 0
10 12 7 0 0
10 12 8 0 0
10 12 9 0 0
10 12 10 0 2
10 12 11 0 34
10 13 4 1 66
10 13 5 1 2
10 13 6 1 2
10 13 7 1 2
10 13 8 1 2
10 13 9 1 2
10 13 10 1 2
10 13 11 1 34
10 14 4 1 76
10 14 5 1 12
10 14 6 1 8
10 14 7 1 0
10 14 8 1 0
10 14 9 1 0
10 14 10 1 8
10 14 11 1 44
10 15 7 1 76
10 15 8 1 14
10 15 9 1 44
11 0 5 1 82
11 0 6 1 16
11 0 7 1 16
11 0 8 1 16
11 0 9 1 16
11 0 10 1 50
11 1 5 1 66
11 1 6 1 2
11 1 7 1 0
11 1 8 1 0
11 1 9 1 2
11 1 10 1 34
11 2 5 1 66
11 2 6 1 2
11 2 7 1 2
11 2 8 1 2
11 2 9 1 2
11 2 10 1 34
11 3 5 1 66
11 3 6 1 0
11 3 7 1 0
11 3 8 1 0
11 3 9 1 0
11 3 10 1 34
11 4 5 1 66
11 4 6 1 0
11 4 7 1 0
11 4 8 1 0
11 4 9 1 0
11 4 10 1 34
11 5 5 1 66
11 5 6 1 0
11 5 7 1 0
11 5 8 1 0
11 5 9 1 0
11 5 10 1 34
11 6 4 1 82
11 6 5 1 0
11 6 6 1 0
11 6 7 1 0
11 6 8 1 0
11 6 9 1 0
11 6 10 1 0
11 6 11 1 50
11 7 4 1 64
11 7 5 1 0
11 7 6 1 0
11 7 7 1 0
11 7 8 1 0
11 7 9 1 0
11 7 10 1 0
11 7 11 1 32
11 8 4 1 64
11 8 5 1 0
11 8 6 1 0
11 8 7 1 0
11 8 8 1 0
11 8 9 1 0
11 8 10 1 0
11 8 11 1 32
11 9 4 1 64
11 9 5 1 0
11 9 6 1 0
11 9 7 1 0
11 9 8 1 0
11 9 9 1 0
11 9 10 1 0
11 9 11 1 32
11 10 4 1 74
11 10 5 1 0
11 10 6 1 0
11 10 7 1 0
11 10 8 1 0
11 10 9 1 0
11 10 10 1 0
11 10 11 1 42
11 11 5 1 74
11 11 6 1 0
11 11 7 1 0
11 11 8 1 0
11 11 9 1 0
11 11 10 1 42
11 12 6 1 74
11 12 7 1 8
11 12 8 1 8
11 12 9 1 42
11 14 4 1 90
11 14 5 1 16
11 14 6 1 16
11 14 7 1 16
11 14 8 1 26
11 14 9 1 16
11 14 10 1 16
11 14 11 1 50
11 15 5 1 76
11 15 6 1 12
11 15 7 1 42
11 15 9 1 74
11 15 10 1 12
11 15 11 1 44
12 0 6 2 90
12 0 7 2 16
12 0 8 2 16
12 0 9 2 58
12 1 7 2 74
12 1 8 2 42
12 3 6 1 82
12 3 7 1 16
12 3 8 1 16
12 3 9 1 50
12 4 6 1 64
12 4 7 1 0
12 4 8 1 0
12 4 9 1 32
12 5 6 1 66
12 5 7 1 0
12 5 8 1 0
12 5 9 1 34
12 6 5 1 82
12 6 6 1 0
12 6 7 1 0
12 6 8 1 0
12 6 9 1 0
12 6 10 1 50
12 7 4 1 82
12 7 5 1 0
12 7 6 1 0
12 7 7 1 0
12 7 8 1 0
12 7 9 1 0
12 7 10 1 0
12 7 11 1 50
12 8 4 1 66
12 8 5 1 0
12 8 6 1 0
12 8 7 1 0
12 8 8 1 0
12 8 9 1 0
12 8 10 1 0
12 8 11 1 34
12 9 4 1 74
12 9 5 1 0
12 9 6 1 0
12 9 7 1 0
12 9 8 1 0
12 9 9 1 0
12 9 10 1 0
12 9 11 1 42
12 10 5 1 74
12 10 6 1 0
12 10 7 1 0
12 10 8 1 0
12 10 9 1 0
12 10 10 1 42
12 11 6 1 74
12 11 7 1 0
12 11 8 1 0
12 11 9 1 42
12 12 7 2 72
12 12 8 2 40
12 14 5 1 82
12 14 6 1 18
12 14 7 1 58
12 14 9 1 90
12 14 10 1 50
12 15 4 1 92
12 15 5 1 8
12 15 6 1 42
12 15 10 1 74
12 15 11 1 24
12 15 12 1 60
13 0 7 2 90
13 0 8 2 58
13 3 7 2 82
13 3 8 2 50
13 4 6 2 90
13 4 7 2 0
13 4 8 2 0
13 4 9 2 58
13 5 7 2 66
13 5 8 2 34
13 6 6 1 82
13 6 7 1 2
13 6 8 1 2
13 6 9 1 50
13 7 5 1 82
13 7 6 1 2
13 7 7 1 0
13 7 8 1 0
13 7 9 1 2
13 7 10 1 50
13 8 5 1 66
13 8 6 1 0
13 8 7 1 0
13 8 8 1 0
13 8 9 1 0
13 8 10 1 34
13 9 5 1 74
13 9 6 1 2
13 9 7 1 0
13 9 8 1 0
13 9 9 1 2
13 9 10 1 42
13 10 6 1 74
13 10 7 1 2
13 10 8 1 2
13 10 9 1 42
13 11 7 2 66
13 11 8 2 34
13 12 7 2 74
13 12 8 2 42
13 15 3 1 94
13 15 4 1 26
13 15 5 1 58
13 15 11 1 90
13 15 12 1 26
13 15 13 1 62
14 4 7 2 90
14 4 8 2 58
14 7 7 2 82
14 7 8 2 50
14 8 6 2 90
14 8 7 2 0
14 8 8 2 0
14 8 9 2 58
14 9 7 2 74
14 9 8 2 42
15 8 7 2 90
15 8 8 2 58
