Qubicle Exchange Format
Version 0.2
www.minddesk.com
16 16 16
3
0.000000 0.407843 0.000000
0.721569 0.972549 0.094118
1.000000 1.000000 1.000000
2 4 11 1 124
2 8 5 0 92
2 8 6 0 20
2 8 7 0 20
2 8 8 0 20
2 8 9 0 20
2 8 10 0 60
2 9 6 2 76
2 9 7 2 4
2 9 8 2 4
2 9 9 2 44
2 10 7 2 76
2 10 8 2 44
3 2 4 1 116
3 2 11 0 116
3 3 4 1 108
3 3 11 0 100
3 4 10 1 84
3 4 11 1 0
3 4 12 1 60
3 5 10 1 76
3 5 11 1 44
3 6 6 2 84
3 6 7 2 20
3 6 8 2 20
3 6 9 2 52
3 7 5 2 84
3 7 6 2 4
3 7 7 2 4
3 7 8 2 4
3 7 9 2 4
3 7 10 2 52
3 8 4 0 92
3 8 5 0 0
3 8 6 0 0
3 8 7 0 0
3 8 8 0 0
3 8 9 0 0
3 8 10 0 0
3 8 11 0 60
3 9 5 2 76
3 9 6 2 0
3 9 7 2 0
3 9 8 2 0
3 9 9 2 0
3 9 10 2 44
3 10 6 2 68
3 10 7 2 0
3 10 8 2 0
3 10 9 2 36
3 11 6 0 76
3 11 7 0 4
3 11 8 0 4
3 11 9 0 44
3 12 7 2 76
3 12 8 2 44
4 0 4 0 116
4 1 4 0 100
4 2 3 1 84
4 2 4 1 0
4 2 5 1 52
4 2 10 0 84
4 2 11 0 16
4 2 12 0 52
4 3 3 1 76
4 3 4 1 0
4 3 5 1 36
4 3 10 0 68
4 3 11 0 0
4 3 12 0 36
4 4 4 1 68
4 4 5 1 36
4 4 10 1 64
4 4 11 1 0
4 4 12 1 32
4 5 4 1 68
4 5 5 1 4
4 5 6 1 52
4 5 9 1 84
4 5 10 1 0
4 5 11 1 0
4 5 12 1 44
4 6 4 1 68
4 6 5 1 4
4 6 6 1 0
4 6 7 1 16
4 6 8 1 16
4 6 9 1 0
4 6 10 1 4
4 6 11 1 36
4 7 4 2 68
4 7 5 2 0
4 7 6 2 0
4 7 7 2 0
4 7 8 2 0
4 7 9 2 0
4 7 10 2 0
4 7 11 2 36
4 8 3 0 92
4 8 4 0 0
4 8 5 0 0
4 8 6 0 0
4 8 7 0 0
4 8 8 0 0
4 8 9 0 0
4 8 10 0 0
4 8 11 0 0
4 8 12 0 60
4 9 4 2 76
4 9 5 2 0
4 9 6 2 0
4 9 7 2 0
4 9 8 2 0
4 9 9 2 0
4 9 10 2 0
4 9 11 2 44
4 10 5 2 68
4 10 6 2 0
4 10 7 2 0
4 10 8 2 0
4 10 9 2 0
4 10 10 2 36
4 11 5 0 76
4 11 6 0 0
4 11 7 0 0
4 11 8 0 0
4 11 9 0 0
4 11 10 0 44
4 12 6 2 76
4 12 7 2 0
4 12 8 2 0
4 12 9 2 44
4 13 7 0 76
4 13 8 0 44
5 0 3 0 84
5 0 4 0 16
5 0 5 0 54
5 1 3 0 68
5 1 4 0 0
5 1 5 0 36
5 2 3 1 64
5 2 4 1 0
5 2 5 1 32
5 2 10 0 80
5 2 11 0 16
5 2 12 0 16
5 2 13 0 52
5 3 3 1 64
5 3 4 1 0
5 3 5 1 32
5 3 10 0 64
5 3 11 0 0
5 3 12 0 0
5 3 13 0 36
5 4 3 1 68
5 4 4 1 0
5 4 5 1 0
5 4 6 1 52
5 4 9 1 84
5 4 10 1 0
5 4 11 1 0
5 4 12 1 0
5 4 13 1 36
5 5 3 1 68
5 5 4 1 0
5 5 5 1 0
5 5 6 1 0
5 5 7 1 20
5 5 8 1 20
5 5 9 1 0
5 5 10 1 0
5 5 11 1 0
5 5 12 1 0
5 5 13 1 44
5 6 3 1 68
5 6 4 1 0
5 6 5 1 0
5 6 6 1 0
5 6 7 1 0
5 6 8 1 0
5 6 9 1 0
5 6 10 1 0
5 6 11 1 0
5 6 12 1 36
5 7 3 2 68
5 7 4 2 0
5 7 5 2 0
5 7 6 2 0
5 7 7 2 0
5 7 8 2 0
5 7 9 2 0
5 7 10 2 0
5 7 11 2 0
5 7 12 2 36
5 8 3 1 64
5 8 4 1 0
5 8 5 1 0
5 8 6 1 0
5 8 7 1 0
5 8 8 1 0
5 8 9 1 0
5 8 10 1 0
5 8 11 1 0
5 8 12 1 32
5 9 3 1 76
5 9 4 1 0
5 9 5 1 0
5 9 6 1 0
5 9 7 1 0
5 9 8 1 0
5 9 9 1 0
5 9 10 1 0
5 9 11 1 0
5 9 12 1 44
5 10 4 1 68
5 10 5 1 0
5 10 6 1 0
5 10 7 1 0
5 10 8 1 0
5 10 9 1 0
5 10 10 1 0
5 10 11 1 36
5 11 4 1 76
5 11 5 1 0
5 11 6 1 0
5 11 7 1 0
5 11 8 1 0
5 11 9 1 0
5 11 10 1 0
5 11 11 1 44
5 12 5 1 76
5 12 6 1 0
5 12 7 1 0
5 12 8 1 0
5 12 9 1 0
5 12 10 1 44
5 13 6 0 76
5 13 7 0 0
5 13 8 0 0
5 13 9 0 44
5 14 7 2 76
5 14 8 2 44
6 0 2 0 84
6 0 3 0 16
6 0 4 0 48
6 1 2 0 68
6 1 3 0 0
6 1 4 0 0
6 1 5 0 48
6 2 2 1 68
6 2 3 1 0
6 2 4 1 0
6 2 5 1 32
6 2 10 0 80
6 2 11 0 16
6 2 12 0 16
6 2 13 0 48
6 3 2 1 68
6 3 3 1 0
6 3 4 1 0
6 3 5 1 32
6 3 10 0 64
6 3 11 0 0
6 3 12 0 0
6 3 13 0 32
6 4 2 1 68
6 4 3 1 0
6 4 4 1 0
6 4 5 1 0
6 4 6 1 16
6 4 7 1 20
6 4 8 1 20
6 4 9 1 16
6 4 10 1 0
6 4 11 1 0
6 4 12 1 0
6 4 13 1 32
6 5 2 1 68
6 5 3 1 0
6 5 4 1 0
6 5 5 1 0
6 5 6 1 0
6 5 7 1 0
6 5 8 1 0
6 5 9 1 0
6 5 10 1 0
6 5 11 1 0
6 5 12 1 0
6 5 13 1 32
6 6 2 1 68
6 6 3 1 0
6 6 4 1 0
6 6 5 1 0
6 6 6 1 0
6 6 7 1 0
6 6 8 1 0
6 6 9 1 0
6 6 10 1 0
6 6 11 1 0
6 6 12 1 0
6 6 13 1 36
6 7 2 1 68
6 7 3 1 0
6 7 4 1 0
6 7 5 1 0
6 7 6 1 0
6 7 7 1 0
6 7 8 1 0
6 7 9 1 0
6 7 10 1 0
6 7 11 1 0
6 7 12 1 0
6 7 13 1 36
6 8 2 1 68
6 8 3 1 0
6 8 4 1 0
6 8 5 1 0
6 8 6 1 0
6 8 7 1 0
6 8 8 1 0
6 8 9 1 0
6 8 10 1 0
6 8 11 1 0
6 8 12 1 0
6 8 13 1 36
6 9 2 1 76
6 9 3 1 0
6 9 4 1 0
6 9 5 1 0
6 9 6 1 0
6 9 7 1 0
6 9 8 1 0
6 9 9 1 0
6 9 10 1 0
6 9 11 1 0
6 9 12 1 0
6 9 13 1 44
6 10 3 1 68
6 10 4 1 0
6 10 5 1 0
6 10 6 1 0
6 10 7 1 0
6 10 8 1 0
6 10 9 1 0
6 10 10 1 0
6 10 11 1 0
6 10 12 1 36
6 11 3 1 76
6 11 4 1 0
6 11 5 1 0
6 11 6 1 0
6 11 7 1 0
6 11 8 1 0
6 11 9 1 0
6 11 10 1 0
6 11 11 1 0
6 11 12 1 44
6 12 4 1 76
6 12 5 1 0
6 12 6 1 0
6 12 7 1 0
6 12 8 1 0
6 12 9 1 0
6 12 10 1 0
6 12 11 1 44
6 13 5 1 76
6 13 6 1 0
6 13 7 1 0
6 13 8 1 0
6 13 9 1 0
6 13 10 1 44
6 14 6 1 76
6 14 7 1 0
6 14 8 1 0
6 14 9 1 44
6 15 7 0 76
6 15 8 0 44
7 0 2 0 80
7 0 3 0 16
7 0 4 0 16
7 0 5 0 52
7 1 2 0 64
7 1 3 0 0
7 1 4 0 0
7 1 5 0 32
7 2 2 1 64
7 2 3 1 0
7 2 4 1 0
7 2 5 1 32
7 2 10 0 82
7 2 11 0 18
7 2 12 0 18
7 2 13 0 50
7 3 2 1 64
7 3 3 1 0
7 3 4 1 0
7 3 5 1 32
7 3 10 0 66
7 3 11 0 0
7 3 12 0 0
7 3 13 0 34
7 4 2 1 64
7 4 3 1 0
7 4 4 1 0
7 4 5 1 0
7 4 6 1 16
7 4 7 1 16
7 4 8 1 16
7 4 9 1 16
7 4 10 0 0
7 4 11 0 0
7 4 12 0 0
7 4 13 0 32
7 5 2 1 64
7 5 3 1 0
7 5 4 1 0
7 5 5 1 0
7 5 6 1 0
7 5 7 1 0
7 5 8 1 0
7 5 9 1 0
7 5 10 1 0
7 5 11 1 0
7 5 12 1 0
7 5 13 1 32
7 6 2 1 64
7 6 3 1 0
7 6 4 1 0
7 6 5 1 0
7 6 6 1 0
7 6 7 1 0
7 6 8 1 0
7 6 9 1 0
7 6 10 1 0
7 6 11 1 0
7 6 12 1 0
7 6 13 1 32
7 7 2 1 64
7 7 3 1 0
7 7 4 1 0
7 7 5 1 0
7 7 6 1 0
7 7 7 1 0
7 7 8 1 0
7 7 9 1 0
7 7 10 1 0
7 7 11 1 0
7 7 12 1 0
7 7 13 1 32
7 8 2 1 64
7 8 3 1 0
7 8 4 1 0
7 8 5 1 0
7 8 6 1 0
7 8 7 1 0
7 8 8 1 0
7 8 9 1 0
7 8 10 1 0
7 8 11 1 0
7 8 12 1 0
7 8 13 1 32
7 9 2 1 64
7 9 3 1 0
7 9 4 1 0
7 9 5 1 0
7 9 6 1 0
7 9 7 1 0
7 9 8 1 0
7 9 9 1 0
7 9 10 1 0
7 9 11 1 0
7 9 12 1 0
7 9 13 1 32
7 10 2 1 76
7 10 3 1 0
7 10 4 1 0
7 10 5 1 0
7 10 6 1 0
7 10 7 1 0
7 10 8 1 0
7 10 9 1 0
7 10 10 1 0
7 10 11 1 0
7 10 12 1 0
7 10 13 1 44
7 11 3 1 64
7 11 4 1 0
7 11 5 1 0
7 11 6 1 0
7 11 7 1 0
7 11 8 1 0
7 11 9 1 0
7 11 10 1 0
7 11 11 1 0
7 11 12 1 32
7 12 3 1 76
7 12 4 1 0
7 12 5 1 0
7 12 6 1 0
7 12 7 1 0
7 12 8 1 0
7 12 9 1 0
7 12 10 1 0
7 12 11 1 0
7 12 12 1 44
7 13 4 1 76
7 13 5 1 0
7 13 6 1 0
7 13 7 1 0
7 13 8 1 0
7 13 9 1 0
7 13 10 1 0
7 13 11 1 44
7 14 5 1 76
7 14 6 1 0
7 14 7 1 0
7 14 8 1 0
7 14 9 1 0
7 14 10 1 44
7 15 6 1 76
7 15 7 1 8
7 15 8 1 8
7 15 9 1 44
8 0 2 0 82
8 0 3 0 18
8 0 4 0 18
8 0 5 0 50
8 1 2 0 66
8 1 3 0 0
8 1 4 0 0
8 1 5 0 32
8 2 2 0 66
8 2 3 0 0
8 2 4 0 0
8 2 5 0 32
8 3 2 1 66
8 3 3 1 0
8 3 4 1 0
8 3 5 1 32
8 3 11 0 82
8 3 12 0 50
8 4 2 1 66
8 4 3 1 0
8 4 4 1 0
8 4 5 1 0
8 4 6 1 16
8 4 7 1 16
8 4 8 1 16
8 4 9 1 16
8 4 10 1 16
8 4 11 0 0
8 4 12 0 0
8 4 13 1 48
8 5 2 1 64
8 5 3 1 0
8 5 4 1 0
8 5 5 1 0
8 5 6 1 0
8 5 7 1 0
8 5 8 1 0
8 5 9 1 0
8 5 10 1 0
8 5 11 0 0
8 5 12 0 0
8 5 13 1 32
8 6 2 1 64
8 6 3 1 0
8 6 4 1 0
8 6 5 1 0
8 6 6 1 0
8 6 7 1 0
8 6 8 1 0
8 6 9 1 0
8 6 10 1 0
8 6 11 1 0
8 6 12 1 0
8 6 13 1 32
8 7 2 1 64
8 7 3 1 0
8 7 4 1 0
8 7 5 1 0
8 7 6 1 0
8 7 7 1 0
8 7 8 1 0
8 7 9 1 0
8 7 10 1 0
8 7 11 1 0
8 7 12 1 0
8 7 13 1 32
8 8 2 1 64
8 8 3 1 0
8 8 4 1 0
8 8 5 1 0
8 8 6 1 0
8 8 7 1 0
8 8 8 1 0
8 8 9 1 0
8 8 10 1 0
8 8 11 1 0
8 8 12 1 0
8 8 13 1 32
8 9 2 1 64
8 9 3 1 0
8 9 4 1 0
8 9 5 1 0
8 9 6 1 0
8 9 7 1 0
8 9 8 1 0
8 9 9 1 0
8 9 10 1 0
8 9 11 1 0
8 9 12 1 0
8 9 13 1 32
8 10 2 1 64
8 10 3 1 0
8 10 4 1 0
8 10 5 1 0
8 10 6 1 0
8 10 7 1 0
8 10 8 1 0
8 10 9 1 0
8 10 10 1 0
8 10 11 1 0
8 10 12 1 0
8 10 13 1 32
8 11 2 1 76
8 11 3 1 0
8 11 4 1 0
8 11 5 1 0
8 11 6 1 0
8 11 7 1 0
8 11 8 1 0
8 11 9 1 0
8 11 10 1 0
8 11 11 1 0
8 11 12 1 0
8 11 13 1 44
8 12 3 1 64
8 12 4 1 0
8 12 5 1 0
8 12 6 1 0
8 12 7 1 0
8 12 8 1 0
8 12 9 1 0
8 12 10 1 0
8 12 11 1 0
8 12 12 1 32
8 13 3 1 76
8 13 4 1 0
8 13 5 1 0
8 13 6 1 0
8 13 7 1 0
8 13 8 1 0
8 13 9 1 0
8 13 10 1 0
8 13 11 1 0
8 13 12 1 44
8 14 4 1 76
8 14 5 1 0
8 14 6 1 0
8 14 7 1 0
8 14 8 1 0
8 14 9 1 0
8 14 10 1 0
8 14 11 1 44
8 15 5 1 76
8 15 6 1 8
8 15 7 1 8
8 15 8 1 8
8 15 9 1 8
8 15 10 1 44
9 1 3 0 82
9 1 4 0 18
9 1 5 0 50
9 2 3 0 66
9 2 4 0 2
9 2 5 0 34
9 3 3 0 66
9 3 4 0 2
9 3 5 0 34
9 4 3 2 66
9 4 4 2 0
9 4 5 2 0
9 4 6 2 16
9 4 7 2 16
9 4 8 2 16
9 4 9 2 16
9 4 10 2 16
9 4 11 2 16
9 4 12 2 16
9 4 13 2 50
9 5 2 1 80
9 5 3 1 0
9 5 4 1 0
9 5 5 1 0
9 5 6 1 0
9 5 7 1 0
9 5 8 1 0
9 5 9 1 0
9 5 10 1 0
9 5 11 1 0
9 5 12 1 0
9 5 13 1 32
9 6 2 1 64
9 6 3 1 0
9 6 4 1 0
9 6 5 1 0
9 6 6 1 0
9 6 7 1 0
9 6 8 1 0
9 6 9 1 0
9 6 10 1 0
9 6 11 1 0
9 6 12 1 0
9 6 13 1 32
9 7 2 1 64
9 7 3 1 0
9 7 4 1 0
9 7 5 1 0
9 7 6 1 0
9 7 7 1 0
9 7 8 1 0
9 7 9 1 0
9 7 10 1 0
9 7 11 1 0
9 7 12 1 0
9 7 13 1 32
9 8 2 1 64
9 8 3 1 0
9 8 4 1 0
9 8 5 1 0
9 8 6 1 0
9 8 7 1 0
9 8 8 1 0
9 8 9 1 0
9 8 10 1 0
9 8 11 1 0
9 8 12 1 0
9 8 13 1 32
9 9 2 1 64
9 9 3 1 0
9 9 4 1 0
9 9 5 1 0
9 9 6 1 0
9 9 7 1 0
9 9 8 1 0
9 9 9 1 0
9 9 10 1 0
9 9 11 1 0
9 9 12 1 0
9 9 13 1 32
9 10 2 1 64
9 10 3 1 0
9 10 4 1 0
9 10 5 1 0
9 10 6 1 0
9 10 7 1 0
9 10 8 1 0
9 10 9 1 0
9 10 10 1 0
9 10 11 1 0
9 10 12 1 0
9 10 13 1 32
9 11 2 1 72
9 11 3 1 0
9 11 4 1 0
9 11 5 1 0
9 11 6 1 0
9 11 7 1 0
9 11 8 1 0
9 11 9 1 0
9 11 10 1 0
9 11 11 1 0
9 11 12 1 0
9 11 13 1 40
9 12 3 1 64
9 12 4 1 0
9 12 5 1 0
9 12 6 1 0
9 12 7 1 0
9 12 8 1 0
9 12 9 1 0
9 12 10 1 0
9 12 11 1 0
9 12 12 1 32
9 13 3 1 72
9 13 4 1 0
9 13 5 1 0
9 13 6 1 0
9 13 7 1 0
9 13 8 1 0
9 13 9 1 0
9 13 10 1 0
9 13 11 1 0
9 13 12 1 40
9 14 4 1 64
9 14 5 1 0
9 14 6 1 0
9 14 7 1 0
9 14 8 1 0
9 14 9 1 0
9 14 10 1 0
9 14 11 1 32
9 15 4 1 76
9 15 5 1 8
9 15 6 1 8
9 15 7 1 8
9 15 8 1 8
9 15 9 1 8
9 15 10 1 8
9 15 11 1 44
10 4 4 2 82
10 4 5 2 16
10 4 6 2 16
10 4 7 2 16
10 4 8 2 16
10 4 9 2 16
10 4 10 2 16
10 4 11 2 16
10 4 12 2 50
10 5 2 1 82
10 5 3 1 16
10 5 4 1 0
10 5 5 1 0
10 5 6 1 0
10 5 7 1 0
10 5 8 1 0
10 5 9 1 0
10 5 10 1 0
10 5 11 1 0
10 5 12 1 0
10 5 13 1 50
10 6 2 2 64
10 6 3 2 0
10 6 4 2 0
10 6 5 2 0
10 6 6 2 0
10 6 7 2 0
10 6 8 2 0
10 6 9 2 0
10 6 10 2 0
10 6 11 2 0
10 6 12 2 0
10 6 13 2 32
10 7 2 1 64
10 7 3 1 0
10 7 4 1 0
10 7 5 1 0
10 7 6 1 0
10 7 7 1 0
10 7 8 1 0
10 7 9 1 0
10 7 10 1 0
10 7 11 1 0
10 7 12 1 0
10 7 13 1 32
10 8 2 1 64
10 8 3 1 0
10 8 4 1 0
10 8 5 1 0
10 8 6 1 0
10 8 7 1 0
10 8 8 1 0
10 8 9 1 0
10 8 10 1 0
10 8 11 1 0
10 8 12 1 0
10 8 13 1 32
10 9 2 1 64
10 9 3 1 0
10 9 4 1 0
10 9 5 1 0
10 9 6 1 0
10 9 7 1 0
10 9 8 1 0
10 9 9 1 0
10 9 10 1 0
10 9 11 1 0
10 9 12 1 0
10 9 13 1 32
10 10 2 1 64
10 10 3 1 0
10 10 4 1 0
10 10 5 1 0
10 10 6 1 0
10 10 7 1 0
10 10 8 1 0
10 10 9 1 0
10 10 10 1 0
10 10 11 1 0
10 10 12 1 0
10 10 13 1 32
10 11 2 1 72
10 11 3 1 0
10 11 4 1 0
10 11 5 1 0
10 11 6 1 0
10 11 7 1 0
10 11 8 1 0
10 11 9 1 0
10 11 10 1 0
10 11 11 1 0
10 11 12 1 0
10 11 13 1 40
10 12 3 1 64
10 12 4 1 0
10 12 5 1 0
10 12 6 1 0
10 12 7 1 0
10 12 8 1 0
10 12 9 1 0
10 12 10 1 0
10 12 11 1 0
10 12 12 1 32
10 13 3 1 72
10 13 4 1 0
10 13 5 1 0
10 13 6 1 0
10 13 7 1 0
10 13 8 1 0
10 13 9 1 0
10 13 10 1 0
10 13 11 1 0
10 13 12 1 40
10 14 4 1 64
10 14 5 1 0
10 14 6 1 0
10 14 7 1 0
10 14 8 1 0
10 14 9 1 0
10 14 10 1 0
10 14 11 1 32
10 15 4 1 72
10 15 5 1 8
10 15 6 1 8
10 15 7 1 8
10 15 8 1 8
10 15 9 1 8
10 15 10 1 8
10 15 11 1 40
11 4 5 2 80
11 4 6 2 16
11 4 7 2 16
11 4 8 2 16
11 4 9 2 16
11 4 10 2 16
11 4 11 2 50
11 5 3 2 82
11 5 4 2 16
11 5 5 2 0
11 5 6 2 0
11 5 7 2 0
11 5 8 2 0
11 5 9 2 0
11 5 10 2 0
11 5 11 2 0
11 5 12 2 50
11 6 2 1 82
11 6 3 1 0
11 6 4 1 0
11 6 5 1 0
11 6 6 1 0
11 6 7 1 0
11 6 8 1 0
11 6 9 1 0
11 6 10 1 0
11 6 11 1 0
11 6 12 1 0
11 6 13 1 50
11 7 2 1 64
11 7 3 1 0
11 7 4 1 0
11 7 5 1 0
11 7 6 1 0
11 7 7 1 0
11 7 8 1 0
11 7 9 1 0
11 7 10 1 0
11 7 11 1 0
11 7 12 1 0
11 7 13 1 32
11 8 2 1 66
11 8 3 1 0
11 8 4 1 0
11 8 5 1 0
11 8 6 1 0
11 8 7 1 0
11 8 8 1 0
11 8 9 1 0
11 8 10 1 0
11 8 11 1 0
11 8 12 1 0
11 8 13 1 32
11 9 2 1 64
11 9 3 1 0
11 9 4 1 0
11 9 5 1 0
11 9 6 1 0
11 9 7 1 0
11 9 8 1 0
11 9 9 1 0
11 9 10 1 0
11 9 11 1 0
11 9 12 1 0
11 9 13 1 32
11 10 2 1 126
11 10 3 1 0
11 10 4 1 0
11 10 5 1 0
11 10 6 1 0
11 10 7 1 0
11 10 8 1 0
11 10 9 1 0
11 10 10 1 0
11 10 11 1 0
11 10 12 1 0
11 10 13 1 32
11 11 2 1 72
11 11 3 1 0
11 11 4 1 0
11 11 5 1 0
11 11 6 1 0
11 11 7 1 0
11 11 8 1 0
11 11 9 1 0
11 11 10 1 0
11 11 11 1 0
11 11 12 1 0
11 11 13 1 40
11 12 3 1 64
11 12 4 1 0
11 12 5 1 0
11 12 6 1 0
11 12 7 1 0
11 12 8 1 0
11 12 9 1 0
11 12 10 1 0
11 12 11 1 0
11 12 12 1 32
11 13 3 1 72
11 13 4 1 0
11 13 5 1 0
11 13 6 1 0
11 13 7 1 0
11 13 8 1 0
11 13 9 1 0
11 13 10 1 0
11 13 11 1 0
11 13 12 1 40
11 14 4 1 64
11 14 5 1 0
11 14 6 1 0
11 14 7 1 0
11 14 8 1 0
11 14 9 1 0
11 14 10 1 0
11 14 11 1 32
11 15 4 1 74
11 15 5 1 8
11 15 6 1 8
11 15 7 1 8
11 15 8 1 8
11 15 9 1 8
11 15 10 1 8
11 15 11 1 42
12 4 5 2 80
12 4 6 2 16
12 4 7 2 16
12 4 8 2 16
12 4 9 2 16
12 4 10 2 48
12 5 4 2 80
12 5 5 2 0
12 5 6 2 0
12 5 7 2 0
12 5 8 2 0
12 5 9 2 0
12 5 10 2 0
12 5 11 2 48
12 6 3 1 80
12 6 4 1 0
12 6 5 1 0
12 6 6 1 0
12 6 7 1 0
12 6 8 1 0
12 6 9 1 0
12 6 10 1 0
12 6 11 1 0
12 6 12 1 48
12 7 2 1 88
12 7 3 1 0
12 7 4 1 0
12 7 5 1 0
12 7 6 1 0
12 7 7 1 0
12 7 8 1 0
12 7 9 1 0
12 7 10 1 0
12 7 11 1 0
12 7 12 1 0
12 7 13 1 48
12 8 2 1 64
12 8 3 1 64
12 8 4 1 0
12 8 5 1 0
12 8 6 1 0
12 8 7 1 0
12 8 8 1 0
12 8 9 1 0
12 8 10 1 0
12 8 11 1 0
12 8 12 1 0
12 8 13 1 32
12 9 2 1 80
12 9 3 1 0
12 9 4 1 0
12 9 5 1 0
12 9 6 1 0
12 9 7 1 0
12 9 8 1 0
12 9 9 1 0
12 9 10 1 0
12 9 11 1 0
12 9 12 1 0
12 9 13 1 32
12 10 2 1 64
12 10 3 1 0
12 10 4 1 0
12 10 5 1 0
12 10 6 1 0
12 10 7 1 0
12 10 8 1 0
12 10 9 1 0
12 10 10 1 0
12 10 11 1 0
12 10 12 1 0
12 10 13 1 32
12 11 2 1 72
12 11 3 1 0
12 11 4 1 0
12 11 5 1 0
12 11 6 1 0
12 11 7 1 0
12 11 8 1 0
12 11 9 1 0
12 11 10 1 0
12 11 11 1 0
12 11 12 1 0
12 11 13 1 40
12 12 3 1 64
12 12 4 1 0
12 12 5 1 0
12 12 6 1 0
12 12 7 1 0
12 12 8 1 0
12 12 9 1 0
12 12 10 1 0
12 12 11 1 0
12 12 12 1 32
12 13 3 1 72
12 13 4 1 0
12 13 5 1 0
12 13 6 1 0
12 13 7 1 0
12 13 8 1 0
12 13 9 1 0
12 13 10 1 0
12 13 11 1 0
12 13 12 1 40
12 14 4 1 72
12 14 5 1 0
12 14 6 1 0
12 14 7 1 0
12 14 8 1 0
12 14 9 1 0
12 14 10 1 0
12 14 11 1 40
12 15 5 1 74
12 15 6 1 8
12 15 7 1 8
12 15 8 1 8
12 15 9 1 8
12 15 10 1 42
13 4 5 2 80
13 4 6 2 16
13 4 7 2 16
13 4 8 2 16
13 4 9 2 16
13 4 10 2 48
13 5 4 2 80
13 5 5 2 0
13 5 6 2 0
13 5 7 2 0
13 5 8 2 0
13 5 9 2 0
13 5 10 2 0
13 5 11 2 48
13 6 3 1 80
13 6 4 1 0
13 6 5 1 0
13 6 6 1 0
13 6 7 1 0
13 6 8 1 0
13 6 9 1 0
13 6 10 1 0
13 6 11 1 0
13 6 12 1 48
13 7 2 1 80
13 7 3 1 0
13 7 4 1 0
13 7 5 1 0
13 7 6 1 0
13 7 7 1 0
13 7 8 1 0
13 7 9 1 0
13 7 10 1 0
13 7 11 1 0
13 7 12 1 0
13 7 13 1 48
13 8 2 1 68
13 8 3 1 0
13 8 4 1 0
13 8 5 1 0
13 8 6 1 0
13 8 7 1 0
13 8 8 1 0
13 8 9 1 0
13 8 10 1 0
13 8 11 1 0
13 8 12 1 0
13 8 13 1 32
13 9 2 1 64
13 9 3 1 0
13 9 4 1 0
13 9 5 1 0
13 9 6 1 0
13 9 7 1 0
13 9 8 1 0
13 9 9 1 0
13 9 10 1 0
13 9 11 1 0
13 9 12 1 0
13 9 13 1 32
13 10 2 1 64
13 10 3 1 0
13 10 4 1 0
13 10 5 1 0
13 10 6 1 0
13 10 7 1 0
13 10 8 1 0
13 10 9 1 0
13 10 10 1 0
13 10 11 1 0
13 10 12 1 0
13 10 13 1 32
13 11 2 1 72
13 11 3 1 0
13 11 4 1 0
13 11 5 1 0
13 11 6 1 0
13 11 7 1 0
13 11 8 1 0
13 11 9 1 0
13 11 10 1 0
13 11 11 1 0
13 11 12 1 0
13 11 13 1 40
13 12 3 1 64
13 12 4 1 0
13 12 5 1 0
13 12 6 1 0
13 12 7 1 0
13 12 8 1 0
13 12 9 1 0
13 12 10 1 0
13 12 11 1 0
13 12 12 1 32
13 13 3 1 72
13 13 4 1 0
13 13 5 1 0
13 13 6 1 0
13 13 7 1 0
13 13 8 1 0
13 13 9 1 0
13 13 10 1 0
13 13 11 1 0
13 13 12 1 40
13 14 4 1 72
13 14 5 1 8
13 14 6 1 0
13 14 7 1 0
13 14 8 1 0
13 14 9 1 0
13 14 10 1 8
13 14 11 1 40
13 15 6 2 74
13 15 7 2 10
13 15 8 2 10
13 15 9 2 42
14 4 5 2 80
14 4 6 2 16
14 4 7 2 16
14 4 8 2 16
14 4 9 2 16
14 4 10 2 48
14 5 4 2 80
14 5 5 2 0
14 5 6 2 0
14 5 7 2 0
14 5 8 2 0
14 5 9 2 0
14 5 10 2 0
14 5 11 2 48
14 6 3 1 80
14 6 4 1 0
14 6 5 1 0
14 6 6 1 0
14 6 7 1 0
14 6 8 1 0
14 6 9 1 0
14 6 10 1 0
14 6 11 1 0
14 6 12 1 48
14 7 2 1 80
14 7 3 1 0
14 7 4 1 0
14 7 5 1 0
14 7 6 1 0
14 7 7 1 0
14 7 8 1 0
14 7 9 1 0
14 7 10 1 0
14 7 11 1 0
14 7 12 1 0
14 7 13 1 48
14 8 2 1 64
14 8 3 1 0
14 8 4 1 0
14 8 5 1 0
14 8 6 1 0
14 8 7 1 0
14 8 8 1 0
14 8 9 1 0
14 8 10 1 0
14 8 11 1 0
14 8 12 1 0
14 8 13 1 32
14 9 2 1 64
14 9 3 1 0
14 9 4 1 0
14 9 5 1 0
14 9 6 1 0
14 9 7 1 0
14 9 8 1 0
14 9 9 1 0
14 9 10 1 0
14 9 11 1 0
14 9 12 1 0
14 9 13 1 32
14 10 2 1 64
14 10 3 1 0
14 10 4 1 0
14 10 5 1 0
14 10 6 1 0
14 10 7 1 0
14 10 8 1 0
14 10 9 1 0
14 10 10 1 0
14 10 11 1 0
14 10 12 1 0
14 10 13 1 32
14 11 2 1 74
14 11 3 1 0
14 11 4 1 0
14 11 5 1 0
14 11 6 1 0
14 11 7 1 0
14 11 8 1 0
14 11 9 1 0
14 11 10 1 0
14 11 11 1 0
14 11 12 1 0
14 11 13 1 42
14 12 3 1 126
14 12 4 0 0
14 12 5 0 0
14 12 6 0 0
14 12 7 0 0
14 12 8 0 0
14 12 9 0 0
14 12 10 0 0
14 12 11 0 0
14 12 12 1 126
14 13 3 1 72
14 13 4 1 0
14 13 5 1 0
14 13 6 1 0
14 13 7 1 0
14 13 8 1 0
14 13 9 1 0
14 13 10 1 0
14 13 11 1 0
14 13 12 1 40
14 14 4 1 72
14 14 5 1 8
14 14 6 1 8
14 14 7 1 8
14 14 8 1 8
14 14 9 1 8
14 14 10 1 8
14 14 11 1 40
14 15 1 0 124
14 15 14 0 124
15 0 11 0 86
15 0 12 0 62
15 1 11 0 110
15 4 5 2 82
15 4 6 2 18
15 4 7 2 18
15 4 8 2 18
15 4 9 2 18
15 4 10 2 50
15 5 4 2 82
15 5 5 2 2
15 5 6 2 2
15 5 7 2 2
15 5 8 2 2
15 5 9 2 2
15 5 10 2 2
15 5 11 2 50
15 6 2 1 86
15 6 3 1 18
15 6 4 1 2
15 6 5 1 2
15 6 6 1 2
15 6 7 1 2
15 6 8 1 2
15 6 9 1 2
15 6 10 1 2
15 6 11 1 2
15 6 12 1 18
15 6 13 1 54
15 7 2 1 66
15 7 3 1 2
15 7 4 1 2
15 7 5 1 2
15 7 6 1 2
15 7 7 1 2
15 7 8 1 2
15 7 9 1 2
15 7 10 1 2
15 7 11 1 2
15 7 12 1 2
15 7 13 1 34
15 8 2 1 66
15 8 3 1 2
15 8 4 1 2
15 8 5 1 2
15 8 6 1 2
15 8 7 1 2
15 8 8 1 2
15 8 9 1 2
15 8 10 1 2
15 8 11 1 2
15 8 12 1 2
15 8 13 1 34
15 9 2 1 66
15 9 3 1 2
15 9 4 1 2
15 9 5 1 2
15 9 6 1 2
15 9 7 1 2
15 9 8 1 2
15 9 9 1 2
15 9 10 1 2
15 9 11 1 2
15 9 12 1 2
15 9 13 1 34
15 10 2 1 74
15 10 3 1 2
15 10 4 1 2
15 10 5 1 2
15 10 6 1 2
15 10 7 1 2
15 10 8 1 2
15 10 9 1 2
15 10 10 1 2
15 10 11 1 2
15 10 12 1 2
15 10 13 1 42
15 11 3 1 126
15 11 4 0 2
15 11 5 0 2
15 11 6 0 2
15 11 7 0 2
15 11 8 0 2
15 11 9 0 2
15 11 10 0 2
15 11 11 0 2
15 11 12 1 126
15 12 3 1 126
15 12 4 0 2
15 12 5 0 2
15 12 6 0 2
15 12 7 0 2
15 12 8 0 2
15 12 9 0 2
15 12 10 0 2
15 12 11 0 2
15 12 12 1 126
15 13 3 1 126
15 13 4 0 2
15 13 5 0 2
15 13 6 0 2
15 13 7 0 2
15 13 8 0 2
15 13 9 0 2
15 13 10 0 2
15 13 11 0 2
15 13 12 1 126
15 14 2 0 126
15 14 3 0 78
15 14 4 1 10
15 14 5 1 10
15 14 6 0 2
15 14 7 0 2
15 14 8 0 2
15 14 9 0 2
15 14 10 1 10
15 14 11 1 10
15 14 12 0 46
15 14 13 0 126
15 15 1 0 122
15 15 6 2 78
15 15 7 2 14
15 15 8 2 14
15 15 9 2 46
15 15 14 0 122
