Qubicle Exchange Format
Version 0.2
www.minddesk.com
16 16 16
3
0.000000 0.407843 0.000000
0.721569 0.972549 0.094118
1.000000 1.000000 1.000000
0 0 11 0 84
0 0 12 0 52
0 1 11 0 68
0 1 12 0 36
0 2 11 1 68
0 2 12 1 36
0 3 11 1 68
0 3 12 1 36
0 4 5 1 86
0 4 6 1 20
0 4 7 1 20
0 4 8 1 20
0 4 9 1 20
0 4 10 1 20
0 4 11 1 4
0 4 12 1 4
0 4 13 1 52
0 5 4 1 126
0 5 5 1 70
0 5 6 1 4
0 5 7 1 4
0 5 8 1 4
0 5 9 1 4
0 5 10 1 4
0 5 11 1 4
0 5 12 1 4
0 5 13 1 36
0 6 2 0 84
0 6 3 0 20
0 6 4 0 20
0 6 5 0 4
0 6 6 0 4
0 6 7 0 4
0 6 8 0 4
0 6 9 0 4
0 6 10 0 4
0 6 11 0 4
0 6 12 0 4
0 6 13 0 36
0 7 2 1 68
0 7 3 1 4
0 7 4 1 4
0 7 5 1 4
0 7 6 1 4
0 7 7 1 4
0 7 8 1 4
0 7 9 1 4
0 7 10 1 4
0 7 11 1 4
0 7 12 1 4
0 7 13 1 36
0 8 2 1 68
0 8 3 1 4
0 8 4 1 4
0 8 5 1 4
0 8 6 1 4
0 8 7 1 4
0 8 8 1 4
0 8 9 1 4
0 8 10 1 4
0 8 11 1 4
0 8 12 1 4
0 8 13 1 36
0 9 2 1 68
0 9 3 1 4
0 9 4 1 4
0 9 5 1 4
0 9 6 1 4
0 9 7 1 4
0 9 8 1 4
0 9 9 1 4
0 9 10 1 4
0 9 11 1 4
0 9 12 1 4
0 9 13 1 36
0 10 2 1 126
0 10 3 1 4
0 10 4 1 4
0 10 5 1 4
0 10 6 1 4
0 10 7 1 4
0 10 8 1 4
0 10 9 1 4
0 10 10 1 4
0 10 11 1 4
0 10 12 1 4
0 10 13 1 44
0 11 3 1 126
0 11 4 0 4
0 11 5 0 4
0 11 6 0 4
0 11 7 0 4
0 11 8 0 4
0 11 9 0 4
0 11 10 0 4
0 11 11 0 4
0 11 12 1 126
0 12 3 1 126
0 12 4 0 4
0 12 5 0 4
0 12 6 0 4
0 12 7 0 4
0 12 8 0 4
0 12 9 0 4
0 12 10 0 4
0 12 11 0 4
0 12 12 1 126
0 13 3 1 126
0 13 4 0 4
0 13 5 0 4
0 13 6 0 4
0 13 7 0 4
0 13 8 0 4
0 13 9 0 4
0 13 10 0 4
0 13 11 0 4
0 13 12 1 126
0 14 2 0 126
0 14 3 0 76
0 14 4 0 12
0 14 5 0 4
0 14 6 0 4
0 14 7 0 4
0 14 8 0 4
0 14 9 0 4
0 14 10 0 4
0 14 11 0 12
0 14 12 0 44
0 14 13 0 126
0 15 0 0 92
0 15 1 0 60
0 15 5 2 78
0 15 6 2 12
0 15 7 2 12
0 15 8 2 12
0 15 9 2 12
0 15 10 2 46
0 15 14 0 92
0 15 15 0 60
1 0 10 0 84
1 0 11 0 16
1 0 12 0 16
1 0 13 0 52
1 1 10 0 68
1 1 11 1 0
1 1 12 1 0
1 1 13 0 36
1 2 3 0 92
1 2 4 0 52
1 2 10 1 68
1 2 11 1 0
1 2 12 1 0
1 2 13 1 36
1 3 4 0 108
1 3 10 1 68
1 3 11 1 0
1 3 12 1 0
1 3 13 1 36
1 4 6 1 80
1 4 7 1 16
1 4 8 1 16
1 4 9 1 16
1 4 10 1 0
1 4 11 1 0
1 4 12 1 0
1 4 13 1 32
1 5 3 1 126
1 5 4 1 126
1 5 5 1 126
1 5 6 1 64
1 5 7 1 0
1 5 8 1 0
1 5 9 1 0
1 5 10 1 0
1 5 11 1 0
1 5 12 1 0
1 5 13 1 32
1 6 2 1 80
1 6 3 1 16
1 6 4 1 16
1 6 5 1 16
1 6 6 1 0
1 6 7 1 0
1 6 8 1 0
1 6 9 1 0
1 6 10 1 0
1 6 11 1 0
1 6 12 1 0
1 6 13 1 32
1 7 2 1 64
1 7 3 1 0
1 7 4 1 0
1 7 5 1 0
1 7 6 1 0
1 7 7 1 0
1 7 8 1 0
1 7 9 1 0
1 7 10 1 0
1 7 11 1 0
1 7 12 1 0
1 7 13 1 32
1 8 2 1 64
1 8 3 1 0
1 8 4 1 0
1 8 5 1 0
1 8 6 1 0
1 8 7 1 0
1 8 8 1 0
1 8 9 1 0
1 8 10 1 0
1 8 11 1 0
1 8 12 1 0
1 8 13 1 32
1 9 2 1 64
1 9 3 1 0
1 9 4 1 0
1 9 5 1 0
1 9 6 1 0
1 9 7 1 0
1 9 8 1 0
1 9 9 1 0
1 9 10 1 0
1 9 11 1 0
1 9 12 1 0
1 9 13 1 32
1 10 2 1 74
1 10 3 1 0
1 10 4 1 0
1 10 5 1 0
1 10 6 1 0
1 10 7 1 0
1 10 8 1 0
1 10 9 1 0
1 10 10 1 0
1 10 11 1 0
1 10 12 1 0
1 10 13 1 42
1 11 3 1 126
1 11 4 0 0
1 11 5 0 0
1 11 6 0 0
1 11 7 0 0
1 11 8 0 0
1 11 9 0 0
1 11 10 0 0
1 11 11 0 0
1 11 12 1 126
1 12 3 1 126
1 12 4 0 0
1 12 5 0 0
1 12 6 0 0
1 12 7 0 0
1 12 8 0 0
1 12 9 0 0
1 12 10 0 0
1 12 11 0 0
1 12 12 1 126
1 13 3 1 126
1 13 4 0 0
1 13 5 0 0
1 13 6 0 0
1 13 7 0 0
1 13 8 0 0
1 13 9 0 0
1 13 10 0 0
1 13 11 0 0
1 13 12 1 126
1 14 2 0 126
1 14 3 0 72
1 14 4 0 8
1 14 5 1 8
1 14 6 0 0
1 14 7 0 0
1 14 8 0 0
1 14 9 0 0
1 14 10 1 8
1 14 11 0 8
1 14 12 0 40
1 14 13 0 126
1 15 0 0 88
1 15 1 0 56
1 15 6 2 74
1 15 7 2 10
1 15 8 2 10
1 15 9 2 42
1 15 14 0 88
1 15 15 0 56
2 0 10 0 80
2 0 11 0 16
2 0 12 0 16
2 0 13 0 48
2 1 10 0 64
2 1 11 1 0
2 1 12 1 0
2 1 13 0 32
2 2 3 0 80
2 2 4 0 48
2 2 10 1 64
2 2 11 1 0
2 2 12 1 0
2 2 13 1 32
2 3 3 0 68
2 3 4 0 32
2 3 10 1 64
2 3 11 1 0
2 3 12 1 0
2 3 13 1 32
2 4 3 1 68
2 4 4 1 36
2 4 6 1 80
2 4 7 1 16
2 4 8 1 16
2 4 9 1 16
2 4 10 1 0
2 4 11 1 0
2 4 12 1 0
2 4 13 1 32
2 5 2 1 126
2 5 3 1 68
2 5 4 1 36
2 5 6 1 64
2 5 7 1 0
2 5 8 1 0
2 5 9 1 0
2 5 10 1 0
2 5 11 1 0
2 5 12 1 0
2 5 13 1 32
2 6 2 1 80
2 6 3 1 0
2 6 4 1 0
2 6 5 1 16
2 6 6 1 0
2 6 7 1 0
2 6 8 1 0
2 6 9 1 0
2 6 10 1 0
2 6 11 1 0
2 6 12 1 0
2 6 13 1 32
2 7 2 1 64
2 7 3 1 0
2 7 4 1 0
2 7 5 1 0
2 7 6 1 0
2 7 7 1 0
2 7 8 1 0
2 7 9 1 0
2 7 10 1 0
2 7 11 1 0
2 7 12 1 0
2 7 13 1 32
2 8 2 1 64
2 8 3 1 0
2 8 4 1 0
2 8 5 1 0
2 8 6 1 0
2 8 7 1 0
2 8 8 1 0
2 8 9 1 0
2 8 10 1 0
2 8 11 1 0
2 8 12 1 0
2 8 13 1 32
2 9 2 1 74
2 9 3 1 0
2 9 4 1 0
2 9 5 1 0
2 9 6 1 0
2 9 7 1 0
2 9 8 1 0
2 9 9 1 0
2 9 10 1 0
2 9 11 1 0
2 9 12 1 0
2 9 13 1 42
2 10 3 1 64
2 10 4 1 0
2 10 5 1 0
2 10 6 1 0
2 10 7 1 0
2 10 8 1 0
2 10 9 1 0
2 10 10 1 0
2 10 11 1 0
2 10 12 1 32
2 11 3 1 126
2 11 4 0 0
2 11 5 0 0
2 11 6 0 0
2 11 7 0 0
2 11 8 0 0
2 11 9 0 0
2 11 10 0 0
2 11 11 0 0
2 11 12 1 126
2 12 3 1 126
2 12 4 0 0
2 12 5 0 0
2 12 6 0 0
2 12 7 0 0
2 12 8 0 0
2 12 9 0 0
2 12 10 0 0
2 12 11 0 0
2 12 12 1 126
2 13 3 1 126
2 13 4 0 0
2 13 5 0 0
2 13 6 0 0
2 13 7 0 0
2 13 8 0 0
2 13 9 0 0
2 13 10 0 0
2 13 11 0 0
2 13 12 1 126
2 14 2 0 126
2 14 3 0 74
2 14 4 1 8
2 14 5 1 8
2 14 6 1 8
2 14 7 1 8
2 14 8 1 8
2 14 9 1 8
2 14 10 1 8
2 14 11 1 8
2 14 12 0 42
2 14 13 0 126
2 15 0 0 88
2 15 1 0 56
2 15 14 0 88
2 15 15 0 56
3 0 10 0 82
3 0 11 0 16
3 0 12 0 16
3 0 13 0 50
3 1 10 0 64
3 1 11 1 0
3 1 12 1 0
3 1 13 0 34
3 2 2 0 84
3 2 3 0 16
3 2 4 0 16
3 2 5 0 52
3 2 10 1 64
3 2 11 1 0
3 2 12 1 0
3 2 13 1 34
3 3 2 0 68
3 3 3 1 0
3 3 4 1 0
3 3 5 0 36
3 3 10 1 64
3 3 11 1 0
3 3 12 1 0
3 3 13 1 34
3 4 2 1 68
3 4 3 1 0
3 4 4 1 0
3 4 5 1 4
3 4 6 1 16
3 4 7 1 16
3 4 8 1 16
3 4 9 1 16
3 4 10 1 0
3 4 11 1 0
3 4 12 1 0
3 4 13 1 34
3 5 2 1 68
3 5 3 1 0
3 5 4 1 0
3 5 5 1 4
3 5 6 1 0
3 5 7 1 0
3 5 8 1 0
3 5 9 1 0
3 5 10 1 0
3 5 11 1 0
3 5 12 1 0
3 5 13 1 34
3 6 2 1 66
3 6 3 1 0
3 6 4 1 0
3 6 5 1 0
3 6 6 1 0
3 6 7 1 0
3 6 8 1 0
3 6 9 1 0
3 6 10 1 0
3 6 11 1 0
3 6 12 1 0
3 6 13 1 34
3 7 2 1 66
3 7 3 1 0
3 7 4 1 0
3 7 5 1 0
3 7 6 1 0
3 7 7 1 0
3 7 8 1 0
3 7 9 1 0
3 7 10 1 0
3 7 11 1 0
3 7 12 1 0
3 7 13 1 34
3 8 2 1 74
3 8 3 1 0
3 8 4 1 0
3 8 5 1 0
3 8 6 1 0
3 8 7 1 0
3 8 8 1 0
3 8 9 1 0
3 8 10 1 0
3 8 11 1 0
3 8 12 1 0
3 8 13 1 42
3 9 3 1 64
3 9 4 1 0
3 9 5 1 0
3 9 6 1 0
3 9 7 1 0
3 9 8 1 0
3 9 9 1 0
3 9 10 1 0
3 9 11 1 0
3 9 12 1 32
3 10 3 1 64
3 10 4 1 0
3 10 5 1 0
3 10 6 1 0
3 10 7 1 0
3 10 8 1 0
3 10 9 1 0
3 10 10 1 0
3 10 11 1 0
3 10 12 1 32
3 11 3 1 126
3 11 4 0 0
3 11 5 0 0
3 11 6 0 0
3 11 7 0 0
3 11 8 0 0
3 11 9 0 0
3 11 10 0 0
3 11 11 0 0
3 11 12 1 126
3 12 3 1 126
3 12 4 0 0
3 12 5 0 0
3 12 6 0 0
3 12 7 0 0
3 12 8 0 0
3 12 9 0 0
3 12 10 0 0
3 12 11 0 0
3 12 12 1 126
3 13 3 1 126
3 13 4 0 0
3 13 5 0 0
3 13 6 0 0
3 13 7 0 0
3 13 8 0 0
3 13 9 0 0
3 13 10 0 0
3 13 11 0 0
3 13 12 1 126
3 14 4 1 72
3 14 5 1 8
3 14 6 1 0
3 14 7 1 0
3 14 8 1 0
3 14 9 1 0
3 14 10 1 8
3 14 11 1 40
3 15 0 0 88
3 15 1 0 56
3 15 2 0 126
3 15 3 0 126
3 15 6 2 76
3 15 7 2 12
3 15 8 2 12
3 15 9 2 44
3 15 12 0 126
3 15 13 0 126
3 15 14 0 88
3 15 15 0 56
4 0 11 0 82
4 0 12 0 50
4 1 10 0 82
4 1 11 1 0
4 1 12 0 34
4 2 2 0 80
4 2 3 0 16
4 2 4 0 16
4 2 5 0 48
4 2 10 1 66
4 2 11 1 0
4 2 12 0 34
4 3 2 0 64
4 3 3 1 0
4 3 4 1 0
4 3 5 0 32
4 3 10 1 66
4 3 11 1 0
4 3 12 1 34
4 4 2 1 64
4 4 3 1 0
4 4 4 1 0
4 4 5 1 0
4 4 6 1 18
4 4 7 1 18
4 4 8 1 18
4 4 9 1 18
4 4 10 1 2
4 4 11 1 0
4 4 12 1 34
4 5 2 1 74
4 5 3 1 0
4 5 4 1 0
4 5 5 1 0
4 5 6 1 0
4 5 7 1 0
4 5 8 1 0
4 5 9 1 0
4 5 10 1 2
4 5 11 1 0
4 5 12 1 34
4 6 3 1 66
4 6 4 1 0
4 6 5 1 0
4 6 6 1 0
4 6 7 1 0
4 6 8 1 0
4 6 9 1 0
4 6 10 1 0
4 6 11 1 0
4 6 12 1 34
4 7 3 1 66
4 7 4 1 0
4 7 5 1 0
4 7 6 1 0
4 7 7 1 0
4 7 8 1 0
4 7 9 1 0
4 7 10 1 0
4 7 11 1 0
4 7 12 1 34
4 8 3 1 64
4 8 4 1 0
4 8 5 1 0
4 8 6 1 0
4 8 7 1 0
4 8 8 1 0
4 8 9 1 0
4 8 10 1 0
4 8 11 1 0
4 8 12 1 32
4 9 3 1 64
4 9 4 1 0
4 9 5 1 0
4 9 6 1 0
4 9 7 1 0
4 9 8 1 0
4 9 9 1 0
4 9 10 1 0
4 9 11 1 0
4 9 12 1 32
4 10 3 1 64
4 10 4 1 0
4 10 5 1 0
4 10 6 1 0
4 10 7 1 0
4 10 8 1 0
4 10 9 1 0
4 10 10 1 0
4 10 11 1 0
4 10 12 1 32
4 11 3 1 126
4 11 4 0 0
4 11 5 0 0
4 11 6 0 0
4 11 7 0 0
4 11 8 0 0
4 11 9 0 0
4 11 10 0 0
4 11 11 0 0
4 11 12 1 126
4 12 3 1 126
4 12 4 0 0
4 12 5 0 0
4 12 6 0 0
4 12 7 0 0
4 12 8 0 0
4 12 9 0 0
4 12 10 0 0
4 12 11 0 0
4 12 12 1 126
4 13 4 1 64
4 13 5 1 0
4 13 6 1 0
4 13 7 1 0
4 13 8 1 0
4 13 9 1 0
4 13 10 1 0
4 13 11 1 32
4 14 4 1 72
4 14 5 1 0
4 14 6 1 0
4 14 7 1 0
4 14 8 1 0
4 14 9 1 0
4 14 10 1 0
4 14 11 1 40
4 15 0 0 88
4 15 1 0 56
4 15 2 0 126
4 15 5 2 76
4 15 6 2 8
4 15 7 2 8
4 15 8 2 8
4 15 9 2 8
4 15 10 2 44
4 15 13 0 126
4 15 14 0 88
4 15 15 0 56
5 1 11 0 114
5 2 2 0 82
5 2 3 0 18
5 2 4 0 16
5 2 5 0 50
5 2 11 0 98
5 3 2 0 66
5 3 3 1 0
5 3 4 1 0
5 3 5 0 32
5 3 11 1 98
5 4 2 1 74
5 4 3 1 0
5 4 4 1 0
5 4 5 1 32
5 4 11 1 98
5 5 3 1 74
5 5 4 1 0
5 5 5 1 0
5 5 6 1 18
5 5 7 1 18
5 5 8 1 18
5 5 9 1 50
5 5 11 1 98
5 6 4 1 66
5 6 5 1 2
5 6 6 1 0
5 6 7 1 0
5 6 8 1 0
5 6 9 1 0
5 6 10 1 18
5 6 11 1 34
5 7 4 1 66
5 7 5 1 0
5 7 6 1 0
5 7 7 1 0
5 7 8 1 0
5 7 9 1 0
5 7 10 1 0
5 7 11 1 34
5 8 3 1 82
5 8 4 1 0
5 8 5 1 0
5 8 6 1 0
5 8 7 1 0
5 8 8 1 0
5 8 9 1 0
5 8 10 1 0
5 8 11 1 0
5 8 12 1 50
5 9 3 1 66
5 9 4 1 0
5 9 5 1 0
5 9 6 1 0
5 9 7 1 0
5 9 8 1 0
5 9 9 1 0
5 9 10 1 0
5 9 11 1 0
5 9 12 1 34
5 10 3 1 66
5 10 4 1 0
5 10 5 1 0
5 10 6 1 0
5 10 7 1 0
5 10 8 1 0
5 10 9 1 0
5 10 10 1 0
5 10 11 1 0
5 10 12 1 34
5 11 3 1 126
5 11 4 0 0
5 11 5 0 0
5 11 6 0 0
5 11 7 0 0
5 11 8 0 0
5 11 9 0 0
5 11 10 0 0
5 11 11 0 0
5 11 12 1 126
5 12 4 1 126
5 12 5 0 0
5 12 6 0 0
5 12 7 0 0
5 12 8 0 0
5 12 9 0 0
5 12 10 0 0
5 12 11 1 126
5 13 4 1 64
5 13 5 1 0
5 13 6 1 0
5 13 7 1 0
5 13 8 1 0
5 13 9 1 0
5 13 10 1 0
5 13 11 1 32
5 14 4 1 64
5 14 5 1 0
5 14 6 1 0
5 14 7 1 0
5 14 8 1 0
5 14 9 1 0
5 14 10 1 0
5 14 11 1 32
5 15 0 0 88
5 15 1 0 58
5 15 4 1 76
5 15 5 1 8
5 15 6 1 8
5 15 7 1 8
5 15 8 1 8
5 15 9 1 8
5 15 10 1 8
5 15 11 1 44
5 15 14 0 90
5 15 15 0 56
6 2 4 0 114
6 3 3 0 82
6 3 4 1 0
6 3 5 0 50
6 4 3 0 74
6 4 4 1 0
6 4 5 1 34
6 5 4 1 74
6 5 5 1 42
6 6 6 1 82
6 6 7 1 18
6 6 8 1 18
6 6 9 1 50
6 7 5 1 82
6 7 6 1 2
6 7 7 1 2
6 7 8 1 2
6 7 9 1 2
6 7 10 1 50
6 8 4 1 82
6 8 5 1 2
6 8 6 1 2
6 8 7 1 2
6 8 8 1 2
6 8 9 1 2
6 8 10 1 2
6 8 11 1 50
6 9 4 1 66
6 9 5 1 2
6 9 6 1 0
6 9 7 1 0
6 9 8 1 0
6 9 9 1 0
6 9 10 1 2
6 9 11 1 34
6 10 4 1 66
6 10 5 1 0
6 10 6 1 0
6 10 7 1 0
6 10 8 1 0
6 10 9 1 0
6 10 10 1 0
6 10 11 1 34
6 11 4 1 126
6 11 5 0 0
6 11 6 0 0
6 11 7 0 0
6 11 8 0 0
6 11 9 0 0
6 11 10 0 0
6 11 11 1 126
6 12 4 1 64
6 12 5 1 0
6 12 6 1 0
6 12 7 1 0
6 12 8 1 0
6 12 9 1 0
6 12 10 1 0
6 12 11 1 32
6 13 4 1 64
6 13 5 1 0
6 13 6 1 0
6 13 7 1 0
6 13 8 1 0
6 13 9 1 0
6 13 10 1 0
6 13 11 1 32
6 14 4 1 66
6 14 5 1 0
6 14 6 1 0
6 14 7 1 0
6 14 8 1 0
6 14 9 1 0
6 14 10 1 0
6 14 11 1 34
6 15 0 0 122
6 15 4 1 74
6 15 5 1 8
6 15 6 1 8
6 15 7 1 8
6 15 8 1 8
6 15 9 1 8
6 15 10 1 8
6 15 11 1 42
6 15 15 0 122
7 3 4 0 114
7 4 4 0 106
7 9 6 1 82
7 9 7 1 18
7 9 8 1 18
7 9 9 1 50
7 10 5 1 82
7 10 6 1 2
7 10 7 1 2
7 10 8 1 2
7 10 9 1 2
7 10 10 1 50
7 11 4 1 82
7 11 5 1 2
7 11 6 1 2
7 11 7 1 2
7 11 8 1 2
7 11 9 1 2
7 11 10 1 2
7 11 11 1 50
7 12 4 1 66
7 12 5 1 2
7 12 6 1 2
7 12 7 1 2
7 12 8 1 2
7 12 9 1 2
7 12 10 1 2
7 12 11 1 34
7 13 4 1 74
7 13 5 1 2
7 13 6 1 2
7 13 7 1 2
7 13 8 1 2
7 13 9 1 2
7 13 10 1 2
7 13 11 1 42
7 14 5 1 66
7 14 6 1 2
7 14 7 1 2
7 14 8 1 2
7 14 9 1 2
7 14 10 1 34
7 15 5 1 74
7 15 6 1 10
7 15 7 1 10
7 15 8 1 10
7 15 9 1 10
7 15 10 1 42
