Qubicle Exchange Format
Version 0.2
www.minddesk.com
16 16 16
4
0.298039 0.345098 0.392157
0.972549 0.219608 0.000000
1.000000 0.627451 0.266667
1.000000 1.000000 1.000000
0 5 4 1 124
0 5 6 1 124
0 5 9 1 124
0 5 11 1 124
0 6 3 1 116
0 6 5 1 116
0 6 7 1 84
0 6 8 1 52
0 6 10 1 124
0 6 12 1 116
0 7 3 1 108
0 7 5 1 108
0 7 7 1 68
0 7 8 1 44
0 7 10 1 108
0 7 12 1 108
0 8 4 1 124
0 8 6 1 92
0 8 7 1 44
0 8 9 1 124
0 8 11 1 124
1 3 3 1 116
1 3 6 1 116
1 3 8 1 116
1 3 10 1 116
1 3 12 1 116
1 4 2 1 84
1 4 3 1 4
1 4 4 1 20
1 4 5 1 20
1 4 6 1 4
1 4 7 1 20
1 4 8 1 4
1 4 9 1 20
1 4 10 1 4
1 4 11 1 20
1 4 12 1 12
1 4 13 1 52
1 5 2 1 68
1 5 3 1 4
1 5 4 1 0
1 5 5 1 4
1 5 6 1 0
1 5 7 1 4
1 5 8 1 4
1 5 9 1 4
1 5 10 1 4
1 5 11 1 32
1 5 13 1 100
1 6 2 1 68
1 6 3 1 0
1 6 4 1 4
1 6 5 1 0
1 6 6 1 4
1 6 7 1 0
1 6 8 1 0
1 6 9 1 4
1 6 10 1 0
1 6 11 1 4
1 6 12 1 16
1 6 13 1 36
1 7 2 0 76
1 7 3 0 0
1 7 4 0 4
1 7 5 0 0
1 7 6 0 4
1 7 7 0 0
1 7 8 0 0
1 7 9 0 4
1 7 10 0 4
1 7 11 0 4
1 7 12 0 0
1 7 13 0 44
1 8 3 0 76
1 8 4 0 0
1 8 5 0 4
1 8 6 0 0
1 8 7 0 0
1 8 8 0 4
1 8 9 0 0
1 8 10 0 4
1 8 11 0 0
1 8 12 0 44
1 9 4 1 76
1 9 5 1 4
1 9 6 1 12
1 9 7 1 4
1 9 8 1 12
1 9 9 1 12
1 9 10 1 4
1 9 11 1 44
1 10 5 1 110
1 10 7 1 110
1 10 8 1 46
1 10 10 1 110
2 1 3 1 84
2 1 4 1 20
2 1 5 1 20
2 1 6 1 20
2 1 7 1 20
2 1 8 1 20
2 1 9 1 20
2 1 10 1 20
2 1 11 1 20
2 1 12 1 52
2 2 2 1 84
2 2 3 1 4
2 2 4 1 4
2 2 5 1 4
2 2 6 1 4
2 2 7 1 4
2 2 8 1 4
2 2 9 1 4
2 2 10 1 4
2 2 11 1 4
2 2 12 1 4
2 2 13 1 52
2 3 2 1 68
2 3 3 1 0
2 3 4 1 4
2 3 5 1 4
2 3 6 1 0
2 3 7 1 4
2 3 8 1 0
2 3 9 1 4
2 3 10 1 0
2 3 11 1 4
2 3 12 1 0
2 3 13 1 36
2 4 2 1 64
2 4 3 1 0
2 4 4 1 0
2 4 5 1 0
2 4 6 1 0
2 4 7 1 0
2 4 8 1 0
2 4 9 1 0
2 4 10 1 0
2 4 11 1 0
2 4 12 1 0
2 4 13 1 32
2 5 2 1 64
2 5 3 1 0
2 5 4 1 0
2 5 5 1 0
2 5 6 1 0
2 5 7 1 0
2 5 8 1 0
2 5 9 1 0
2 5 10 1 0
2 5 11 1 0
2 5 12 1 4
2 5 13 1 32
2 6 2 1 64
2 6 3 1 0
2 6 4 1 0
2 6 5 1 0
2 6 6 1 0
2 6 7 1 0
2 6 8 1 0
2 6 9 1 0
2 6 10 1 0
2 6 11 1 0
2 6 12 1 0
2 6 13 1 32
2 7 2 1 64
2 7 3 1 0
2 7 4 1 0
2 7 5 1 0
2 7 6 1 0
2 7 7 1 0
2 7 8 1 0
2 7 9 1 0
2 7 10 1 0
2 7 11 1 0
2 7 12 1 0
2 7 13 1 32
2 8 2 1 76
2 8 3 1 0
2 8 4 1 0
2 8 5 1 0
2 8 6 1 0
2 8 7 1 0
2 8 8 1 0
2 8 9 1 0
2 8 10 1 0
2 8 11 1 0
2 8 12 1 0
2 8 13 1 44
2 9 3 1 76
2 9 4 1 8
2 9 5 1 8
2 9 6 1 8
2 9 7 1 8
2 9 8 1 8
2 9 9 1 8
2 9 10 1 8
2 9 11 1 8
2 9 12 1 44
2 12 5 2 126
2 12 7 2 94
2 12 8 2 62
2 12 10 2 126
2 14 5 1 126
2 14 7 1 94
2 14 8 1 62
2 14 10 1 126
2 15 4 1 126
2 15 6 1 126
2 15 9 1 126
2 15 11 1 126
3 1 2 1 84
3 1 3 1 16
3 1 4 1 16
3 1 5 1 16
3 1 6 1 16
3 1 7 1 16
3 1 8 1 16
3 1 9 1 16
3 1 10 1 16
3 1 11 1 16
3 1 12 1 16
3 1 13 1 52
3 2 2 1 64
3 2 3 1 0
3 2 4 1 0
3 2 5 1 0
3 2 6 1 0
3 2 7 1 0
3 2 8 1 0
3 2 9 1 0
3 2 10 1 0
3 2 11 1 0
3 2 12 1 0
3 2 13 1 32
3 3 2 2 64
3 3 3 2 0
3 3 4 2 0
3 3 5 2 0
3 3 6 2 0
3 3 7 2 0
3 3 8 2 0
3 3 9 2 0
3 3 10 2 0
3 3 11 2 0
3 3 12 2 0
3 3 13 2 32
3 4 2 2 64
3 4 3 2 0
3 4 4 2 0
3 4 5 2 0
3 4 6 2 0
3 4 7 2 0
3 4 8 2 0
3 4 9 2 0
3 4 10 2 0
3 4 11 2 0
3 4 12 2 0
3 4 13 2 32
3 5 2 1 64
3 5 3 1 0
3 5 4 1 0
3 5 5 1 0
3 5 6 1 0
3 5 7 1 0
3 5 8 1 0
3 5 9 1 0
3 5 10 1 0
3 5 11 1 0
3 5 12 1 0
3 5 13 1 32
3 6 2 1 64
3 6 3 1 0
3 6 4 1 0
3 6 5 1 0
3 6 6 1 0
3 6 7 1 0
3 6 8 1 0
3 6 9 1 0
3 6 10 1 0
3 6 11 1 0
3 6 12 1 0
3 6 13 1 32
3 7 2 1 64
3 7 3 1 0
3 7 4 1 0
3 7 5 1 0
3 7 6 1 0
3 7 7 1 0
3 7 8 1 0
3 7 9 1 0
3 7 10 1 0
3 7 11 1 0
3 7 12 1 0
3 7 13 1 32
3 8 2 1 64
3 8 3 1 0
3 8 4 1 0
3 8 5 1 0
3 8 6 1 0
3 8 7 1 0
3 8 8 1 0
3 8 9 1 0
3 8 10 1 0
3 8 11 1 0
3 8 12 1 0
3 8 13 1 32
3 9 2 1 76
3 9 3 1 0
3 9 4 1 0
3 9 5 1 0
3 9 6 1 0
3 9 7 1 0
3 9 8 1 0
3 9 9 1 0
3 9 10 1 0
3 9 11 1 0
3 9 12 1 0
3 9 13 1 44
3 10 3 1 76
3 10 4 1 4
3 10 5 1 4
3 10 6 1 4
3 10 7 1 4
3 10 8 1 4
3 10 9 1 4
3 10 10 1 4
3 10 11 1 4
3 10 12 1 44
3 11 4 1 78
3 11 5 1 14
3 11 6 1 14
3 11 7 1 14
3 11 8 1 14
3 11 9 1 14
3 11 10 1 14
3 11 11 1 46
4 0 3 1 84
4 0 4 1 20
4 0 5 1 20
4 0 6 1 20
4 0 7 1 20
4 0 8 1 20
4 0 9 1 20
4 0 10 1 20
4 0 11 1 20
4 0 12 1 52
4 1 2 1 80
4 1 3 1 0
4 1 4 1 0
4 1 5 1 0
4 1 6 1 0
4 1 7 1 0
4 1 8 1 0
4 1 9 1 0
4 1 10 1 0
4 1 11 1 0
4 1 12 1 0
4 1 13 1 48
4 2 2 2 64
4 2 3 2 0
4 2 4 2 0
4 2 5 2 0
4 2 6 2 0
4 2 7 2 0
4 2 8 2 0
4 2 9 2 0
4 2 10 2 0
4 2 11 2 0
4 2 12 2 0
4 2 13 2 32
4 3 2 2 64
4 3 3 2 0
4 3 4 2 0
4 3 5 2 0
4 3 6 2 0
4 3 7 2 0
4 3 8 2 0
4 3 9 2 0
4 3 10 2 0
4 3 11 2 0
4 3 12 2 0
4 3 13 2 32
4 4 2 2 64
4 4 3 2 0
4 4 4 2 0
4 4 5 2 0
4 4 6 2 0
4 4 7 2 0
4 4 8 2 0
4 4 9 2 0
4 4 10 2 0
4 4 11 2 0
4 4 12 2 0
4 4 13 2 32
4 5 2 2 64
4 5 3 2 0
4 5 4 2 0
4 5 5 2 0
4 5 6 2 0
4 5 7 2 0
4 5 8 2 0
4 5 9 2 0
4 5 10 2 0
4 5 11 2 0
4 5 12 2 0
4 5 13 2 32
4 6 2 1 64
4 6 3 1 0
4 6 4 1 0
4 6 5 1 0
4 6 6 1 0
4 6 7 1 0
4 6 8 1 0
4 6 9 1 0
4 6 10 1 0
4 6 11 1 0
4 6 12 1 0
4 6 13 1 32
4 7 2 1 64
4 7 3 1 0
4 7 4 1 0
4 7 5 1 0
4 7 6 1 0
4 7 7 1 0
4 7 8 1 0
4 7 9 1 0
4 7 10 1 0
4 7 11 1 0
4 7 12 1 0
4 7 13 1 32
4 8 2 1 64
4 8 3 1 0
4 8 4 1 0
4 8 5 1 0
4 8 6 1 0
4 8 7 1 0
4 8 8 1 0
4 8 9 1 0
4 8 10 1 0
4 8 11 1 0
4 8 12 1 0
4 8 13 1 32
4 9 2 1 64
4 9 3 1 0
4 9 4 1 0
4 9 5 1 0
4 9 6 1 0
4 9 7 1 0
4 9 8 1 0
4 9 9 1 0
4 9 10 1 0
4 9 11 1 0
4 9 12 1 0
4 9 13 1 32
4 10 2 1 76
4 10 3 1 8
4 10 4 1 8
4 10 5 1 8
4 10 6 1 8
4 10 7 1 8
4 10 8 1 8
4 10 9 1 8
4 10 10 1 8
4 10 11 1 8
4 10 12 1 8
4 10 13 1 44
5 0 2 1 84
5 0 3 1 16
5 0 4 1 16
5 0 5 1 16
5 0 6 1 16
5 0 7 1 16
5 0 8 1 16
5 0 9 1 16
5 0 10 1 16
5 0 11 1 16
5 0 12 1 16
5 0 13 1 52
5 1 2 2 64
5 1 3 2 0
5 1 4 2 0
5 1 5 2 0
5 1 6 2 0
5 1 7 2 0
5 1 8 2 0
5 1 9 2 0
5 1 10 2 0
5 1 11 2 0
5 1 12 2 0
5 1 13 2 32
5 2 2 2 64
5 2 3 2 0
5 2 4 2 0
5 2 5 2 0
5 2 6 2 0
5 2 7 2 0
5 2 8 2 0
5 2 9 2 0
5 2 10 2 0
5 2 11 2 0
5 2 12 2 0
5 2 13 2 32
5 3 2 3 64
5 3 3 3 0
5 3 4 3 0
5 3 5 3 0
5 3 6 3 0
5 3 7 3 0
5 3 8 3 0
5 3 9 3 0
5 3 10 3 0
5 3 11 3 0
5 3 12 3 0
5 3 13 3 32
5 4 2 2 64
5 4 3 2 0
5 4 4 2 0
5 4 5 2 0
5 4 6 2 0
5 4 7 2 0
5 4 8 2 0
5 4 9 2 0
5 4 10 2 0
5 4 11 2 0
5 4 12 2 0
5 4 13 2 32
5 5 2 2 64
5 5 3 2 0
5 5 4 2 0
5 5 5 2 0
5 5 6 2 0
5 5 7 2 0
5 5 8 2 0
5 5 9 2 0
5 5 10 2 0
5 5 11 2 0
5 5 12 2 0
5 5 13 2 32
5 6 2 2 64
5 6 3 2 0
5 6 4 2 0
5 6 5 2 0
5 6 6 2 0
5 6 7 2 0
5 6 8 2 0
5 6 9 2 0
5 6 10 2 0
5 6 11 2 0
5 6 12 2 0
5 6 13 2 32
5 7 2 1 64
5 7 3 1 0
5 7 4 1 0
5 7 5 1 0
5 7 6 1 0
5 7 7 1 0
5 7 8 1 0
5 7 9 1 0
5 7 10 1 0
5 7 11 1 0
5 7 12 1 0
5 7 13 1 32
5 8 2 1 64
5 8 3 1 0
5 8 4 1 0
5 8 5 1 0
5 8 6 1 0
5 8 7 1 0
5 8 8 1 0
5 8 9 1 0
5 8 10 1 0
5 8 11 1 0
5 8 12 1 0
5 8 13 1 32
5 9 2 2 64
5 9 3 2 0
5 9 4 2 0
5 9 5 2 0
5 9 6 2 0
5 9 7 2 0
5 9 8 2 0
5 9 9 2 0
5 9 10 2 0
5 9 11 2 0
5 9 12 2 0
5 9 13 2 32
5 10 2 0 72
5 10 3 0 0
5 10 4 0 0
5 10 5 0 0
5 10 6 0 0
5 10 7 0 0
5 10 8 0 0
5 10 9 0 0
5 10 10 0 0
5 10 11 0 0
5 10 12 0 0
5 10 13 0 40
5 11 3 1 76
5 11 4 1 4
5 11 5 1 4
5 11 6 1 4
5 11 7 1 4
5 11 8 1 4
5 11 9 1 4
5 11 10 1 4
5 11 11 1 4
5 11 12 1 44
5 12 4 1 76
5 12 5 1 4
5 12 6 1 12
5 12 7 1 4
5 12 8 1 4
5 12 9 1 12
5 12 10 1 4
5 12 11 1 44
5 13 5 1 110
5 13 7 1 78
5 13 8 1 46
5 13 10 1 110
6 0 2 1 80
6 0 3 1 16
6 0 4 1 16
6 0 5 1 16
6 0 6 1 16
6 0 7 1 16
6 0 8 1 16
6 0 9 1 16
6 0 10 1 16
6 0 11 1 16
6 0 12 1 16
6 0 13 1 48
6 1 2 2 64
6 1 3 2 0
6 1 4 2 0
6 1 5 2 0
6 1 6 2 0
6 1 7 2 0
6 1 8 2 0
6 1 9 2 0
6 1 10 2 0
6 1 11 2 0
6 1 12 2 0
6 1 13 2 32
6 2 2 3 64
6 2 3 3 0
6 2 4 3 0
6 2 5 3 0
6 2 6 3 0
6 2 7 3 0
6 2 8 3 0
6 2 9 3 0
6 2 10 3 0
6 2 11 3 0
6 2 12 3 0
6 2 13 3 32
6 3 2 3 64
6 3 3 3 0
6 3 4 3 0
6 3 5 3 0
6 3 6 3 0
6 3 7 3 0
6 3 8 3 0
6 3 9 3 0
6 3 10 3 0
6 3 11 3 0
6 3 12 3 0
6 3 13 3 32
6 4 2 3 64
6 4 3 3 0
6 4 4 3 0
6 4 5 3 0
6 4 6 3 0
6 4 7 3 0
6 4 8 3 0
6 4 9 3 0
6 4 10 3 0
6 4 11 3 0
6 4 12 3 0
6 4 13 3 32
6 5 2 2 64
6 5 3 2 0
6 5 4 2 0
6 5 5 2 0
6 5 6 2 0
6 5 7 2 0
6 5 8 2 0
6 5 9 2 0
6 5 10 2 0
6 5 11 2 0
6 5 12 2 0
6 5 13 2 32
6 6 2 1 64
6 6 3 1 0
6 6 4 1 0
6 6 5 1 0
6 6 6 1 0
6 6 7 1 0
6 6 8 1 0
6 6 9 1 0
6 6 10 1 0
6 6 11 1 0
6 6 12 1 0
6 6 13 1 32
6 7 2 2 64
6 7 3 2 0
6 7 4 2 0
6 7 5 2 0
6 7 6 2 0
6 7 7 2 0
6 7 8 2 0
6 7 9 2 0
6 7 10 2 0
6 7 11 2 0
6 7 12 2 0
6 7 13 2 32
6 8 2 1 64
6 8 3 1 0
6 8 4 1 0
6 8 5 1 0
6 8 6 1 0
6 8 7 1 0
6 8 8 1 0
6 8 9 1 0
6 8 10 1 0
6 8 11 1 0
6 8 12 1 0
6 8 13 1 32
6 9 2 1 64
6 9 3 1 0
6 9 4 1 0
6 9 5 1 0
6 9 6 1 0
6 9 7 1 0
6 9 8 1 0
6 9 9 1 0
6 9 10 1 0
6 9 11 1 0
6 9 12 1 0
6 9 13 1 32
6 10 2 1 64
6 10 3 1 0
6 10 4 1 0
6 10 5 1 0
6 10 6 1 0
6 10 7 1 0
6 10 8 1 0
6 10 9 1 0
6 10 10 1 0
6 10 11 1 0
6 10 12 1 0
6 10 13 1 32
6 11 2 1 76
6 11 3 1 0
6 11 4 1 0
6 11 5 1 0
6 11 6 1 0
6 11 7 1 0
6 11 8 1 0
6 11 9 1 0
6 11 10 1 0
6 11 11 1 0
6 11 12 1 0
6 11 13 1 44
6 12 3 1 76
6 12 4 1 8
6 12 5 1 8
6 12 6 1 8
6 12 7 1 8
6 12 8 1 8
6 12 9 1 8
6 12 10 1 8
6 12 11 1 8
6 12 12 1 44
6 15 5 1 126
6 15 7 1 94
6 15 8 1 62
6 15 10 1 126
7 0 2 1 80
7 0 3 1 16
7 0 4 1 16
7 0 5 1 16
7 0 6 1 16
7 0 7 1 16
7 0 8 1 16
7 0 9 1 16
7 0 10 1 16
7 0 11 1 16
7 0 12 1 16
7 0 13 1 48
7 1 2 2 64
7 1 3 2 0
7 1 4 2 0
7 1 5 2 0
7 1 6 2 0
7 1 7 2 0
7 1 8 2 0
7 1 9 2 0
7 1 10 2 0
7 1 11 2 0
7 1 12 2 0
7 1 13 2 32
7 2 2 3 64
7 2 3 3 0
7 2 4 3 0
7 2 5 3 0
7 2 6 3 0
7 2 7 3 0
7 2 8 3 0
7 2 9 3 0
7 2 10 3 0
7 2 11 3 0
7 2 12 3 0
7 2 13 3 32
7 3 2 3 64
7 3 3 3 0
7 3 4 3 0
7 3 5 3 0
7 3 6 3 0
7 3 7 3 0
7 3 8 3 0
7 3 9 3 0
7 3 10 3 0
7 3 11 3 0
7 3 12 3 0
7 3 13 3 32
7 4 2 2 64
7 4 3 2 0
7 4 4 2 0
7 4 5 2 0
7 4 6 2 0
7 4 7 2 0
7 4 8 2 0
7 4 9 2 0
7 4 10 2 0
7 4 11 2 0
7 4 12 2 0
7 4 13 2 32
7 5 2 2 64
7 5 3 2 0
7 5 4 2 0
7 5 5 2 0
7 5 6 2 0
7 5 7 2 0
7 5 8 2 0
7 5 9 2 0
7 5 10 2 0
7 5 11 2 0
7 5 12 2 0
7 5 13 2 32
7 6 2 2 64
7 6 3 2 0
7 6 4 2 0
7 6 5 2 0
7 6 6 2 0
7 6 7 2 0
7 6 8 2 0
7 6 9 2 0
7 6 10 2 0
7 6 11 2 0
7 6 12 2 0
7 6 13 2 32
7 7 2 1 64
7 7 3 1 0
7 7 4 1 0
7 7 5 1 0
7 7 6 1 0
7 7 7 1 0
7 7 8 1 0
7 7 9 1 0
7 7 10 1 0
7 7 11 1 0
7 7 12 1 0
7 7 13 1 32
7 8 2 1 64
7 8 3 1 0
7 8 4 1 0
7 8 5 1 0
7 8 6 1 0
7 8 7 1 0
7 8 8 1 0
7 8 9 1 0
7 8 10 1 0
7 8 11 1 0
7 8 12 1 0
7 8 13 1 32
7 9 2 1 64
7 9 3 1 0
7 9 4 1 0
7 9 5 1 0
7 9 6 1 0
7 9 7 1 0
7 9 8 1 0
7 9 9 1 0
7 9 10 1 0
7 9 11 1 0
7 9 12 1 0
7 9 13 1 32
7 10 2 1 64
7 10 3 1 0
7 10 4 1 0
7 10 5 1 0
7 10 6 1 0
7 10 7 1 0
7 10 8 1 0
7 10 9 1 0
7 10 10 1 0
7 10 11 1 0
7 10 12 1 0
7 10 13 1 32
7 11 2 1 64
7 11 3 1 0
7 11 4 1 0
7 11 5 1 0
7 11 6 1 0
7 11 7 1 0
7 11 8 1 0
7 11 9 1 0
7 11 10 1 0
7 11 11 1 0
7 11 12 1 0
7 11 13 1 32
7 12 2 1 78
7 12 3 1 0
7 12 4 1 0
7 12 5 1 0
7 12 6 1 0
7 12 7 1 0
7 12 8 1 0
7 12 9 1 0
7 12 10 1 0
7 12 11 1 0
7 12 12 1 0
7 12 13 1 46
7 13 3 1 78
7 13 4 1 4
7 13 5 1 14
7 13 6 1 4
7 13 7 1 14
7 13 8 1 14
7 13 9 1 4
7 13 10 1 14
7 13 11 1 4
7 13 12 1 46
7 14 4 1 110
7 14 6 1 110
7 14 9 1 110
7 14 11 1 110
8 0 2 1 80
8 0 3 1 16
8 0 4 1 16
8 0 5 1 16
8 0 6 1 16
8 0 7 1 16
8 0 8 1 16
8 0 9 1 16
8 0 10 1 16
8 0 11 1 16
8 0 12 1 16
8 0 13 1 48
8 1 2 2 64
8 1 3 2 0
8 1 4 2 0
8 1 5 2 0
8 1 6 2 0
8 1 7 2 0
8 1 8 2 0
8 1 9 2 0
8 1 10 2 0
8 1 11 2 0
8 1 12 2 0
8 1 13 2 32
8 2 2 3 64
8 2 3 3 0
8 2 4 3 0
8 2 5 3 0
8 2 6 3 0
8 2 7 3 0
8 2 8 3 0
8 2 9 3 0
8 2 10 3 0
8 2 11 3 0
8 2 12 3 0
8 2 13 3 32
8 3 2 3 64
8 3 3 3 0
8 3 4 3 0
8 3 5 3 0
8 3 6 3 0
8 3 7 3 0
8 3 8 3 0
8 3 9 3 0
8 3 10 3 0
8 3 11 3 0
8 3 12 3 0
8 3 13 3 32
8 4 2 3 64
8 4 3 3 0
8 4 4 3 0
8 4 5 3 0
8 4 6 3 0
8 4 7 3 0
8 4 8 3 0
8 4 9 3 0
8 4 10 3 0
8 4 11 3 0
8 4 12 3 0
8 4 13 3 32
8 5 2 3 64
8 5 3 3 0
8 5 4 3 0
8 5 5 3 0
8 5 6 3 0
8 5 7 3 0
8 5 8 3 0
8 5 9 3 0
8 5 10 3 0
8 5 11 3 0
8 5 12 3 0
8 5 13 3 32
8 6 2 2 64
8 6 3 2 0
8 6 4 2 0
8 6 5 2 0
8 6 6 2 0
8 6 7 2 0
8 6 8 2 0
8 6 9 2 0
8 6 10 2 0
8 6 11 2 0
8 6 12 2 0
8 6 13 2 32
8 7 2 2 64
8 7 3 2 0
8 7 4 2 0
8 7 5 2 0
8 7 6 2 0
8 7 7 2 0
8 7 8 2 0
8 7 9 2 0
8 7 10 2 0
8 7 11 2 0
8 7 12 2 0
8 7 13 2 32
8 8 2 2 64
8 8 3 2 0
8 8 4 2 0
8 8 5 2 0
8 8 6 2 0
8 8 7 2 0
8 8 8 2 0
8 8 9 2 0
8 8 10 2 0
8 8 11 2 0
8 8 12 2 0
8 8 13 2 32
8 9 2 1 64
8 9 3 1 0
8 9 4 1 0
8 9 5 1 0
8 9 6 1 0
8 9 7 1 0
8 9 8 1 0
8 9 9 1 0
8 9 10 1 0
8 9 11 1 0
8 9 12 1 0
8 9 13 1 32
8 10 2 1 64
8 10 3 1 0
8 10 4 1 0
8 10 5 1 0
8 10 6 1 0
8 10 7 1 0
8 10 8 1 0
8 10 9 1 0
8 10 10 1 0
8 10 11 1 0
8 10 12 1 0
8 10 13 1 32
8 11 2 1 72
8 11 3 1 0
8 11 4 1 0
8 11 5 1 0
8 11 6 1 0
8 11 7 1 0
8 11 8 1 0
8 11 9 1 0
8 11 10 1 0
8 11 11 1 0
8 11 12 1 0
8 11 13 1 40
8 12 3 1 72
8 12 4 1 0
8 12 5 1 10
8 12 6 1 0
8 12 7 1 10
8 12 8 1 10
8 12 9 1 0
8 12 10 1 10
8 12 11 1 0
8 12 12 1 40
8 13 4 1 106
8 13 6 1 106
8 13 9 1 106
8 13 11 1 106
9 0 2 1 82
9 0 3 1 16
9 0 4 1 16
9 0 5 1 16
9 0 6 1 16
9 0 7 1 16
9 0 8 1 16
9 0 9 1 16
9 0 10 1 16
9 0 11 1 16
9 0 12 1 16
9 0 13 1 50
9 1 2 2 64
9 1 3 2 0
9 1 4 2 0
9 1 5 2 0
9 1 6 2 0
9 1 7 2 0
9 1 8 2 0
9 1 9 2 0
9 1 10 2 0
9 1 11 2 0
9 1 12 2 0
9 1 13 2 32
9 2 2 3 64
9 2 3 3 0
9 2 4 3 0
9 2 5 3 0
9 2 6 3 0
9 2 7 3 0
9 2 8 3 0
9 2 9 3 0
9 2 10 3 0
9 2 11 3 0
9 2 12 3 0
9 2 13 3 32
9 3 2 3 64
9 3 3 3 0
9 3 4 3 0
9 3 5 3 0
9 3 6 3 0
9 3 7 3 0
9 3 8 3 0
9 3 9 3 0
9 3 10 3 0
9 3 11 3 0
9 3 12 3 0
9 3 13 3 32
9 4 2 2 64
9 4 3 2 0
9 4 4 2 0
9 4 5 2 0
9 4 6 2 0
9 4 7 2 0
9 4 8 2 0
9 4 9 2 0
9 4 10 2 0
9 4 11 2 0
9 4 12 2 0
9 4 13 2 32
9 5 2 2 64
9 5 3 2 0
9 5 4 2 0
9 5 5 2 0
9 5 6 2 0
9 5 7 2 0
9 5 8 2 0
9 5 9 2 0
9 5 10 2 0
9 5 11 2 0
9 5 12 2 0
9 5 13 2 32
9 6 2 2 64
9 6 3 2 0
9 6 4 2 0
9 6 5 2 0
9 6 6 2 0
9 6 7 2 0
9 6 8 2 0
9 6 9 2 0
9 6 10 2 0
9 6 11 2 0
9 6 12 2 0
9 6 13 2 32
9 7 2 1 64
9 7 3 1 0
9 7 4 1 0
9 7 5 1 0
9 7 6 1 0
9 7 7 1 0
9 7 8 1 0
9 7 9 1 0
9 7 10 1 0
9 7 11 1 0
9 7 12 1 0
9 7 13 1 32
9 8 2 1 64
9 8 3 1 0
9 8 4 1 0
9 8 5 1 0
9 8 6 1 0
9 8 7 1 0
9 8 8 1 0
9 8 9 1 0
9 8 10 1 0
9 8 11 1 0
9 8 12 1 0
9 8 13 1 32
9 9 2 1 64
9 9 3 1 0
9 9 4 1 0
9 9 5 1 0
9 9 6 1 0
9 9 7 1 0
9 9 8 1 0
9 9 9 1 0
9 9 10 1 0
9 9 11 1 0
9 9 12 1 0
9 9 13 1 32
9 10 2 2 64
9 10 3 2 0
9 10 4 2 0
9 10 5 2 0
9 10 6 2 0
9 10 7 2 0
9 10 8 2 0
9 10 9 2 0
9 10 10 2 0
9 10 11 2 0
9 10 12 2 0
9 10 13 2 32
9 11 2 1 66
9 11 3 1 0
9 11 4 1 0
9 11 5 1 8
9 11 6 1 0
9 11 7 1 10
9 11 8 1 10
9 11 9 1 0
9 11 10 1 8
9 11 11 1 0
9 11 12 1 0
9 11 13 1 34
9 12 2 1 78
9 12 3 1 10
9 12 4 1 42
9 12 6 1 106
9 12 9 1 106
9 12 11 1 74
9 12 12 1 10
9 12 13 1 46
10 0 3 1 82
10 0 4 1 18
10 0 5 1 18
10 0 6 1 18
10 0 7 1 18
10 0 8 1 18
10 0 9 1 18
10 0 10 1 18
10 0 11 1 18
10 0 12 1 50
10 1 2 1 80
10 1 3 1 0
10 1 4 1 0
10 1 5 1 0
10 1 6 1 0
10 1 7 1 0
10 1 8 1 0
10 1 9 1 0
10 1 10 1 0
10 1 11 1 0
10 1 12 1 0
10 1 13 1 48
10 2 2 2 64
10 2 3 2 0
10 2 4 2 0
10 2 5 2 0
10 2 6 2 0
10 2 7 2 0
10 2 8 2 0
10 2 9 2 0
10 2 10 2 0
10 2 11 2 0
10 2 12 2 0
10 2 13 2 32
10 3 2 2 64
10 3 3 2 0
10 3 4 2 0
10 3 5 2 0
10 3 6 2 0
10 3 7 2 0
10 3 8 2 0
10 3 9 2 0
10 3 10 2 0
10 3 11 2 0
10 3 12 2 0
10 3 13 2 32
10 4 2 3 64
10 4 3 3 0
10 4 4 3 0
10 4 5 3 0
10 4 6 3 0
10 4 7 3 0
10 4 8 3 0
10 4 9 3 0
10 4 10 3 0
10 4 11 3 0
10 4 12 3 0
10 4 13 3 32
10 5 2 2 64
10 5 3 2 0
10 5 4 2 0
10 5 5 2 0
10 5 6 2 0
10 5 7 2 0
10 5 8 2 0
10 5 9 2 0
10 5 10 2 0
10 5 11 2 0
10 5 12 2 0
10 5 13 2 32
10 6 2 2 64
10 6 3 2 0
10 6 4 2 0
10 6 5 2 0
10 6 6 2 0
10 6 7 2 0
10 6 8 2 0
10 6 9 2 0
10 6 10 2 0
10 6 11 2 0
10 6 12 2 0
10 6 13 2 32
10 7 2 2 64
10 7 3 2 0
10 7 4 2 0
10 7 5 2 0
10 7 6 2 0
10 7 7 2 0
10 7 8 2 0
10 7 9 2 0
10 7 10 2 0
10 7 11 2 0
10 7 12 2 0
10 7 13 2 32
10 8 2 2 64
10 8 3 2 0
10 8 4 2 0
10 8 5 2 0
10 8 6 2 0
10 8 7 2 0
10 8 8 2 0
10 8 9 2 0
10 8 10 2 0
10 8 11 2 0
10 8 12 2 0
10 8 13 2 32
10 9 2 2 64
10 9 3 2 0
10 9 4 2 0
10 9 5 2 0
10 9 6 2 0
10 9 7 2 0
10 9 8 2 0
10 9 9 2 0
10 9 10 2 0
10 9 11 2 0
10 9 12 2 0
10 9 13 2 32
10 10 2 1 72
10 10 3 1 0
10 10 4 1 0
10 10 5 1 0
10 10 6 1 0
10 10 7 1 8
10 10 8 1 8
10 10 9 1 0
10 10 10 1 0
10 10 11 1 0
10 10 12 1 0
10 10 13 1 40
10 11 3 1 72
10 11 4 1 8
10 11 5 1 8
10 11 6 1 40
10 11 9 1 72
10 11 10 1 8
10 11 11 1 8
10 11 12 1 40
10 14 3 1 126
10 14 5 1 126
10 14 7 1 94
10 14 8 1 62
10 14 10 1 126
10 14 12 1 126
11 1 2 1 80
11 1 3 1 16
11 1 4 1 16
11 1 5 1 16
11 1 6 1 16
11 1 7 1 16
11 1 8 1 16
11 1 9 1 16
11 1 10 1 16
11 1 11 1 16
11 1 12 1 16
11 1 13 1 50
11 2 2 2 64
11 2 3 2 0
11 2 4 2 0
11 2 5 2 0
11 2 6 2 0
11 2 7 2 0
11 2 8 2 0
11 2 9 2 0
11 2 10 2 0
11 2 11 2 0
11 2 12 2 0
11 2 13 2 32
11 3 2 2 64
11 3 3 2 0
11 3 4 2 0
11 3 5 2 0
11 3 6 2 0
11 3 7 2 0
11 3 8 2 0
11 3 9 2 0
11 3 10 2 0
11 3 11 2 0
11 3 12 2 0
11 3 13 2 32
11 4 2 2 64
11 4 3 2 0
11 4 4 2 0
11 4 5 2 0
11 4 6 2 0
11 4 7 2 0
11 4 8 2 0
11 4 9 2 0
11 4 10 2 0
11 4 11 2 0
11 4 12 2 0
11 4 13 2 32
11 5 2 1 64
11 5 3 1 0
11 5 4 1 0
11 5 5 1 0
11 5 6 1 0
11 5 7 1 0
11 5 8 1 0
11 5 9 1 0
11 5 10 1 0
11 5 11 1 0
11 5 12 1 0
11 5 13 1 32
11 6 2 2 64
11 6 3 2 0
11 6 4 2 0
11 6 5 2 0
11 6 6 2 0
11 6 7 2 0
11 6 8 2 0
11 6 9 2 0
11 6 10 2 0
11 6 11 2 0
11 6 12 2 0
11 6 13 2 32
11 7 2 2 64
11 7 3 2 0
11 7 4 2 0
11 7 5 2 0
11 7 6 2 0
11 7 7 2 0
11 7 8 2 0
11 7 9 2 0
11 7 10 2 0
11 7 11 2 0
11 7 12 2 0
11 7 13 2 32
11 8 2 1 64
11 8 3 1 0
11 8 4 1 0
11 8 5 1 0
11 8 6 1 0
11 8 7 1 0
11 8 8 1 0
11 8 9 1 0
11 8 10 1 0
11 8 11 1 0
11 8 12 1 0
11 8 13 1 32
11 9 2 1 64
11 9 3 1 0
11 9 4 1 0
11 9 5 1 0
11 9 6 1 0
11 9 7 1 0
11 9 8 1 0
11 9 9 1 0
11 9 10 1 0
11 9 11 1 0
11 9 12 1 0
11 9 13 1 32
11 10 2 1 66
11 10 3 1 0
11 10 4 1 2
11 10 5 1 2
11 10 6 1 2
11 10 7 1 2
11 10 8 1 2
11 10 9 1 2
11 10 10 1 2
11 10 11 1 2
11 10 12 1 0
11 10 13 1 34
11 11 2 1 78
11 11 3 1 10
11 11 4 1 2
11 11 5 1 2
11 11 6 1 2
11 11 7 1 6
11 11 8 1 6
11 11 9 1 2
11 11 10 1 2
11 11 11 1 2
11 11 12 1 10
11 11 13 1 46
11 12 4 1 78
11 12 5 1 6
11 12 6 1 14
11 12 7 1 6
11 12 8 1 6
11 12 9 1 14
11 12 10 1 6
11 12 11 1 46
11 13 5 1 110
11 13 7 1 78
11 13 8 1 46
11 13 10 1 110
12 1 2 1 82
12 1 3 1 16
12 1 4 1 16
12 1 5 1 16
12 1 6 1 16
12 1 7 1 16
12 1 8 1 16
12 1 9 1 16
12 1 10 1 16
12 1 11 1 16
12 1 12 1 48
12 1 13 1 126
12 2 2 1 64
12 2 3 1 0
12 2 4 1 0
12 2 5 1 0
12 2 6 1 0
12 2 7 1 0
12 2 8 1 0
12 2 9 1 0
12 2 10 1 0
12 2 11 1 0
12 2 12 1 0
12 2 13 1 50
12 3 2 1 64
12 3 3 1 0
12 3 4 1 0
12 3 5 1 0
12 3 6 1 0
12 3 7 1 0
12 3 8 1 0
12 3 9 1 0
12 3 10 1 0
12 3 11 1 0
12 3 12 1 0
12 3 13 1 32
12 4 2 2 64
12 4 3 2 0
12 4 4 2 0
12 4 5 2 0
12 4 6 2 0
12 4 7 2 0
12 4 8 2 0
12 4 9 2 0
12 4 10 2 0
12 4 11 2 0
12 4 12 2 0
12 4 13 2 32
12 5 2 2 64
12 5 3 2 0
12 5 4 2 0
12 5 5 2 0
12 5 6 2 0
12 5 7 2 0
12 5 8 2 0
12 5 9 2 0
12 5 10 2 0
12 5 11 2 0
12 5 12 2 0
12 5 13 2 32
12 6 2 2 64
12 6 3 2 0
12 6 4 2 0
12 6 5 2 0
12 6 6 2 0
12 6 7 2 0
12 6 8 2 0
12 6 9 2 0
12 6 10 2 0
12 6 11 2 0
12 6 12 2 0
12 6 13 2 32
12 7 2 1 64
12 7 3 1 0
12 7 4 1 0
12 7 5 1 0
12 7 6 1 0
12 7 7 1 0
12 7 8 1 0
12 7 9 1 0
12 7 10 1 0
12 7 11 1 0
12 7 12 1 0
12 7 13 1 32
12 8 2 1 64
12 8 3 1 0
12 8 4 1 0
12 8 5 1 0
12 8 6 1 0
12 8 7 1 0
12 8 8 1 0
12 8 9 1 0
12 8 10 1 0
12 8 11 1 0
12 8 12 1 0
12 8 13 1 32
12 9 2 1 74
12 9 3 1 0
12 9 4 1 8
12 9 5 1 8
12 9 6 1 8
12 9 7 1 8
12 9 8 1 8
12 9 9 1 8
12 9 10 1 8
12 9 11 1 8
12 9 12 1 0
12 9 13 1 42
12 10 3 1 106
12 10 12 1 106
12 14 4 2 126
12 14 6 2 126
12 14 9 2 126
12 14 11 2 126
13 1 3 1 82
13 1 4 1 18
13 1 5 1 18
13 1 6 1 18
13 1 7 1 18
13 1 8 1 18
13 1 9 1 18
13 1 10 1 18
13 1 11 1 18
13 1 12 1 50
13 2 2 1 82
13 2 3 1 0
13 2 4 1 0
13 2 5 1 0
13 2 6 1 0
13 2 7 1 0
13 2 8 1 0
13 2 9 1 0
13 2 10 1 0
13 2 11 1 0
13 2 12 1 32
13 2 13 1 126
13 3 2 1 64
13 3 3 1 0
13 3 4 1 0
13 3 5 1 0
13 3 6 1 0
13 3 7 1 0
13 3 8 1 0
13 3 9 1 0
13 3 10 1 0
13 3 11 1 0
13 3 12 1 0
13 3 13 1 50
13 4 2 1 66
13 4 3 1 2
13 4 4 1 0
13 4 5 1 0
13 4 6 1 0
13 4 7 1 0
13 4 8 1 0
13 4 9 1 0
13 4 10 1 0
13 4 11 1 0
13 4 12 1 2
13 4 13 1 34
13 5 2 1 66
13 5 3 1 0
13 5 4 1 0
13 5 5 1 0
13 5 6 1 0
13 5 7 1 0
13 5 8 1 0
13 5 9 1 0
13 5 10 1 0
13 5 11 1 0
13 5 12 1 0
13 5 13 1 34
13 6 2 1 64
13 6 3 1 0
13 6 4 1 0
13 6 5 1 0
13 6 6 1 0
13 6 7 1 0
13 6 8 1 0
13 6 9 1 0
13 6 10 1 0
13 6 11 1 0
13 6 12 1 0
13 6 13 1 32
13 7 2 1 66
13 7 3 1 0
13 7 4 1 0
13 7 5 1 0
13 7 6 1 0
13 7 7 1 0
13 7 8 1 0
13 7 9 1 0
13 7 10 1 0
13 7 11 1 0
13 7 12 1 0
13 7 13 1 34
13 8 2 1 74
13 8 3 1 2
13 8 4 1 0
13 8 5 1 0
13 8 6 1 0
13 8 7 1 2
13 8 8 1 0
13 8 9 1 0
13 8 10 1 0
13 8 11 1 0
13 8 12 1 2
13 8 13 1 42
13 9 3 1 74
13 9 4 1 2
13 9 5 1 0
13 9 6 1 0
13 9 7 1 0
13 9 8 1 2
13 9 9 1 0
13 9 10 1 0
13 9 11 1 2
13 9 12 1 42
13 10 4 1 78
13 10 5 1 14
13 10 6 1 12
13 10 7 1 14
13 10 8 1 14
13 10 9 1 12
13 10 10 1 14
13 10 11 1 46
13 12 2 1 94
13 12 3 1 62
13 12 5 1 126
13 12 7 1 94
13 12 8 1 62
13 12 10 1 126
13 12 12 1 94
13 12 13 1 62
13 13 4 1 126
13 13 6 1 126
13 13 9 1 126
13 13 11 1 126
14 2 3 1 82
14 2 4 1 18
14 2 5 1 18
14 2 6 1 18
14 2 7 1 18
14 2 8 1 18
14 2 9 1 18
14 2 10 1 18
14 2 11 1 18
14 2 12 1 50
14 3 2 1 90
14 3 3 1 10
14 3 4 1 2
14 3 5 1 2
14 3 6 1 2
14 3 7 1 2
14 3 8 1 2
14 3 9 1 2
14 3 10 1 2
14 3 11 1 2
14 3 12 1 42
14 4 4 1 66
14 4 5 1 0
14 4 6 1 2
14 4 7 1 0
14 4 8 1 0
14 4 9 1 2
14 4 10 1 0
14 4 11 1 34
14 5 3 1 82
14 5 4 1 0
14 5 5 1 0
14 5 6 1 0
14 5 7 1 2
14 5 8 1 2
14 5 9 1 0
14 5 10 1 0
14 5 11 1 0
14 5 12 1 50
14 6 2 0 90
14 6 3 0 2
14 6 4 0 2
14 6 5 0 0
14 6 6 0 2
14 6 7 0 0
14 6 8 0 0
14 6 9 0 2
14 6 10 0 0
14 6 11 0 2
14 6 12 0 2
14 6 13 0 58
14 7 3 1 74
14 7 4 1 2
14 7 5 1 2
14 7 6 1 2
14 7 7 1 10
14 7 8 1 2
14 7 9 1 2
14 7 10 1 2
14 7 11 1 2
14 7 12 1 42
14 8 4 1 74
14 8 5 1 2
14 8 6 1 34
14 8 8 1 74
14 8 9 1 2
14 8 10 1 2
14 8 11 1 42
14 9 5 1 74
14 9 6 1 2
14 9 7 1 58
14 9 9 1 66
14 9 10 1 42
14 10 6 2 106
14 10 9 2 106
15 4 5 1 114
15 4 7 1 90
15 4 8 1 58
15 4 10 1 114
15 5 4 1 90
15 5 5 1 2
15 5 6 1 58
15 5 9 1 90
15 5 10 1 2
15 5 11 1 58
15 6 5 1 106
15 6 7 1 90
15 6 8 1 58
15 6 10 1 106
