Qubicle Exchange Format
Version 0.2
www.minddesk.com
16 16 16
3
0.188235 0.313726 0.501961
0.250980 0.564706 0.752941
0.376471 0.815686 0.878431
4 1 7 0 84
4 1 8 0 52
4 2 7 0 68
4 2 8 0 36
4 3 7 0 76
4 3 8 0 44
5 0 6 0 84
5 0 7 0 20
5 0 8 0 20
5 0 9 0 52
5 1 6 0 68
5 1 7 0 0
5 1 8 0 0
5 1 9 0 36
5 2 6 0 68
5 2 7 0 0
5 2 8 0 0
5 2 9 0 36
5 3 6 0 68
5 3 7 0 0
5 3 8 0 0
5 3 9 0 36
5 4 6 0 76
5 4 7 0 12
5 4 8 0 12
5 4 9 0 44
6 0 5 0 84
6 0 6 0 16
6 0 7 0 16
6 0 8 0 16
6 0 9 0 16
6 0 10 0 52
6 1 5 0 68
6 1 6 0 0
6 1 7 0 0
6 1 8 0 0
6 1 9 0 0
6 1 10 0 36
6 2 5 0 68
6 2 6 0 0
6 2 7 0 0
6 2 8 0 0
6 2 9 0 0
6 2 10 0 36
6 3 5 0 68
6 3 6 0 0
6 3 7 0 0
6 3 8 0 0
6 3 9 0 0
6 3 10 0 36
6 4 5 0 76
6 4 6 0 0
6 4 7 0 0
6 4 8 0 0
6 4 9 0 0
6 4 10 0 44
6 5 6 0 76
6 5 7 0 4
6 5 8 0 4
6 5 9 0 44
6 6 7 0 76
6 6 8 0 44
7 0 5 0 80
7 0 6 0 16
7 0 7 0 16
7 0 8 0 16
7 0 9 0 16
7 0 10 0 48
7 1 4 0 84
7 1 5 0 0
7 1 6 0 0
7 1 7 0 0
7 1 8 0 0
7 1 9 0 0
7 1 10 0 0
7 1 11 0 52
7 2 4 0 68
7 2 5 0 0
7 2 6 0 0
7 2 7 0 0
7 2 8 0 0
7 2 9 0 0
7 2 10 0 0
7 2 11 0 36
7 3 4 0 76
7 3 5 0 0
7 3 6 0 0
7 3 7 0 0
7 3 8 0 0
7 3 9 0 0
7 3 10 0 0
7 3 11 0 44
7 4 5 0 72
7 4 6 0 0
7 4 7 0 0
7 4 8 0 0
7 4 9 0 0
7 4 10 0 40
7 5 6 0 64
7 5 7 0 0
7 5 8 0 0
7 5 9 0 32
7 6 6 0 76
7 6 7 0 0
7 6 8 0 0
7 6 9 0 44
7 7 7 0 76
7 7 8 0 44
8 0 5 0 80
8 0 6 0 16
8 0 7 0 16
8 0 8 0 16
8 0 9 0 16
8 0 10 0 48
8 1 4 0 82
8 1 5 0 0
8 1 6 0 0
8 1 7 0 0
8 1 8 0 0
8 1 9 0 0
8 1 10 0 0
8 1 11 0 50
8 2 4 0 66
8 2 5 0 0
8 2 6 0 0
8 2 7 0 0
8 2 8 0 0
8 2 9 0 0
8 2 10 0 0
8 2 11 0 34
8 3 4 0 74
8 3 5 0 0
8 3 6 0 0
8 3 7 0 0
8 3 8 0 0
8 3 9 0 0
8 3 10 0 0
8 3 11 0 42
8 4 5 0 72
8 4 6 0 0
8 4 7 0 0
8 4 8 0 0
8 4 9 0 0
8 4 10 0 40
8 5 6 0 64
8 5 7 2 0
8 5 8 2 0
8 5 9 2 32
8 6 6 0 74
8 6 7 2 0
8 6 8 2 0
8 6 9 2 42
8 7 7 0 74
8 7 8 1 42
9 0 5 0 82
9 0 6 0 16
9 0 7 0 16
9 0 8 0 16
9 0 9 0 16
9 0 10 0 50
9 1 5 0 66
9 1 6 0 0
9 1 7 0 0
9 1 8 0 0
9 1 9 0 0
9 1 10 0 34
9 2 5 0 66
9 2 6 0 0
9 2 7 0 0
9 2 8 0 0
9 2 9 0 0
9 2 10 0 34
9 3 5 0 66
9 3 6 0 0
9 3 7 0 0
9 3 8 0 0
9 3 9 0 0
9 3 10 0 34
9 4 5 0 74
9 4 6 2 0
9 4 7 2 0
9 4 8 2 0
9 4 9 2 0
9 4 10 2 42
9 5 6 0 74
9 5 7 0 2
9 5 8 1 126
9 5 9 1 42
9 6 7 0 74
9 6 8 1 42
10 0 6 0 82
10 0 7 0 18
10 0 8 0 18
10 0 9 0 50
10 1 6 0 66
10 1 7 0 0
10 1 8 0 0
10 1 9 0 34
10 2 6 0 66
10 2 7 0 0
10 2 8 0 0
10 2 9 0 34
10 3 6 0 66
10 3 7 0 0
10 3 8 0 0
10 3 9 0 34
10 4 6 0 74
10 4 7 0 10
10 4 8 0 10
10 4 9 0 42
11 1 7 0 82
11 1 8 0 50
11 2 7 0 66
11 2 8 0 34
11 3 7 0 74
11 3 8 0 42
