Qubicle Exchange Format
Version 0.2
www.minddesk.com
16 16 16
3
0.878431 0.313726 0.000000
1.000000 0.627451 0.000000
1.000000 1.000000 1.000000
2 4 8 0 84
2 4 9 0 20
2 4 10 0 52
2 5 7 0 84
2 5 8 0 4
2 5 9 0 4
2 5 10 0 4
2 5 11 0 52
2 6 7 0 76
2 6 8 0 12
2 6 9 0 12
2 6 10 0 4
2 6 11 0 44
2 7 10 0 108
2 15 5 1 92
2 15 6 1 60
3 0 5 0 126
3 0 6 0 126
3 0 7 0 126
3 0 8 0 126
3 1 4 0 126
3 1 5 0 126
3 1 6 0 126
3 2 5 0 126
3 2 6 0 126
3 2 13 1 124
3 3 8 1 86
3 3 9 0 22
3 3 10 0 54
3 3 14 2 116
3 4 7 1 84
3 4 8 0 2
3 4 9 0 2
3 4 10 0 2
3 4 11 0 22
3 4 12 0 54
3 4 13 2 22
3 4 14 2 100
3 5 6 0 84
3 5 7 0 2
3 5 8 0 2
3 5 9 0 2
3 5 10 0 2
3 5 11 0 2
3 5 12 0 38
3 5 13 2 30
3 5 14 2 78
3 5 15 2 60
3 6 6 0 68
3 6 7 0 2
3 6 8 0 2
3 6 9 0 2
3 6 10 0 2
3 6 11 0 2
3 6 12 0 44
3 7 6 0 78
3 7 7 0 6
3 7 8 0 6
3 7 9 0 6
3 7 10 0 2
3 7 11 0 44
3 8 7 0 68
3 8 8 0 6
3 8 9 0 6
3 8 10 0 44
3 9 7 0 78
3 9 8 0 14
3 9 9 0 46
3 15 5 1 88
3 15 6 1 56
4 0 5 0 86
4 0 6 0 20
4 0 7 0 28
4 0 8 0 62
4 1 4 0 94
4 1 5 0 6
4 1 6 0 38
4 2 5 0 78
4 2 6 0 38
4 2 13 1 120
4 3 6 1 68
4 3 7 1 52
4 3 14 2 114
4 4 5 0 84
4 4 6 1 6
4 4 7 1 42
4 4 11 0 126
4 4 12 0 126
4 4 13 2 126
4 4 14 2 104
4 5 5 1 68
4 5 6 0 34
4 5 13 2 126
4 5 14 2 126
4 5 15 2 112
4 6 5 1 68
4 6 6 1 42
4 6 12 0 120
4 6 15 2 108
4 7 5 1 108
4 7 11 0 112
4 8 6 1 84
4 8 7 0 56
4 8 10 2 82
4 8 11 0 126
4 8 12 0 126
4 8 13 2 126
4 9 6 1 108
4 9 10 2 68
4 9 11 2 36
4 9 12 2 126
4 9 13 2 126
4 10 7 0 92
4 10 8 0 22
4 10 9 0 22
4 10 10 0 4
4 10 11 0 36
4 11 8 0 76
4 11 9 0 12
4 11 10 0 12
4 11 11 0 44
4 14 6 1 84
4 14 7 1 60
4 15 5 1 88
4 15 6 1 40
5 0 5 0 126
5 0 6 0 90
5 0 7 0 58
5 0 8 0 126
5 1 4 0 126
5 1 5 0 126
5 1 6 0 126
5 2 5 0 126
5 2 6 0 126
5 2 13 1 112
5 3 5 1 84
5 3 6 1 24
5 3 7 1 58
5 3 13 1 108
5 4 4 0 84
5 4 5 1 34
5 4 11 0 126
5 4 12 0 126
5 4 14 2 120
5 5 4 1 68
5 5 5 1 34
5 5 12 0 126
5 5 13 1 126
5 5 14 0 126
5 5 15 2 114
5 6 4 1 68
5 6 5 1 34
5 6 12 1 114
5 6 15 2 106
5 7 4 1 76
5 7 5 1 34
5 7 11 1 82
5 7 12 1 36
5 8 5 1 68
5 8 6 1 16
5 8 7 0 58
5 8 11 1 66
5 8 12 1 36
5 9 5 1 76
5 9 6 1 34
5 9 10 2 82
5 9 11 2 2
5 9 12 2 38
5 9 13 2 126
5 10 6 0 76
5 10 7 0 50
5 10 10 2 66
5 10 11 2 2
5 10 12 2 38
5 10 13 2 126
5 11 7 0 78
5 11 8 0 18
5 11 9 0 18
5 11 10 0 2
5 11 11 0 8
5 11 12 0 44
5 12 8 0 78
5 12 9 0 12
5 12 10 0 44
5 14 6 1 82
5 14 7 1 18
5 14 8 1 62
5 15 5 1 90
5 15 6 1 10
5 15 7 1 46
6 2 5 1 84
6 2 6 1 52
6 2 13 1 112
6 3 4 1 84
6 3 5 1 8
6 3 6 1 42
6 3 13 1 96
6 4 3 0 84
6 4 4 1 34
6 4 12 0 126
6 4 13 0 68
6 4 14 0 56
6 5 3 1 68
6 5 4 1 34
6 5 12 1 92
6 5 13 1 36
6 6 3 1 68
6 6 4 1 34
6 6 13 1 108
6 7 3 1 76
6 7 4 1 34
6 7 12 1 112
6 8 4 1 68
6 8 5 1 18
6 8 6 1 58
6 8 12 1 72
6 8 13 0 52
6 9 4 1 76
6 9 5 1 34
6 9 13 2 100
6 10 5 1 76
6 10 6 0 50
6 10 13 2 108
6 11 6 0 108
6 11 11 0 82
6 11 12 0 50
6 12 7 0 124
6 12 9 0 82
6 12 10 0 18
6 12 11 2 6
6 12 12 2 44
6 13 8 0 92
6 13 9 0 4
6 13 10 0 6
6 13 11 0 44
6 13 12 0 126
6 14 9 0 76
6 14 10 0 44
7 2 5 1 80
7 2 6 1 24
7 2 7 1 60
7 2 13 1 112
7 3 4 1 88
7 3 5 1 40
7 3 13 0 64
7 3 14 0 52
7 4 3 0 112
7 4 13 0 64
7 4 14 0 32
7 5 3 1 96
7 5 12 1 80
7 5 13 0 0
7 5 14 0 44
7 6 3 1 96
7 6 12 1 68
7 6 13 1 40
7 7 3 1 104
7 7 12 1 96
7 8 4 1 112
7 8 12 1 72
7 8 13 0 48
7 9 4 1 104
7 9 13 2 96
7 10 5 1 120
7 10 7 0 124
7 10 13 2 96
7 11 6 0 120
7 11 13 1 108
7 12 7 0 120
7 12 12 2 112
7 13 8 0 80
7 13 9 0 48
7 13 11 0 80
7 13 12 0 44
7 14 8 0 76
7 14 9 0 8
7 14 10 0 24
7 14 11 0 44
8 2 5 1 80
8 2 6 1 16
8 2 7 1 18
8 2 8 1 30
8 2 9 1 30
8 2 10 1 30
8 2 11 1 22
8 2 12 1 20
8 2 13 1 48
8 3 4 1 80
8 3 5 1 0
8 3 6 1 6
8 3 7 1 46
8 3 11 1 78
8 3 12 1 14
8 3 13 0 0
8 3 14 0 48
8 4 3 0 80
8 4 4 1 6
8 4 5 1 6
8 4 6 1 38
8 4 13 2 64
8 4 14 2 32
8 5 3 1 64
8 5 4 1 6
8 5 5 1 6
8 5 6 1 38
8 5 12 1 80
8 5 13 0 0
8 5 14 0 40
8 6 3 1 64
8 6 4 1 6
8 6 5 1 6
8 6 6 1 38
8 6 12 1 64
8 6 13 1 40
8 7 3 1 72
8 7 4 1 6
8 7 5 1 6
8 7 6 1 6
8 7 7 1 22
8 7 8 1 54
8 7 12 1 96
8 8 4 1 64
8 8 5 1 6
8 8 6 1 6
8 8 7 0 6
8 8 8 0 6
8 8 9 2 22
8 8 10 0 22
8 8 11 0 22
8 8 12 0 0
8 8 13 0 48
8 9 4 1 72
8 9 5 0 6
8 9 6 0 6
8 9 7 0 6
8 9 8 0 6
8 9 9 2 6
8 9 10 2 6
8 9 11 2 6
8 9 12 2 6
8 9 13 2 32
8 10 5 1 72
8 10 6 0 6
8 10 7 0 2
8 10 8 0 6
8 10 9 0 6
8 10 10 2 6
8 10 11 2 6
8 10 12 2 6
8 10 13 2 32
8 11 6 0 72
8 11 7 0 6
8 11 8 0 6
8 11 9 0 6
8 11 10 0 6
8 11 11 0 6
8 11 12 0 6
8 11 13 1 32
8 12 7 0 72
8 12 8 0 6
8 12 9 0 6
8 12 10 0 6
8 12 11 2 6
8 12 12 2 0
8 12 13 0 46
8 13 8 0 64
8 13 9 0 0
8 13 10 0 6
8 13 11 0 0
8 13 12 0 40
8 14 8 0 72
8 14 9 0 8
8 14 10 0 8
8 14 11 0 40
9 2 5 1 80
9 2 6 1 56
9 2 12 1 88
9 2 13 1 48
9 3 4 1 88
9 3 5 1 40
9 3 13 0 64
9 3 14 0 50
9 4 3 0 112
9 4 13 0 64
9 4 14 0 32
9 5 3 1 96
9 5 12 1 80
9 5 13 0 0
9 5 14 0 42
9 6 3 1 96
9 6 12 1 64
9 6 13 1 40
9 7 3 1 104
9 7 12 1 96
9 8 4 1 112
9 8 12 0 72
9 8 13 0 48
9 9 4 1 104
9 9 13 2 96
9 10 5 1 120
9 10 13 2 96
9 11 6 0 120
9 11 13 1 106
9 12 7 0 120
9 12 12 2 112
9 13 8 0 80
9 13 9 0 48
9 13 11 0 80
9 13 12 0 42
9 14 8 0 74
9 14 9 0 8
9 14 10 0 24
9 14 11 0 42
10 0 11 0 126
10 0 12 0 126
10 0 13 0 126
10 0 14 0 126
10 0 15 0 126
10 1 13 0 126
10 1 14 0 126
10 2 5 1 82
10 2 6 1 48
10 2 12 1 88
10 2 13 1 48
10 3 4 1 82
10 3 5 1 0
10 3 6 1 36
10 3 13 1 96
10 4 3 0 82
10 4 4 1 4
10 4 5 1 12
10 4 6 1 44
10 4 13 0 64
10 4 14 0 56
10 5 3 1 66
10 5 4 1 36
10 5 12 1 80
10 5 13 1 32
10 6 3 1 66
10 6 4 1 36
10 6 12 1 64
10 6 13 1 40
10 7 3 1 74
10 7 4 1 36
10 7 12 1 96
10 8 4 1 66
10 8 5 1 52
10 8 12 1 72
10 8 13 0 50
10 9 4 1 74
10 9 5 1 36
10 9 13 2 98
10 10 5 1 106
10 10 13 2 106
10 11 6 0 122
10 11 12 0 116
10 12 7 0 90
10 12 8 0 20
10 12 9 0 20
10 12 10 0 20
10 12 11 2 22
10 12 12 2 42
10 13 8 0 74
10 13 9 0 2
10 13 10 0 6
10 13 11 0 42
10 13 12 0 126
10 14 9 0 74
10 14 10 0 42
11 0 11 0 126
11 0 12 0 126
11 0 13 0 126
11 0 14 0 126
11 0 15 0 126
11 1 13 0 126
11 1 14 0 126
11 2 6 1 114
11 2 12 1 88
11 2 13 1 48
11 3 5 1 82
11 3 6 1 0
11 3 7 1 20
11 3 8 1 52
11 3 13 1 96
11 4 4 0 82
11 4 5 1 0
11 4 6 1 10
11 4 7 1 12
11 4 8 1 46
11 4 12 0 84
11 4 13 0 0
11 4 14 0 58
11 5 4 1 66
11 5 5 1 36
11 5 12 1 64
11 5 13 1 32
11 6 4 1 66
11 6 5 1 36
11 6 12 1 64
11 6 13 1 42
11 7 4 1 74
11 7 5 1 36
11 7 11 1 126
11 7 12 1 98
11 8 5 1 66
11 8 6 1 52
11 8 10 2 116
11 8 12 1 98
11 9 5 1 74
11 9 6 1 36
11 9 9 2 84
11 9 10 2 36
11 9 12 2 102
11 9 13 2 126
11 10 6 0 78
11 10 7 0 20
11 10 8 0 20
11 10 9 0 4
11 10 10 2 4
11 10 11 2 20
11 10 12 2 38
11 10 13 2 126
11 11 7 0 78
11 11 8 0 4
11 11 9 0 4
11 11 10 0 4
11 11 11 0 12
11 11 12 0 42
11 12 8 0 74
11 12 9 0 10
11 12 10 0 42
11 14 6 1 84
11 14 7 1 20
11 14 8 1 62
11 15 5 1 92
11 15 6 1 12
11 15 7 1 46
12 0 11 0 94
12 0 12 0 30
12 0 13 0 22
12 0 14 0 22
12 0 15 0 62
12 1 13 0 70
12 1 14 0 46
12 2 7 1 86
12 2 8 1 22
12 2 9 1 22
12 2 10 1 22
12 2 11 1 22
12 2 12 1 18
12 2 13 1 34
12 3 6 1 90
12 3 7 1 0
12 3 8 1 8
12 3 9 1 12
12 3 10 1 12
12 3 11 1 12
12 3 12 1 4
12 3 13 1 32
12 4 5 0 114
12 4 7 1 104
12 4 12 0 64
12 4 13 0 32
12 5 5 1 64
12 5 6 0 52
12 5 11 1 92
12 5 12 1 0
12 5 13 1 42
12 6 5 1 64
12 6 6 1 36
12 6 12 1 106
12 7 5 1 74
12 7 6 1 36
12 7 11 1 126
12 8 6 1 66
12 8 7 0 52
12 8 9 2 86
12 8 10 0 126
12 8 11 0 126
12 8 12 0 126
12 8 13 2 126
12 9 6 1 74
12 9 7 0 36
12 9 9 2 66
12 9 10 2 2
12 9 11 2 38
12 9 12 2 126
12 9 13 2 126
12 10 7 0 74
12 10 8 0 18
12 10 9 0 2
12 10 10 0 2
12 10 11 0 34
12 11 8 0 74
12 11 9 0 10
12 11 10 0 10
12 11 11 0 42
12 14 6 1 82
12 14 7 1 58
12 15 5 1 88
12 15 6 1 40
13 3 7 1 82
13 3 8 1 26
13 3 9 1 26
13 3 10 1 26
13 3 11 1 18
13 3 12 1 18
13 3 13 1 50
13 4 6 1 86
13 4 7 1 32
13 4 11 0 68
13 4 12 0 2
13 4 13 0 42
13 5 5 0 82
13 5 6 0 0
13 5 7 0 4
13 5 8 0 28
13 5 9 2 20
13 5 10 1 20
13 5 11 1 0
13 5 12 1 42
13 6 5 0 74
13 6 6 1 0
13 6 7 1 36
13 6 9 1 68
13 6 10 1 4
13 6 11 1 46
13 7 6 1 72
13 7 7 1 36
13 7 9 0 126
13 7 10 0 126
13 8 7 0 66
13 8 8 0 52
13 9 7 0 74
13 9 8 0 46
13 15 5 1 88
13 15 6 1 58
14 4 7 2 82
14 4 8 2 22
14 4 9 2 22
14 4 10 2 22
14 4 11 1 50
14 5 6 0 82
14 5 7 2 2
14 5 8 2 2
14 5 9 2 2
14 5 10 2 2
14 5 11 0 42
14 6 6 0 66
14 6 7 2 2
14 6 8 2 6
14 6 9 2 2
14 6 10 0 126
14 7 6 0 74
14 7 7 0 10
14 7 8 0 6
14 7 9 0 126
14 8 8 0 106
14 15 5 1 122
