Qubicle Exchange Format
Version 0.2
www.minddesk.com
16 16 16
2
0.156863 0.000000 0.721569
0.313726 0.501961 1.000000
0 0 0 0 94
0 0 1 0 22
0 0 2 0 22
0 0 3 0 62
0 1 1 0 76
0 1 2 0 44
1 1 0 0 86
1 1 1 0 18
1 1 2 0 18
1 1 3 0 54
1 2 0 0 76
1 2 1 0 4
1 2 2 0 4
1 2 3 0 44
1 3 1 0 76
1 3 2 0 44
2 2 0 0 80
2 2 1 0 16
2 2 2 0 16
2 2 3 0 50
2 3 0 0 68
2 3 1 0 0
2 3 2 0 0
2 3 3 0 36
2 4 0 0 76
2 4 1 0 4
2 4 2 0 4
2 4 3 0 44
2 5 1 0 76
2 5 2 0 44
3 1 0 0 86
3 1 1 0 22
3 1 2 0 22
3 1 3 0 62
3 2 0 0 64
3 2 1 0 0
3 2 2 0 32
3 2 3 0 32
3 3 0 0 64
3 3 1 0 0
3 3 2 0 0
3 3 3 0 50
3 4 0 0 64
3 4 1 0 0
3 4 2 0 0
3 4 3 0 32
3 5 0 0 76
3 5 1 0 0
3 5 2 0 0
3 5 3 0 44
3 6 1 0 76
3 6 2 0 44
4 2 0 0 80
4 2 1 0 16
4 2 2 0 16
4 2 3 0 60
4 3 0 0 64
4 3 1 0 0
4 3 2 0 32
4 3 3 0 32
4 4 0 0 64
4 4 1 0 0
4 4 2 0 0
4 4 3 0 48
4 5 0 0 64
4 5 1 0 0
4 5 2 0 0
4 5 3 0 32
4 6 0 0 70
4 6 1 0 2
4 6 2 0 2
4 6 3 0 46
4 7 0 0 78
4 7 1 0 14
4 7 2 0 46
4 7 3 0 46
5 1 0 0 84
5 1 1 0 20
5 1 2 0 20
5 1 3 0 52
5 2 0 0 64
5 2 1 0 0
5 2 2 0 0
5 2 3 0 32
5 3 0 0 64
5 3 1 0 0
5 3 2 0 0
5 3 3 0 36
5 4 0 0 64
5 4 1 0 0
5 4 2 0 0
5 4 3 0 32
5 5 0 0 72
5 5 1 0 8
5 5 2 0 126
5 5 3 0 40
6 0 0 0 86
6 0 1 0 22
6 0 2 0 22
6 0 3 0 54
6 1 0 0 64
6 1 1 0 0
6 1 2 0 0
6 1 3 0 32
6 2 0 0 64
6 2 1 0 0
6 2 2 0 0
6 2 3 0 32
6 3 0 0 64
6 3 1 0 0
6 3 2 0 0
6 3 3 0 32
6 4 0 0 126
6 4 1 0 0
6 4 2 0 0
6 4 3 0 32
6 5 0 0 126
6 5 1 1 0
6 5 2 1 0
6 5 3 1 32
6 6 0 0 126
6 6 1 0 126
6 6 2 0 126
6 6 3 1 38
6 7 0 0 78
6 7 1 0 14
6 7 2 0 14
6 7 3 0 46
7 1 0 0 80
7 1 1 0 16
7 1 2 0 16
7 1 3 0 48
7 2 0 0 64
7 2 1 0 0
7 2 2 0 0
7 2 3 0 32
7 3 0 0 64
7 3 1 0 0
7 3 2 0 0
7 3 3 0 32
7 4 0 0 64
7 4 1 0 0
7 4 2 0 0
7 4 3 0 32
7 5 0 0 64
7 5 1 0 0
7 5 2 0 0
7 5 3 0 40
7 6 0 0 72
7 6 1 0 8
7 6 2 0 40
7 6 3 0 40
8 1 0 0 80
8 1 1 0 16
8 1 2 0 16
8 1 3 0 48
8 2 0 0 64
8 2 1 0 0
8 2 2 0 0
8 2 3 0 32
8 3 0 0 64
8 3 1 0 0
8 3 2 0 0
8 3 3 0 32
8 4 0 0 64
8 4 1 0 0
8 4 2 0 0
8 4 3 0 32
8 5 0 0 64
8 5 1 0 0
8 5 2 0 0
8 5 3 0 40
8 6 0 0 72
8 6 1 0 8
8 6 2 0 40
8 6 3 0 44
9 0 0 0 86
9 0 1 0 22
9 0 2 0 22
9 0 3 0 54
9 1 0 0 64
9 1 1 0 0
9 1 2 0 0
9 1 3 0 32
9 2 0 0 64
9 2 1 0 0
9 2 2 0 0
9 2 3 0 32
9 3 0 0 64
9 3 1 0 0
9 3 2 0 0
9 3 3 0 32
9 4 0 0 64
9 4 1 0 0
9 4 2 0 0
9 4 3 0 32
9 5 0 0 126
9 5 1 1 0
9 5 2 1 0
9 5 3 1 32
9 6 0 0 126
9 6 1 0 126
9 6 2 0 126
9 6 3 1 38
9 7 0 0 78
9 7 1 0 14
9 7 2 0 126
9 7 3 0 46
10 1 0 0 82
10 1 1 0 18
10 1 2 0 18
10 1 3 0 50
10 2 0 0 64
10 2 1 0 0
10 2 2 0 0
10 2 3 0 32
10 3 0 0 64
10 3 1 0 0
10 3 2 0 0
10 3 3 0 32
10 4 0 0 64
10 4 1 0 0
10 4 2 0 0
10 4 3 0 32
10 5 0 0 72
10 5 1 0 8
10 5 2 0 8
10 5 3 0 40
11 2 0 0 80
11 2 1 0 16
11 2 2 0 16
11 2 3 0 48
11 3 0 0 64
11 3 1 0 0
11 3 2 0 0
11 3 3 0 32
11 4 0 0 64
11 4 1 0 0
11 4 2 0 0
11 4 3 0 32
11 5 0 0 64
11 5 1 0 0
11 5 2 0 0
11 5 3 0 32
11 6 0 0 70
11 6 1 0 4
11 6 2 0 4
11 6 3 0 46
11 7 0 0 78
11 7 1 0 14
11 7 2 0 46
11 7 3 0 46
12 1 0 0 86
12 1 1 0 22
12 1 2 0 22
12 1 3 0 54
12 2 0 0 64
12 2 1 0 0
12 2 2 0 0
12 2 3 0 32
12 3 0 0 64
12 3 1 0 0
12 3 2 0 0
12 3 3 0 32
12 4 0 0 64
12 4 1 0 0
12 4 2 0 0
12 4 3 0 32
12 5 0 0 74
12 5 1 0 0
12 5 2 0 0
12 5 3 0 42
12 6 1 0 74
12 6 2 0 42
13 2 0 0 80
13 2 1 0 16
13 2 2 0 16
13 2 3 0 48
13 3 0 0 66
13 3 1 0 0
13 3 2 0 0
13 3 3 0 34
13 4 0 0 74
13 4 1 0 2
13 4 2 0 2
13 4 3 0 42
13 5 1 0 74
13 5 2 0 42
14 1 0 0 86
14 1 1 0 20
14 1 2 0 20
14 1 3 0 54
14 2 0 0 74
14 2 1 0 2
14 2 2 0 2
14 2 3 0 42
14 3 1 0 74
14 3 2 0 42
15 0 0 0 94
15 0 1 0 22
15 0 2 0 22
15 0 3 0 62
15 1 1 0 74
15 1 2 0 42
