Qubicle Exchange Format
Version 0.2
www.minddesk.com
16 16 16
2
0.156863 0.000000 0.721569
0.313726 0.501961 1.000000
3 3 0 0 126
3 3 1 0 126
3 3 2 0 126
3 3 3 0 126
3 4 0 0 126
3 4 1 0 126
3 4 2 0 126
3 4 3 0 126
3 5 1 0 126
3 5 3 0 126
4 1 0 0 126
4 1 1 0 126
4 1 2 0 126
4 1 3 0 126
4 2 0 0 126
4 2 1 0 126
4 2 2 0 126
4 2 3 0 126
4 3 0 0 126
4 3 1 0 126
4 3 2 0 126
4 3 3 0 126
4 4 0 0 126
4 4 1 0 126
4 4 2 0 126
4 4 3 0 126
4 5 0 0 126
4 5 1 0 126
4 5 2 0 126
4 5 3 0 126
4 6 0 0 126
4 6 1 0 126
4 6 2 0 126
4 6 3 0 126
4 7 1 0 126
4 7 2 0 126
5 0 0 0 126
5 0 1 0 126
5 0 2 0 126
5 0 3 0 126
5 1 0 0 126
5 1 1 0 126
5 1 2 0 126
5 1 3 0 126
5 2 0 0 126
5 2 1 0 126
5 2 2 0 126
5 2 3 0 126
5 3 0 0 126
5 3 1 0 126
5 3 2 0 126
5 3 3 0 126
5 4 0 0 126
5 4 1 0 126
5 4 2 0 126
5 4 3 0 126
5 5 0 0 126
5 5 1 0 126
5 5 2 0 126
5 5 3 0 126
5 6 0 0 126
5 6 1 0 126
5 6 2 0 126
5 6 3 0 126
5 7 0 0 126
5 7 1 0 126
5 7 2 0 126
5 7 3 0 126
5 8 0 0 126
5 8 1 0 126
5 8 2 0 126
5 8 3 0 126
5 9 1 0 126
5 9 2 0 126
6 2 0 0 126
6 2 1 0 126
6 2 2 0 126
6 2 3 0 126
6 3 0 0 126
6 3 1 0 126
6 3 2 0 126
6 3 3 0 126
6 4 0 0 126
6 4 1 0 126
6 4 2 0 126
6 4 3 0 126
6 5 0 0 126
6 5 1 0 126
6 5 2 0 126
6 5 3 0 126
6 6 0 0 126
6 6 1 0 126
6 6 2 0 126
6 6 3 0 126
6 7 0 0 126
6 7 1 1 126
6 7 2 1 126
6 7 3 1 126
6 8 0 0 126
6 8 1 1 126
6 8 2 1 126
6 8 3 1 126
6 9 0 0 126
6 9 1 0 126
6 9 2 0 126
6 9 3 0 126
7 3 0 0 126
7 3 1 0 126
7 3 2 0 126
7 3 3 0 126
7 4 0 0 126
7 4 1 0 126
7 4 2 0 126
7 4 3 0 126
7 5 0 0 126
7 5 1 0 126
7 5 2 0 126
7 5 3 0 126
7 6 0 0 126
7 6 1 0 126
7 6 2 0 126
7 6 3 0 126
7 7 0 0 126
7 7 1 0 126
7 7 2 0 126
7 7 3 0 126
7 8 0 0 126
7 8 1 0 126
7 8 2 0 126
7 8 3 0 126
8 3 0 0 126
8 3 1 0 126
8 3 2 0 126
8 3 3 0 126
8 4 0 0 126
8 4 1 0 126
8 4 2 0 126
8 4 3 0 126
8 5 0 0 126
8 5 1 0 126
8 5 2 0 126
8 5 3 0 126
8 6 0 0 126
8 6 1 0 126
8 6 2 0 126
8 6 3 0 126
8 7 0 0 126
8 7 1 0 126
8 7 2 0 126
8 7 3 0 126
8 8 0 0 126
8 8 1 0 126
8 8 2 0 126
8 8 3 0 126
9 2 0 0 126
9 2 1 0 126
9 2 2 0 126
9 2 3 0 126
9 3 0 0 126
9 3 1 0 126
9 3 2 0 126
9 3 3 0 126
9 4 0 0 126
9 4 1 0 126
9 4 2 0 126
9 4 3 0 126
9 5 0 0 126
9 5 1 0 126
9 5 2 0 126
9 5 3 0 126
9 6 0 0 126
9 6 1 0 126
9 6 2 0 126
9 6 3 0 126
9 7 0 0 126
9 7 1 1 126
9 7 2 1 126
9 7 3 1 126
9 8 0 0 126
9 8 1 1 126
9 8 2 1 126
9 8 3 1 126
9 9 0 0 126
9 9 1 0 126
9 9 2 0 126
9 9 3 0 126
10 0 0 0 126
10 0 1 0 126
10 0 2 0 126
10 0 3 0 126
10 1 0 0 126
10 1 1 0 126
10 1 2 0 126
10 1 3 0 126
10 2 0 0 126
10 2 1 0 126
10 2 2 0 126
10 2 3 0 126
10 3 0 0 126
10 3 1 0 126
10 3 2 0 126
10 3 3 0 126
10 4 0 0 126
10 4 1 0 126
10 4 2 0 126
10 4 3 0 126
10 5 0 0 126
10 5 1 0 126
10 5 2 0 126
10 5 3 0 126
10 6 0 0 126
10 6 1 0 126
10 6 2 0 126
10 6 3 0 126
10 7 0 0 126
10 7 1 0 126
10 7 2 0 126
10 7 3 0 126
10 8 0 0 126
10 8 1 0 126
10 8 2 0 126
10 8 3 0 126
10 9 1 0 126
10 9 2 0 126
11 1 0 0 126
11 1 1 0 126
11 1 2 0 126
11 1 3 0 126
11 2 0 0 126
11 2 1 0 126
11 2 2 0 126
11 2 3 0 126
11 3 0 0 126
11 3 1 0 126
11 3 2 0 126
11 3 3 0 126
11 4 0 0 126
11 4 1 0 126
11 4 2 0 126
11 4 3 0 126
11 5 0 0 126
11 5 1 0 126
11 5 2 0 126
11 5 3 0 126
11 6 0 0 126
11 6 1 0 126
11 6 2 0 126
11 6 3 0 126
11 7 1 0 126
11 7 2 0 126
12 3 0 0 126
12 3 1 0 126
12 3 2 0 126
12 3 3 0 126
12 4 0 0 126
12 4 1 0 126
12 4 2 0 126
12 4 3 0 126
12 5 1 0 126
12 5 2 0 126
