Qubicle Exchange Format
Version 0.2
www.minddesk.com
16 16 16
1
1.000000 0.627451 0.000000
2 1 7 0 92
2 1 8 0 60
3 1 6 0 94
3 1 7 0 26
3 1 8 0 26
3 1 9 0 62
4 0 5 0 92
4 0 6 0 60
4 0 9 0 92
4 0 10 0 60
4 2 5 0 124
4 2 7 0 92
4 2 8 0 60
4 2 10 0 124
5 0 4 0 92
5 0 5 0 16
5 0 6 0 48
5 0 9 0 80
5 0 10 0 16
5 0 11 0 60
5 1 5 0 68
5 1 6 0 12
5 1 7 0 20
5 1 8 0 20
5 1 9 0 12
5 1 10 0 36
5 2 4 0 94
5 2 5 0 42
5 2 7 0 74
5 2 8 0 42
5 2 10 0 74
5 2 11 0 62
6 0 4 0 90
6 0 5 0 18
6 0 6 0 50
6 0 9 0 82
6 0 10 0 18
6 0 11 0 58
6 1 3 0 124
6 1 5 0 72
6 1 6 0 8
6 1 7 0 24
6 1 8 0 24
6 1 9 0 8
6 1 10 0 40
6 1 12 0 124
6 3 7 0 92
6 3 8 0 60
7 1 2 0 92
7 1 3 0 56
7 1 5 0 80
7 1 6 0 24
7 1 7 0 16
7 1 8 0 16
7 1 9 0 24
7 1 10 0 48
7 1 12 0 88
7 1 13 0 60
7 2 4 0 92
7 2 5 0 44
7 2 7 0 68
7 2 8 0 36
7 2 10 0 76
7 2 11 0 60
7 3 6 0 92
7 3 7 0 8
7 3 8 0 8
7 3 9 0 60
8 1 2 0 90
8 1 3 0 56
8 1 5 0 80
8 1 6 0 24
8 1 7 0 16
8 1 8 0 16
8 1 9 0 24
8 1 10 0 48
8 1 12 0 88
8 1 13 0 58
8 2 4 0 90
8 2 5 0 42
8 2 7 0 66
8 2 8 0 34
8 2 10 0 74
8 2 11 0 58
8 3 6 0 90
8 3 7 0 8
8 3 8 0 8
8 3 9 0 58
9 0 4 0 92
9 0 5 0 20
9 0 6 0 52
9 0 9 0 84
9 0 10 0 20
9 0 11 0 60
9 1 3 0 122
9 1 5 0 72
9 1 6 0 8
9 1 7 0 24
9 1 8 0 24
9 1 9 0 8
9 1 10 0 40
9 1 12 0 122
9 3 7 0 90
9 3 8 0 58
10 0 4 0 90
10 0 5 0 16
10 0 6 0 48
10 0 9 0 80
10 0 10 0 16
10 0 11 0 58
10 1 5 0 66
10 1 6 0 10
10 1 7 0 18
10 1 8 0 18
10 1 9 0 10
10 1 10 0 34
10 2 4 0 94
10 2 5 0 44
10 2 7 0 76
10 2 8 0 44
10 2 10 0 76
10 2 11 0 62
11 0 5 0 90
11 0 6 0 58
11 0 9 0 90
11 0 10 0 58
11 2 5 0 122
11 2 7 0 90
11 2 8 0 58
11 2 10 0 122
12 1 6 0 94
12 1 7 0 28
12 1 8 0 28
12 1 9 0 62
13 1 7 0 90
13 1 8 0 58
