Qubicle Exchange Format
Version 0.2
www.minddesk.com
17 16 16
4
0.000000 0.000000 0.000000
0.858824 0.168627 0.000000
1.000000 0.607843 0.231373
1.000000 1.000000 1.000000
1 2 7 1 84
1 2 8 1 20
1 2 9 1 20
1 2 10 1 52
1 3 7 1 70
1 3 8 1 6
1 3 9 1 6
1 3 10 1 38
1 4 7 1 70
1 4 8 1 6
1 4 9 1 6
1 4 10 1 38
1 5 7 1 68
1 5 8 1 4
1 5 9 1 4
1 5 10 1 36
1 6 7 1 76
1 6 8 1 4
1 6 9 1 4
1 6 10 1 44
1 7 8 1 76
1 7 9 1 44
2 0 6 1 86
2 0 7 1 22
2 0 8 1 22
2 0 9 1 22
2 0 10 1 54
2 1 6 1 70
2 1 7 1 6
2 1 8 1 6
2 1 9 1 6
2 1 10 1 38
2 2 6 1 78
2 2 7 1 10
2 2 8 1 10
2 2 9 1 10
2 2 10 1 42
2 5 6 1 84
2 5 7 2 16
2 5 8 2 16
2 5 9 2 16
2 5 10 2 16
2 5 11 2 54
2 6 6 1 68
2 6 7 2 0
2 6 8 2 0
2 6 9 2 0
2 6 10 2 0
2 6 11 2 46
2 7 6 1 68
2 7 7 1 4
2 7 8 1 0
2 7 9 1 0
2 7 10 1 36
2 8 6 1 76
2 8 7 1 4
2 8 8 1 4
2 8 9 1 4
2 8 10 1 44
2 9 7 1 76
2 9 8 1 12
2 9 9 1 44
3 3 6 1 86
3 3 7 1 22
3 3 8 1 22
3 3 9 1 22
3 3 10 1 54
3 4 6 1 68
3 4 7 1 4
3 4 8 1 4
3 4 9 1 4
3 4 10 1 36
3 5 6 1 64
3 5 7 1 0
3 5 8 1 0
3 5 9 1 0
3 5 10 1 32
3 6 6 1 64
3 6 7 1 0
3 6 8 1 0
3 6 9 1 0
3 6 10 1 32
3 7 6 1 64
3 7 7 1 0
3 7 8 1 0
3 7 9 1 0
3 7 10 1 32
3 8 6 1 64
3 8 7 1 0
3 8 8 1 0
3 8 9 1 0
3 8 10 1 32
3 9 6 1 68
3 9 7 1 0
3 9 8 1 0
3 9 9 1 0
3 9 10 1 36
3 10 6 1 68
3 10 7 1 4
3 10 8 1 4
3 10 9 1 4
3 10 10 1 36
3 11 6 1 68
3 11 7 1 4
3 11 8 1 4
3 11 9 1 4
3 11 10 1 36
3 12 6 1 76
3 12 7 1 4
3 12 8 1 4
3 12 9 1 4
3 12 10 1 44
3 13 7 1 76
3 13 8 1 12
3 13 9 1 44
4 0 5 1 84
4 0 6 1 20
4 0 7 1 20
4 0 8 1 20
4 0 9 2 20
4 0 10 2 20
4 0 11 2 60
4 1 5 1 68
4 1 6 1 4
4 1 7 1 4
4 1 8 1 4
4 1 9 1 4
4 1 10 1 36
4 2 5 1 76
4 2 6 1 12
4 2 7 1 12
4 2 8 1 12
4 2 9 1 12
4 2 10 1 44
4 4 5 1 84
4 4 6 1 16
4 4 7 1 16
4 4 8 1 16
4 4 9 1 16
4 4 10 1 48
4 5 5 1 68
4 5 6 1 0
4 5 7 1 0
4 5 8 1 0
4 5 9 1 0
4 5 10 1 32
4 6 5 1 68
4 6 6 3 0
4 6 7 3 0
4 6 8 3 0
4 6 9 3 0
4 6 10 3 0
4 6 11 3 54
4 7 5 1 68
4 7 6 3 0
4 7 7 3 0
4 7 8 3 0
4 7 9 3 0
4 7 10 3 0
4 7 11 3 38
4 8 5 1 68
4 8 6 3 0
4 8 7 3 0
4 8 8 3 0
4 8 9 3 0
4 8 10 3 0
4 8 11 3 38
4 9 5 1 68
4 9 6 3 0
4 9 7 3 0
4 9 8 3 0
4 9 9 3 0
4 9 10 3 0
4 9 11 3 36
4 10 5 1 68
4 10 6 3 0
4 10 7 3 0
4 10 8 3 0
4 10 9 3 0
4 10 10 3 0
4 10 11 3 36
4 11 5 1 68
4 11 6 3 0
4 11 7 3 0
4 11 8 3 0
4 11 9 3 0
4 11 10 3 0
4 11 11 3 36
4 12 5 1 68
4 12 6 3 0
4 12 7 3 0
4 12 8 3 0
4 12 9 3 0
4 12 10 3 0
4 12 11 3 36
4 13 5 1 76
4 13 6 1 4
4 13 7 1 0
4 13 8 1 0
4 13 9 1 0
4 13 10 1 4
4 13 11 1 44
4 14 6 1 76
4 14 7 1 12
4 14 8 1 12
4 14 9 1 12
4 14 10 1 44
5 0 5 1 80
5 0 6 1 16
5 0 7 1 16
5 0 8 1 16
5 0 9 2 16
5 0 10 2 16
5 0 11 2 56
5 1 5 1 64
5 1 6 1 0
5 1 7 1 0
5 1 8 1 0
5 1 9 1 0
5 1 10 1 32
5 2 5 1 64
5 2 6 1 0
5 2 7 1 0
5 2 8 1 0
5 2 9 1 0
5 2 10 1 32
5 3 5 1 68
5 3 6 1 4
5 3 7 1 4
5 3 8 1 4
5 3 9 1 4
5 3 10 1 36
5 4 5 1 64
5 4 6 1 0
5 4 7 1 0
5 4 8 1 0
5 4 9 1 0
5 4 10 1 32
5 5 5 1 64
5 5 6 1 0
5 5 7 1 0
5 5 8 1 0
5 5 9 1 0
5 5 10 1 32
5 6 5 1 64
5 6 6 1 0
5 6 7 1 0
5 6 8 1 0
5 6 9 1 0
5 6 10 1 32
5 7 5 1 64
5 7 6 1 0
5 7 7 1 0
5 7 8 1 0
5 7 9 1 0
5 7 10 1 32
5 8 5 1 64
5 8 6 1 0
5 8 7 1 0
5 8 8 1 0
5 8 9 1 0
5 8 10 1 32
5 9 5 1 66
5 9 6 2 2
5 9 7 2 2
5 9 8 2 2
5 9 9 2 2
5 9 10 2 2
5 9 11 2 48
5 10 5 1 64
5 10 6 2 0
5 10 7 2 0
5 10 8 2 0
5 10 9 2 0
5 10 10 2 0
5 10 11 2 32
5 11 5 1 66
5 11 6 2 2
5 11 7 2 2
5 11 8 2 2
5 11 9 2 2
5 11 10 2 2
5 11 11 2 32
5 12 5 1 64
5 12 6 3 0
5 12 7 3 0
5 12 8 3 0
5 12 9 3 0
5 12 10 3 0
5 12 11 3 32
5 13 5 1 64
5 13 6 3 0
5 13 7 3 0
5 13 8 3 0
5 13 9 3 0
5 13 10 3 0
5 13 11 3 32
5 14 5 1 76
5 14 6 1 0
5 14 7 1 0
5 14 8 1 0
5 14 9 1 0
5 14 10 1 0
5 14 11 1 44
5 15 6 1 76
5 15 7 1 12
5 15 8 1 12
5 15 9 1 12
5 15 10 1 44
6 0 4 1 84
6 0 5 1 16
6 0 6 1 16
6 0 7 1 16
6 0 8 1 16
6 0 9 2 16
6 0 10 2 16
6 0 11 2 58
6 1 4 1 68
6 1 5 1 0
6 1 6 1 0
6 1 7 1 0
6 1 8 1 0
6 1 9 1 0
6 1 10 1 32
6 2 4 1 68
6 2 5 1 0
6 2 6 1 0
6 2 7 1 0
6 2 8 1 0
6 2 9 1 0
6 2 10 1 32
6 3 4 1 68
6 3 5 1 0
6 3 6 1 0
6 3 7 1 0
6 3 8 1 0
6 3 9 1 0
6 3 10 1 32
6 4 4 1 68
6 4 5 1 0
6 4 6 1 0
6 4 7 1 0
6 4 8 1 0
6 4 9 1 0
6 4 10 1 32
6 5 4 1 68
6 5 5 1 0
6 5 6 1 0
6 5 7 1 0
6 5 8 1 0
6 5 9 1 0
6 5 10 1 32
6 6 4 1 68
6 6 5 1 0
6 6 6 1 0
6 6 7 1 0
6 6 8 1 0
6 6 9 1 0
6 6 10 1 32
6 7 4 1 68
6 7 5 1 0
6 7 6 1 0
6 7 7 1 0
6 7 8 1 0
6 7 9 1 0
6 7 10 1 32
6 8 4 1 68
6 8 5 2 10
6 8 6 2 10
6 8 7 2 10
6 8 8 2 10
6 8 9 2 10
6 8 10 2 10
6 8 11 2 52
6 9 4 1 100
6 9 11 0 96
6 10 4 1 68
6 10 5 2 24
6 10 6 2 24
6 10 7 2 24
6 10 8 2 24
6 10 9 2 24
6 10 10 2 24
6 10 11 2 32
6 11 4 1 100
6 11 11 0 96
6 12 4 1 68
6 12 5 2 16
6 12 6 2 16
6 12 7 2 16
6 12 8 2 16
6 12 9 2 16
6 12 10 2 16
6 12 11 2 32
6 13 4 1 68
6 13 5 3 0
6 13 6 3 0
6 13 7 3 0
6 13 8 3 0
6 13 9 3 0
6 13 10 3 0
6 13 11 3 32
6 14 4 1 76
6 14 5 3 0
6 14 6 3 0
6 14 7 3 0
6 14 8 3 0
6 14 9 3 0
6 14 10 3 0
6 14 11 3 32
6 15 5 1 76
6 15 6 1 8
6 15 7 1 8
6 15 8 1 8
6 15 9 1 8
6 15 10 1 8
6 15 11 1 44
7 0 4 1 80
7 0 5 1 16
7 0 6 1 16
7 0 7 1 16
7 0 8 1 16
7 0 9 1 16
7 0 10 1 48
7 1 4 1 64
7 1 5 1 0
7 1 6 1 0
7 1 7 1 0
7 1 8 1 0
7 1 9 1 0
7 1 10 1 32
7 2 4 1 64
7 2 5 1 0
7 2 6 1 0
7 2 7 1 0
7 2 8 1 0
7 2 9 1 0
7 2 10 1 32
7 3 4 1 64
7 3 5 3 0
7 3 6 3 0
7 3 7 3 0
7 3 8 3 0
7 3 9 3 0
7 3 10 3 0
7 3 11 3 52
7 4 4 1 64
7 4 5 3 0
7 4 6 3 0
7 4 7 3 0
7 4 8 3 0
7 4 9 3 0
7 4 10 3 0
7 4 11 3 44
7 5 4 1 64
7 5 5 1 0
7 5 6 1 0
7 5 7 1 0
7 5 8 1 0
7 5 9 1 0
7 5 10 1 32
7 6 4 1 64
7 6 5 2 0
7 6 6 2 0
7 6 7 2 0
7 6 8 2 0
7 6 9 2 0
7 6 10 2 0
7 6 11 2 52
7 7 4 1 64
7 7 5 2 8
7 7 6 2 8
7 7 7 2 8
7 7 8 2 8
7 7 9 2 8
7 7 10 2 8
7 7 11 2 36
7 8 4 1 96
7 8 11 0 96
7 9 4 1 64
7 9 5 2 20
7 9 6 2 20
7 9 7 2 20
7 9 8 2 20
7 9 9 2 20
7 9 10 2 20
7 9 11 2 32
7 10 4 1 64
7 10 5 2 0
7 10 6 2 0
7 10 7 2 0
7 10 8 2 0
7 10 9 2 0
7 10 10 2 0
7 10 11 2 32
7 11 4 1 64
7 11 5 2 4
7 11 6 2 4
7 11 7 2 4
7 11 8 2 4
7 11 9 2 4
7 11 10 2 4
7 11 11 2 32
7 12 4 1 64
7 12 5 2 0
7 12 6 2 0
7 12 7 2 0
7 12 8 2 0
7 12 9 2 0
7 12 10 2 0
7 12 11 2 32
7 13 4 1 64
7 13 5 3 0
7 13 6 3 0
7 13 7 3 0
7 13 8 3 0
7 13 9 3 0
7 13 10 3 0
7 13 11 3 32
7 14 4 1 64
7 14 5 3 0
7 14 6 3 0
7 14 7 3 0
7 14 8 3 0
7 14 9 3 0
7 14 10 3 0
7 14 11 3 32
7 15 4 1 76
7 15 5 1 8
7 15 6 1 8
7 15 7 1 8
7 15 8 1 8
7 15 9 1 8
7 15 10 1 8
7 15 11 1 40
8 0 4 1 80
8 0 5 1 16
8 0 6 1 16
8 0 7 1 16
8 0 8 1 16
8 0 9 1 16
8 0 10 1 48
8 1 4 1 64
8 1 5 1 0
8 1 6 1 0
8 1 7 1 0
8 1 8 1 0
8 1 9 1 0
8 1 10 1 32
8 2 4 1 64
8 2 5 1 0
8 2 6 1 0
8 2 7 1 0
8 2 8 1 0
8 2 9 1 0
8 2 10 1 32
8 3 4 1 64
8 3 5 3 0
8 3 6 3 0
8 3 7 3 0
8 3 8 3 0
8 3 9 3 0
8 3 10 3 0
8 3 11 3 50
8 4 4 1 64
8 4 5 3 0
8 4 6 3 0
8 4 7 3 0
8 4 8 3 0
8 4 9 3 0
8 4 10 3 0
8 4 11 3 42
8 5 4 1 64
8 5 5 1 0
8 5 6 1 0
8 5 7 1 0
8 5 8 1 0
8 5 9 1 0
8 5 10 1 32
8 6 4 1 64
8 6 5 2 0
8 6 6 2 0
8 6 7 2 0
8 6 8 2 0
8 6 9 2 0
8 6 10 2 0
8 6 11 2 50
8 7 4 1 64
8 7 5 2 8
8 7 6 2 8
8 7 7 2 8
8 7 8 2 8
8 7 9 2 8
8 7 10 2 8
8 7 11 2 34
8 8 4 1 96
8 8 11 0 96
8 9 4 1 64
8 9 5 2 18
8 9 6 2 18
8 9 7 2 18
8 9 8 2 18
8 9 9 2 18
8 9 10 2 18
8 9 11 2 32
8 10 4 1 64
8 10 5 2 0
8 10 6 2 0
8 10 7 2 0
8 10 8 2 0
8 10 9 2 0
8 10 10 2 0
8 10 11 2 32
8 11 4 1 64
8 11 5 2 2
8 11 6 2 2
8 11 7 2 2
8 11 8 2 2
8 11 9 2 2
8 11 10 2 2
8 11 11 2 32
8 12 4 1 64
8 12 5 2 0
8 12 6 2 0
8 12 7 2 0
8 12 8 2 0
8 12 9 2 0
8 12 10 2 0
8 12 11 2 32
8 13 4 1 64
8 13 5 3 0
8 13 6 3 0
8 13 7 3 0
8 13 8 3 0
8 13 9 3 0
8 13 10 3 0
8 13 11 3 32
8 14 4 1 64
8 14 5 3 0
8 14 6 3 0
8 14 7 3 0
8 14 8 3 0
8 14 9 3 0
8 14 10 3 0
8 14 11 3 32
8 15 4 1 74
8 15 5 1 8
8 15 6 1 8
8 15 7 1 8
8 15 8 1 8
8 15 9 1 8
8 15 10 1 8
8 15 11 1 40
9 0 4 1 82
9 0 5 1 16
9 0 6 1 16
9 0 7 1 16
9 0 8 1 16
9 0 9 2 16
9 0 10 2 16
9 0 11 2 60
9 1 4 1 66
9 1 5 1 0
9 1 6 1 0
9 1 7 1 0
9 1 8 1 0
9 1 9 1 0
9 1 10 1 32
9 2 4 1 66
9 2 5 1 0
9 2 6 1 0
9 2 7 1 0
9 2 8 1 0
9 2 9 1 0
9 2 10 1 32
9 3 4 1 66
9 3 5 1 0
9 3 6 1 0
9 3 7 1 0
9 3 8 1 0
9 3 9 1 0
9 3 10 1 32
9 4 4 1 66
9 4 5 1 0
9 4 6 1 0
9 4 7 1 0
9 4 8 1 0
9 4 9 1 0
9 4 10 1 32
9 5 4 1 66
9 5 5 1 0
9 5 6 1 0
9 5 7 1 0
9 5 8 1 0
9 5 9 1 0
9 5 10 1 32
9 6 4 1 66
9 6 5 1 0
9 6 6 1 0
9 6 7 1 0
9 6 8 1 0
9 6 9 1 0
9 6 10 1 32
9 7 4 1 66
9 7 5 1 0
9 7 6 1 0
9 7 7 1 0
9 7 8 1 0
9 7 9 1 0
9 7 10 1 32
9 8 4 1 66
9 8 5 2 12
9 8 6 2 12
9 8 7 2 12
9 8 8 2 12
9 8 9 2 12
9 8 10 2 12
9 8 11 2 50
9 9 4 1 98
9 9 11 0 96
9 10 4 1 66
9 10 5 2 24
9 10 6 2 24
9 10 7 2 24
9 10 8 2 24
9 10 9 2 24
9 10 10 2 24
9 10 11 2 32
9 11 4 1 98
9 11 11 0 96
9 12 4 1 66
9 12 5 2 16
9 12 6 2 16
9 12 7 2 16
9 12 8 2 16
9 12 9 2 16
9 12 10 2 16
9 12 11 2 32
9 13 4 1 66
9 13 5 3 0
9 13 6 3 0
9 13 7 3 0
9 13 8 3 0
9 13 9 3 0
9 13 10 3 0
9 13 11 3 32
9 14 4 1 74
9 14 5 3 0
9 14 6 3 0
9 14 7 3 0
9 14 8 3 0
9 14 9 3 0
9 14 10 3 0
9 14 11 3 32
9 15 5 1 74
9 15 6 1 8
9 15 7 1 8
9 15 8 1 8
9 15 9 1 8
9 15 10 1 8
9 15 11 1 42
10 0 5 1 80
10 0 6 1 16
10 0 7 1 16
10 0 8 1 16
10 0 9 2 16
10 0 10 2 16
10 0 11 2 56
10 1 5 1 64
10 1 6 1 0
10 1 7 1 0
10 1 8 1 0
10 1 9 1 0
10 1 10 1 32
10 2 5 1 64
10 2 6 1 0
10 2 7 1 0
10 2 8 1 0
10 2 9 1 0
10 2 10 1 32
10 3 5 1 66
10 3 6 1 2
10 3 7 1 2
10 3 8 1 2
10 3 9 1 2
10 3 10 1 34
10 4 5 1 64
10 4 6 1 0
10 4 7 1 0
10 4 8 1 0
10 4 9 1 0
10 4 10 1 32
10 5 5 1 64
10 5 6 1 0
10 5 7 1 0
10 5 8 1 0
10 5 9 1 0
10 5 10 1 32
10 6 5 1 64
10 6 6 1 0
10 6 7 1 0
10 6 8 1 0
10 6 9 1 0
10 6 10 1 32
10 7 5 1 64
10 7 6 1 0
10 7 7 1 0
10 7 8 1 0
10 7 9 1 0
10 7 10 1 32
10 8 5 1 64
10 8 6 1 0
10 8 7 1 0
10 8 8 1 0
10 8 9 1 0
10 8 10 1 32
10 9 5 1 68
10 9 6 2 4
10 9 7 2 4
10 9 8 2 4
10 9 9 2 4
10 9 10 2 4
10 9 11 2 48
10 10 5 1 64
10 10 6 2 0
10 10 7 2 0
10 10 8 2 0
10 10 9 2 0
10 10 10 2 0
10 10 11 2 32
10 11 5 1 68
10 11 6 2 4
10 11 7 2 4
10 11 8 2 4
10 11 9 2 4
10 11 10 2 4
10 11 11 2 32
10 12 5 1 64
10 12 6 3 0
10 12 7 3 0
10 12 8 3 0
10 12 9 3 0
10 12 10 3 0
10 12 11 3 32
10 13 5 1 64
10 13 6 3 0
10 13 7 3 0
10 13 8 3 0
10 13 9 3 0
10 13 10 3 0
10 13 11 3 32
10 14 5 1 74
10 14 6 1 0
10 14 7 1 0
10 14 8 1 0
10 14 9 1 0
10 14 10 1 0
10 14 11 1 42
10 15 6 1 74
10 15 7 1 10
10 15 8 1 10
10 15 9 1 10
10 15 10 1 42
11 0 5 1 82
11 0 6 1 18
11 0 7 1 18
11 0 8 1 18
11 0 9 2 18
11 0 10 2 18
11 0 11 2 58
11 1 5 1 66
11 1 6 1 2
11 1 7 1 2
11 1 8 1 2
11 1 9 1 2
11 1 10 1 34
11 2 5 1 74
11 2 6 1 10
11 2 7 1 10
11 2 8 1 10
11 2 9 1 10
11 2 10 1 42
11 4 5 1 82
11 4 6 1 16
11 4 7 1 16
11 4 8 1 16
11 4 9 1 16
11 4 10 1 48
11 5 5 1 66
11 5 6 1 0
11 5 7 1 0
11 5 8 1 0
11 5 9 1 0
11 5 10 1 32
11 6 5 1 66
11 6 6 3 0
11 6 7 3 0
11 6 8 3 0
11 6 9 3 0
11 6 10 3 0
11 6 11 3 54
11 7 5 1 66
11 7 6 3 0
11 7 7 3 0
11 7 8 3 0
11 7 9 3 0
11 7 10 3 0
11 7 11 3 38
11 8 5 1 66
11 8 6 3 0
11 8 7 3 0
11 8 8 3 0
11 8 9 3 0
11 8 10 3 0
11 8 11 3 38
11 9 5 1 66
11 9 6 3 0
11 9 7 3 0
11 9 8 3 0
11 9 9 3 0
11 9 10 3 0
11 9 11 3 34
11 10 5 1 66
11 10 6 3 0
11 10 7 3 0
11 10 8 3 0
11 10 9 3 0
11 10 10 3 0
11 10 11 3 34
11 11 5 1 66
11 11 6 3 0
11 11 7 3 0
11 11 8 3 0
11 11 9 3 0
11 11 10 3 0
11 11 11 3 34
11 12 5 1 66
11 12 6 3 0
11 12 7 3 0
11 12 8 3 0
11 12 9 3 0
11 12 10 3 0
11 12 11 3 34
11 13 5 1 74
11 13 6 1 2
11 13 7 1 0
11 13 8 1 0
11 13 9 1 0
11 13 10 1 2
11 13 11 1 42
11 14 6 1 74
11 14 7 1 10
11 14 8 1 10
11 14 9 1 10
11 14 10 1 42
12 3 6 1 86
12 3 7 1 22
12 3 8 1 22
12 3 9 1 22
12 3 10 1 54
12 4 6 1 66
12 4 7 1 2
12 4 8 1 2
12 4 9 1 2
12 4 10 1 34
12 5 6 1 64
12 5 7 1 0
12 5 8 1 0
12 5 9 1 0
12 5 10 1 32
12 6 6 1 64
12 6 7 1 0
12 6 8 1 0
12 6 9 1 0
12 6 10 1 32
12 7 6 1 64
12 7 7 1 0
12 7 8 1 0
12 7 9 1 0
12 7 10 1 32
12 8 6 1 64
12 8 7 1 0
12 8 8 1 0
12 8 9 1 0
12 8 10 1 32
12 9 6 1 66
12 9 7 1 0
12 9 8 1 0
12 9 9 1 0
12 9 10 1 34
12 10 6 1 66
12 10 7 1 2
12 10 8 1 2
12 10 9 1 2
12 10 10 1 34
12 11 6 1 66
12 11 7 1 2
12 11 8 1 2
12 11 9 1 2
12 11 10 1 34
12 12 6 1 74
12 12 7 1 2
12 12 8 1 2
12 12 9 1 2
12 12 10 1 42
12 13 7 1 74
12 13 8 1 10
12 13 9 1 42
13 0 6 1 86
13 0 7 1 22
13 0 8 1 22
13 0 9 1 22
13 0 10 1 54
13 1 6 1 70
13 1 7 1 6
13 1 8 1 6
13 1 9 1 6
13 1 10 1 38
13 2 6 1 78
13 2 7 1 12
13 2 8 1 12
13 2 9 1 12
13 2 10 1 44
13 5 6 1 82
13 5 7 2 16
13 5 8 2 16
13 5 9 2 16
13 5 10 2 16
13 5 11 2 54
13 6 6 1 66
13 6 7 2 0
13 6 8 2 0
13 6 9 2 0
13 6 10 2 0
13 6 11 2 46
13 7 6 1 66
13 7 7 1 2
13 7 8 1 0
13 7 9 1 0
13 7 10 1 34
13 8 6 1 74
13 8 7 1 2
13 8 8 1 2
13 8 9 1 2
13 8 10 1 42
13 9 7 1 74
13 9 8 1 10
13 9 9 1 42
14 2 7 1 82
14 2 8 1 18
14 2 9 1 18
14 2 10 1 50
14 3 7 1 70
14 3 8 1 6
14 3 9 1 6
14 3 10 1 38
14 4 7 1 70
14 4 8 1 6
14 4 9 1 6
14 4 10 1 38
14 5 7 1 66
14 5 8 1 2
14 5 9 1 2
14 5 10 1 34
14 6 7 1 74
14 6 8 1 2
14 6 9 1 2
14 6 10 1 42
14 7 8 1 74
14 7 9 1 42
