Qubicle Exchange Format
Version 0.2
www.minddesk.com
16 16 16
4
0.000000 0.000000 0.000000
0.513726 0.827451 0.074510
0.796078 0.309804 0.058824
1.000000 0.607843 0.231373
1 3 8 3 84
1 3 9 3 20
1 3 10 3 20
1 3 11 3 52
1 4 7 3 84
1 4 8 3 4
1 4 9 3 4
1 4 10 3 12
1 4 11 3 44
1 5 7 2 68
1 5 8 2 4
1 5 9 2 36
1 6 6 2 84
1 6 7 2 4
1 6 8 2 4
1 6 9 2 36
1 7 6 2 68
1 7 7 2 4
1 7 8 2 4
1 7 9 2 44
1 8 6 2 76
1 8 7 2 12
1 8 8 2 44
2 3 8 3 80
2 3 9 3 16
2 3 10 3 16
2 3 11 3 50
2 4 7 3 80
2 4 8 3 0
2 4 9 3 0
2 4 10 3 0
2 4 11 3 32
2 5 7 3 64
2 5 8 3 0
2 5 9 3 0
2 5 10 3 4
2 5 11 3 36
2 6 6 3 80
2 6 7 3 0
2 6 8 3 0
2 6 9 3 0
2 6 10 3 12
2 6 11 3 44
2 7 6 2 64
2 7 7 2 0
2 7 8 2 0
2 7 9 2 32
2 8 6 2 64
2 8 7 2 0
2 8 8 2 0
2 8 9 2 36
2 9 6 2 76
2 9 7 2 4
2 9 8 2 4
2 9 9 2 44
2 10 7 2 76
2 10 8 2 44
3 1 6 2 84
3 1 7 2 20
3 1 8 2 20
3 1 9 2 52
3 1 11 2 116
3 2 5 2 84
3 2 6 2 4
3 2 7 2 4
3 2 8 2 4
3 2 9 2 4
3 2 10 2 20
3 2 11 2 44
3 3 5 1 68
3 3 6 1 4
3 3 7 1 4
3 3 8 1 0
3 3 9 1 0
3 3 10 1 32
3 4 5 2 68
3 4 6 2 4
3 4 7 3 0
3 4 8 3 0
3 4 9 3 0
3 4 10 3 0
3 4 11 3 48
3 5 5 1 68
3 5 6 1 4
3 5 7 3 0
3 5 8 3 0
3 5 9 3 0
3 5 10 3 0
3 5 11 3 32
3 6 5 1 68
3 6 6 3 0
3 6 7 3 0
3 6 8 3 0
3 6 9 3 0
3 6 10 3 8
3 6 11 3 42
3 7 5 1 68
3 7 6 2 0
3 7 7 2 0
3 7 8 2 0
3 7 9 2 32
3 8 5 1 68
3 8 6 1 0
3 8 7 1 0
3 8 8 1 0
3 8 9 1 0
3 8 10 1 52
3 9 5 1 76
3 9 6 1 8
3 9 7 1 0
3 9 8 1 0
3 9 9 1 0
3 9 10 1 44
3 10 7 3 64
3 10 8 3 0
3 10 9 3 36
3 11 7 3 68
3 11 8 3 4
3 11 9 3 4
3 11 10 3 52
3 12 7 3 68
3 12 8 3 4
3 12 9 3 4
3 12 10 3 36
3 13 5 2 84
3 13 6 2 20
3 13 7 2 4
3 13 8 2 4
3 13 9 2 4
3 13 10 2 4
3 13 11 2 60
3 14 5 2 76
3 14 6 2 12
3 14 7 2 12
3 14 8 2 12
3 14 9 2 12
3 14 10 2 44
4 0 5 2 84
4 0 6 2 20
4 0 7 2 20
4 0 8 2 20
4 0 9 2 20
4 0 10 2 20
4 0 11 2 52
4 1 5 2 68
4 1 6 2 0
4 1 7 2 0
4 1 8 2 0
4 1 9 2 0
4 1 10 2 4
4 1 11 2 32
4 2 5 2 64
4 2 6 2 0
4 2 7 2 0
4 2 8 2 0
4 2 9 2 0
4 2 10 2 0
4 2 11 2 42
4 3 4 1 84
4 3 5 1 0
4 3 6 1 0
4 3 7 1 0
4 3 8 1 0
4 3 9 1 0
4 3 10 1 32
4 4 4 2 68
4 4 5 2 0
4 4 6 2 0
4 4 7 2 0
4 4 8 2 0
4 4 9 2 0
4 4 10 2 0
4 4 11 2 48
4 5 4 1 68
4 5 5 3 0
4 5 6 3 0
4 5 7 3 0
4 5 8 3 0
4 5 9 3 0
4 5 10 3 0
4 5 11 3 42
4 6 4 1 68
4 6 5 1 0
4 6 6 1 0
4 6 7 1 0
4 6 8 1 0
4 6 9 1 0
4 6 10 1 32
4 7 4 1 68
4 7 5 1 0
4 7 6 1 0
4 7 7 1 0
4 7 8 1 0
4 7 9 1 0
4 7 10 1 36
4 8 4 1 68
4 8 5 1 0
4 8 6 1 0
4 8 7 1 0
4 8 8 1 0
4 8 9 1 0
4 8 10 1 32
4 9 4 2 68
4 9 5 2 0
4 9 6 2 0
4 9 7 2 0
4 9 8 2 0
4 9 9 2 0
4 9 10 2 0
4 9 11 2 60
4 10 4 2 68
4 10 5 2 4
4 10 6 2 4
4 10 7 3 0
4 10 8 3 0
4 10 9 3 0
4 10 10 3 36
4 11 4 2 68
4 11 5 2 4
4 11 6 2 4
4 11 7 2 0
4 11 8 2 0
4 11 9 2 0
4 11 10 2 0
4 11 11 2 52
4 12 4 2 68
4 12 5 2 4
4 12 6 2 4
4 12 7 2 0
4 12 8 2 0
4 12 9 2 0
4 12 10 2 0
4 12 11 2 36
4 13 4 2 68
4 13 5 2 0
4 13 6 2 0
4 13 7 2 0
4 13 8 2 0
4 13 9 2 0
4 13 10 2 0
4 13 11 2 32
4 14 4 2 76
4 14 5 2 0
4 14 6 2 0
4 14 7 2 0
4 14 8 2 0
4 14 9 2 0
4 14 10 2 0
4 14 11 2 44
4 15 5 2 76
4 15 6 2 12
4 15 7 2 12
4 15 8 2 12
4 15 9 2 12
4 15 10 2 44
5 0 5 2 82
5 0 6 2 18
5 0 7 2 18
5 0 8 2 18
5 0 9 2 18
5 0 10 2 18
5 0 11 2 50
5 1 5 2 64
5 1 6 2 0
5 1 7 2 0
5 1 8 2 0
5 1 9 2 0
5 1 10 2 0
5 1 11 2 40
5 2 5 1 64
5 2 6 1 0
5 2 7 1 0
5 2 8 1 0
5 2 9 1 0
5 2 10 1 32
5 3 4 1 80
5 3 5 1 0
5 3 6 1 0
5 3 7 1 0
5 3 8 1 0
5 3 9 1 0
5 3 10 1 32
5 4 4 2 64
5 4 5 2 0
5 4 6 2 0
5 4 7 2 0
5 4 8 2 0
5 4 9 2 0
5 4 10 2 0
5 4 11 2 56
5 5 4 1 64
5 5 5 1 0
5 5 6 1 0
5 5 7 1 0
5 5 8 1 0
5 5 9 1 0
5 5 10 1 32
5 6 4 1 64
5 6 5 1 0
5 6 6 1 0
5 6 7 1 0
5 6 8 1 0
5 6 9 1 0
5 6 10 1 32
5 7 4 1 64
5 7 5 1 0
5 7 6 1 0
5 7 7 1 0
5 7 8 1 0
5 7 9 1 0
5 7 10 1 32
5 8 4 2 64
5 8 5 2 0
5 8 6 2 0
5 8 7 2 0
5 8 8 2 0
5 8 9 2 0
5 8 10 2 0
5 8 11 2 52
5 9 4 2 64
5 9 5 2 0
5 9 6 2 0
5 9 7 2 0
5 9 8 2 0
5 9 9 2 0
5 9 10 2 0
5 9 11 2 32
5 10 4 2 64
5 10 5 2 0
5 10 6 2 0
5 10 7 2 0
5 10 8 2 0
5 10 9 2 0
5 10 10 2 0
5 10 11 2 36
5 11 4 2 64
5 11 5 2 0
5 11 6 2 0
5 11 7 2 0
5 11 8 2 0
5 11 9 2 0
5 11 10 2 0
5 11 11 2 32
5 12 4 2 64
5 12 5 3 2
5 12 6 3 2
5 12 7 3 2
5 12 8 3 2
5 12 9 3 2
5 12 10 3 2
5 12 11 3 32
5 13 4 2 64
5 13 5 3 2
5 13 6 3 2
5 13 7 3 2
5 13 8 3 2
5 13 9 3 2
5 13 10 3 2
5 13 11 3 32
5 14 4 2 64
5 14 5 2 0
5 14 6 2 0
5 14 7 2 0
5 14 8 2 0
5 14 9 2 0
5 14 10 2 0
5 14 11 2 32
5 15 4 2 76
5 15 5 2 8
5 15 6 2 8
5 15 7 2 8
5 15 8 2 8
5 15 9 2 8
5 15 10 2 8
5 15 11 2 44
6 1 5 2 82
6 1 6 2 18
6 1 7 2 18
6 1 8 2 18
6 1 9 2 18
6 1 10 2 18
6 1 11 2 58
6 2 4 1 84
6 2 5 1 0
6 2 6 1 0
6 2 7 1 0
6 2 8 1 0
6 2 9 1 0
6 2 10 1 32
6 3 4 1 64
6 3 5 1 0
6 3 6 1 0
6 3 7 1 0
6 3 8 1 0
6 3 9 1 0
6 3 10 1 32
6 4 4 2 64
6 4 5 2 0
6 4 6 2 0
6 4 7 2 0
6 4 8 2 0
6 4 9 2 0
6 4 10 2 0
6 4 11 2 56
6 5 4 1 64
6 5 5 1 0
6 5 6 1 0
6 5 7 1 0
6 5 8 1 0
6 5 9 1 0
6 5 10 1 32
6 6 4 1 64
6 6 5 1 0
6 6 6 1 0
6 6 7 1 0
6 6 8 1 0
6 6 9 1 0
6 6 10 1 32
6 7 4 1 64
6 7 5 1 0
6 7 6 1 0
6 7 7 1 0
6 7 8 1 0
6 7 9 1 0
6 7 10 1 32
6 8 4 2 64
6 8 5 2 0
6 8 6 2 0
6 8 7 2 0
6 8 8 2 0
6 8 9 2 0
6 8 10 2 0
6 8 11 2 48
6 9 4 2 64
6 9 5 2 0
6 9 6 2 0
6 9 7 2 0
6 9 8 2 0
6 9 9 2 0
6 9 10 2 0
6 9 11 2 32
6 10 4 2 64
6 10 5 3 0
6 10 6 3 0
6 10 7 3 0
6 10 8 3 0
6 10 9 3 0
6 10 10 3 0
6 10 11 3 32
6 11 4 2 64
6 11 5 3 8
6 11 6 3 8
6 11 7 3 8
6 11 8 3 8
6 11 9 3 8
6 11 10 3 8
6 11 11 3 32
6 12 4 2 96
6 12 11 0 96
6 13 4 2 96
6 13 11 0 96
6 14 4 2 64
6 14 5 2 16
6 14 6 2 16
6 14 7 2 16
6 14 8 2 16
6 14 9 2 16
6 14 10 2 16
6 14 11 2 32
6 15 4 2 72
6 15 5 2 8
6 15 6 2 8
6 15 7 2 8
6 15 8 2 8
6 15 9 2 8
6 15 10 2 8
6 15 11 2 40
7 2 4 1 80
7 2 5 1 16
7 2 6 1 16
7 2 7 1 16
7 2 8 1 16
7 2 9 1 16
7 2 10 1 48
7 3 4 1 64
7 3 5 2 0
7 3 6 2 0
7 3 7 2 0
7 3 8 2 0
7 3 9 2 0
7 3 10 2 0
7 3 11 2 52
7 4 4 2 64
7 4 5 2 0
7 4 6 2 0
7 4 7 2 0
7 4 8 2 0
7 4 9 2 0
7 4 10 2 0
7 4 11 2 32
7 5 4 1 64
7 5 5 2 0
7 5 6 2 0
7 5 7 2 0
7 5 8 2 0
7 5 9 2 0
7 5 10 2 0
7 5 11 2 44
7 6 4 1 64
7 6 5 1 0
7 6 6 1 0
7 6 7 1 0
7 6 8 1 0
7 6 9 1 0
7 6 10 1 32
7 7 4 1 64
7 7 5 1 0
7 7 6 1 0
7 7 7 1 0
7 7 8 1 0
7 7 9 1 0
7 7 10 1 32
7 8 4 2 64
7 8 5 2 0
7 8 6 2 0
7 8 7 2 0
7 8 8 2 0
7 8 9 2 0
7 8 10 2 0
7 8 11 2 48
7 9 4 2 64
7 9 5 2 0
7 9 6 2 0
7 9 7 2 0
7 9 8 2 0
7 9 9 2 0
7 9 10 2 0
7 9 11 2 32
7 10 4 2 64
7 10 5 3 0
7 10 6 3 0
7 10 7 3 0
7 10 8 3 0
7 10 9 3 0
7 10 10 3 0
7 10 11 3 32
7 11 4 2 64
7 11 5 3 0
7 11 6 3 0
7 11 7 3 0
7 11 8 3 0
7 11 9 3 0
7 11 10 3 0
7 11 11 3 32
7 12 4 2 64
7 12 5 3 4
7 12 6 3 4
7 12 7 3 4
7 12 8 3 4
7 12 9 3 4
7 12 10 3 4
7 12 11 3 32
7 13 4 2 64
7 13 5 3 4
7 13 6 3 4
7 13 7 3 4
7 13 8 3 4
7 13 9 3 4
7 13 10 3 4
7 13 11 3 32
7 14 4 2 64
7 14 5 2 0
7 14 6 2 0
7 14 7 2 0
7 14 8 2 0
7 14 9 2 0
7 14 10 2 0
7 14 11 2 32
7 15 4 2 72
7 15 5 2 8
7 15 6 2 8
7 15 7 2 8
7 15 8 2 8
7 15 9 2 8
7 15 10 2 8
7 15 11 2 40
8 2 4 1 80
8 2 5 1 16
8 2 6 1 16
8 2 7 1 16
8 2 8 1 16
8 2 9 1 16
8 2 10 1 48
8 3 4 1 64
8 3 5 2 0
8 3 6 2 0
8 3 7 2 0
8 3 8 2 0
8 3 9 2 0
8 3 10 2 0
8 3 11 2 50
8 4 4 2 64
8 4 5 2 0
8 4 6 2 0
8 4 7 2 0
8 4 8 2 0
8 4 9 2 0
8 4 10 2 0
8 4 11 2 32
8 5 4 1 64
8 5 5 2 0
8 5 6 2 0
8 5 7 2 0
8 5 8 2 0
8 5 9 2 0
8 5 10 2 0
8 5 11 2 42
8 6 4 1 64
8 6 5 1 0
8 6 6 1 0
8 6 7 1 0
8 6 8 1 0
8 6 9 1 0
8 6 10 1 32
8 7 4 1 64
8 7 5 1 0
8 7 6 1 0
8 7 7 1 0
8 7 8 1 0
8 7 9 1 0
8 7 10 1 32
8 8 4 2 64
8 8 5 2 0
8 8 6 2 0
8 8 7 2 0
8 8 8 2 0
8 8 9 2 0
8 8 10 2 0
8 8 11 2 48
8 9 4 2 64
8 9 5 2 0
8 9 6 2 0
8 9 7 2 0
8 9 8 2 0
8 9 9 2 0
8 9 10 2 0
8 9 11 2 32
8 10 4 2 64
8 10 5 3 0
8 10 6 3 0
8 10 7 3 0
8 10 8 3 0
8 10 9 3 0
8 10 10 3 0
8 10 11 3 32
8 11 4 2 64
8 11 5 3 0
8 11 6 3 0
8 11 7 3 0
8 11 8 3 0
8 11 9 3 0
8 11 10 3 0
8 11 11 3 32
8 12 4 2 64
8 12 5 3 2
8 12 6 3 2
8 12 7 3 2
8 12 8 3 2
8 12 9 3 2
8 12 10 3 2
8 12 11 3 32
8 13 4 2 64
8 13 5 3 2
8 13 6 3 2
8 13 7 3 2
8 13 8 3 2
8 13 9 3 2
8 13 10 3 2
8 13 11 3 32
8 14 4 2 64
8 14 5 2 0
8 14 6 2 0
8 14 7 2 0
8 14 8 2 0
8 14 9 2 0
8 14 10 2 0
8 14 11 2 32
8 15 4 2 72
8 15 5 2 8
8 15 6 2 8
8 15 7 2 8
8 15 8 2 8
8 15 9 2 8
8 15 10 2 8
8 15 11 2 40
9 1 5 2 84
9 1 6 2 20
9 1 7 2 20
9 1 8 2 20
9 1 9 2 20
9 1 10 2 20
9 1 11 2 60
9 2 4 1 82
9 2 5 1 0
9 2 6 1 0
9 2 7 1 0
9 2 8 1 0
9 2 9 1 0
9 2 10 1 32
9 3 4 1 64
9 3 5 1 0
9 3 6 1 0
9 3 7 1 0
9 3 8 1 0
9 3 9 1 0
9 3 10 1 32
9 4 4 2 64
9 4 5 2 0
9 4 6 2 0
9 4 7 2 0
9 4 8 2 0
9 4 9 2 0
9 4 10 2 0
9 4 11 2 56
9 5 4 1 64
9 5 5 1 0
9 5 6 1 0
9 5 7 1 0
9 5 8 1 0
9 5 9 1 0
9 5 10 1 32
9 6 4 1 64
9 6 5 1 0
9 6 6 1 0
9 6 7 1 0
9 6 8 1 0
9 6 9 1 0
9 6 10 1 32
9 7 4 1 64
9 7 5 1 0
9 7 6 1 0
9 7 7 1 0
9 7 8 1 0
9 7 9 1 0
9 7 10 1 32
9 8 4 2 64
9 8 5 2 0
9 8 6 2 0
9 8 7 2 0
9 8 8 2 0
9 8 9 2 0
9 8 10 2 0
9 8 11 2 48
9 9 4 2 64
9 9 5 2 0
9 9 6 2 0
9 9 7 2 0
9 9 8 2 0
9 9 9 2 0
9 9 10 2 0
9 9 11 2 32
9 10 4 2 64
9 10 5 3 0
9 10 6 3 0
9 10 7 3 0
9 10 8 3 0
9 10 9 3 0
9 10 10 3 0
9 10 11 3 32
9 11 4 2 64
9 11 5 3 8
9 11 6 3 8
9 11 7 3 8
9 11 8 3 8
9 11 9 3 8
9 11 10 3 8
9 11 11 3 32
9 12 4 2 96
9 12 11 0 96
9 13 4 2 96
9 13 11 0 96
9 14 4 2 64
9 14 5 2 16
9 14 6 2 16
9 14 7 2 16
9 14 8 2 16
9 14 9 2 16
9 14 10 2 16
9 14 11 2 32
9 15 4 2 72
9 15 5 2 8
9 15 6 2 8
9 15 7 2 8
9 15 8 2 8
9 15 9 2 8
9 15 10 2 8
9 15 11 2 40
10 0 5 2 84
10 0 6 2 20
10 0 7 2 52
10 0 9 2 84
10 0 10 2 20
10 0 11 2 52
10 1 5 2 64
10 1 6 2 0
10 1 7 2 0
10 1 8 2 16
10 1 9 2 0
10 1 10 2 0
10 1 11 2 40
10 2 5 1 64
10 2 6 1 0
10 2 7 1 0
10 2 8 1 0
10 2 9 1 0
10 2 10 1 32
10 3 4 1 80
10 3 5 1 0
10 3 6 1 0
10 3 7 1 0
10 3 8 1 0
10 3 9 1 0
10 3 10 1 32
10 4 4 2 64
10 4 5 2 0
10 4 6 2 0
10 4 7 2 0
10 4 8 2 0
10 4 9 2 0
10 4 10 2 0
10 4 11 2 56
10 5 4 1 64
10 5 5 1 0
10 5 6 1 0
10 5 7 1 0
10 5 8 1 0
10 5 9 1 0
10 5 10 1 32
10 6 4 1 64
10 6 5 1 0
10 6 6 1 0
10 6 7 1 0
10 6 8 1 0
10 6 9 1 0
10 6 10 1 32
10 7 4 1 64
10 7 5 1 0
10 7 6 1 0
10 7 7 1 0
10 7 8 1 0
10 7 9 1 0
10 7 10 1 32
10 8 4 2 64
10 8 5 2 0
10 8 6 2 0
10 8 7 2 0
10 8 8 2 0
10 8 9 2 0
10 8 10 2 0
10 8 11 2 50
10 9 4 2 64
10 9 5 2 0
10 9 6 2 0
10 9 7 2 0
10 9 8 2 0
10 9 9 2 0
10 9 10 2 0
10 9 11 2 32
10 10 4 2 64
10 10 5 2 0
10 10 6 2 0
10 10 7 2 0
10 10 8 2 0
10 10 9 2 0
10 10 10 2 0
10 10 11 2 34
10 11 4 2 64
10 11 5 2 0
10 11 6 2 0
10 11 7 2 0
10 11 8 2 0
10 11 9 2 0
10 11 10 2 0
10 11 11 2 32
10 12 4 2 64
10 12 5 3 4
10 12 6 3 4
10 12 7 3 4
10 12 8 3 4
10 12 9 3 4
10 12 10 3 4
10 12 11 3 32
10 13 4 2 64
10 13 5 3 4
10 13 6 3 4
10 13 7 3 4
10 13 8 3 4
10 13 9 3 4
10 13 10 3 4
10 13 11 3 32
10 14 4 2 64
10 14 5 2 0
10 14 6 2 0
10 14 7 2 0
10 14 8 2 0
10 14 9 2 0
10 14 10 2 0
10 14 11 2 32
10 15 4 2 74
10 15 5 2 8
10 15 6 2 8
10 15 7 2 8
10 15 8 2 8
10 15 9 2 8
10 15 10 2 8
10 15 11 2 42
11 0 5 2 82
11 0 6 2 18
11 0 7 2 18
11 0 8 2 22
11 0 9 2 18
11 0 10 2 18
11 0 11 2 50
11 1 5 2 66
11 1 6 2 0
11 1 7 2 0
11 1 8 2 0
11 1 9 2 0
11 1 10 2 0
11 1 11 2 32
11 2 5 2 64
11 2 6 2 0
11 2 7 2 0
11 2 8 2 0
11 2 9 2 0
11 2 10 2 0
11 2 11 2 44
11 3 4 1 82
11 3 5 1 0
11 3 6 1 0
11 3 7 1 0
11 3 8 1 0
11 3 9 1 0
11 3 10 1 32
11 4 4 2 66
11 4 5 2 0
11 4 6 2 0
11 4 7 2 0
11 4 8 2 0
11 4 9 2 0
11 4 10 2 0
11 4 11 2 48
11 5 4 1 66
11 5 5 3 0
11 5 6 3 0
11 5 7 3 0
11 5 8 3 0
11 5 9 3 0
11 5 10 3 0
11 5 11 3 44
11 6 4 1 66
11 6 5 1 0
11 6 6 1 0
11 6 7 1 0
11 6 8 1 0
11 6 9 1 0
11 6 10 1 32
11 7 4 1 66
11 7 5 1 0
11 7 6 1 0
11 7 7 1 0
11 7 8 1 0
11 7 9 1 0
11 7 10 1 34
11 8 4 1 66
11 8 5 1 0
11 8 6 1 0
11 8 7 1 0
11 8 8 1 0
11 8 9 1 0
11 8 10 1 32
11 9 4 2 66
11 9 5 2 0
11 9 6 2 0
11 9 7 2 0
11 9 8 2 0
11 9 9 2 0
11 9 10 2 0
11 9 11 2 58
11 10 4 2 66
11 10 5 2 2
11 10 6 2 2
11 10 7 3 0
11 10 8 3 0
11 10 9 3 0
11 10 10 3 34
11 11 4 2 66
11 11 5 2 2
11 11 6 2 2
11 11 7 2 0
11 11 8 2 0
11 11 9 2 0
11 11 10 2 0
11 11 11 2 50
11 12 4 2 66
11 12 5 2 2
11 12 6 2 2
11 12 7 2 0
11 12 8 2 0
11 12 9 2 0
11 12 10 2 0
11 12 11 2 34
11 13 4 2 66
11 13 5 2 0
11 13 6 2 0
11 13 7 2 0
11 13 8 2 0
11 13 9 2 0
11 13 10 2 0
11 13 11 2 32
11 14 4 2 74
11 14 5 2 0
11 14 6 2 0
11 14 7 2 0
11 14 8 2 0
11 14 9 2 0
11 14 10 2 0
11 14 11 2 42
11 15 5 2 74
11 15 6 2 10
11 15 7 2 10
11 15 8 2 10
11 15 9 2 10
11 15 10 2 42
12 1 6 2 82
12 1 7 2 18
12 1 8 2 18
12 1 9 2 18
12 1 10 2 18
12 1 11 2 50
12 2 5 2 82
12 2 6 2 2
12 2 7 2 2
12 2 8 2 2
12 2 9 2 2
12 2 10 2 2
12 2 11 2 42
12 3 5 1 66
12 3 6 1 2
12 3 7 1 2
12 3 8 1 0
12 3 9 1 0
12 3 10 1 32
12 4 5 2 66
12 4 6 2 2
12 4 7 3 0
12 4 8 3 0
12 4 9 3 0
12 4 10 3 0
12 4 11 3 48
12 5 5 1 66
12 5 6 1 2
12 5 7 3 0
12 5 8 3 0
12 5 9 3 0
12 5 10 3 0
12 5 11 3 32
12 6 5 1 66
12 6 6 3 0
12 6 7 3 0
12 6 8 3 0
12 6 9 3 0
12 6 10 3 8
12 6 11 3 44
12 7 5 1 66
12 7 6 2 0
12 7 7 2 0
12 7 8 2 0
12 7 9 2 32
12 8 5 1 66
12 8 6 1 0
12 8 7 1 0
12 8 8 1 0
12 8 9 1 0
12 8 10 1 50
12 9 5 1 74
12 9 6 1 8
12 9 7 1 0
12 9 8 1 0
12 9 9 1 0
12 9 10 1 42
12 10 7 3 64
12 10 8 3 0
12 10 9 3 34
12 11 7 3 66
12 11 8 3 2
12 11 9 3 2
12 11 10 3 50
12 12 7 3 66
12 12 8 3 2
12 12 9 3 2
12 12 10 3 34
12 13 5 2 82
12 13 6 2 18
12 13 7 2 2
12 13 8 2 2
12 13 9 2 2
12 13 10 2 2
12 13 11 2 58
12 14 5 2 74
12 14 6 2 10
12 14 7 2 10
12 14 8 2 10
12 14 9 2 10
12 14 10 2 42
13 3 8 3 80
13 3 9 3 16
13 3 10 3 16
13 3 11 3 52
13 4 7 3 80
13 4 8 3 0
13 4 9 3 0
13 4 10 3 0
13 4 11 3 32
13 5 7 3 64
13 5 8 3 0
13 5 9 3 0
13 5 10 3 2
13 5 11 3 34
13 6 6 3 80
13 6 7 3 0
13 6 8 3 0
13 6 9 3 0
13 6 10 3 10
13 6 11 3 42
13 7 6 2 64
13 7 7 2 0
13 7 8 2 0
13 7 9 2 32
13 8 6 2 64
13 8 7 2 0
13 8 8 2 0
13 8 9 2 34
13 9 6 2 74
13 9 7 2 2
13 9 8 2 2
13 9 9 2 42
13 10 7 2 74
13 10 8 2 42
14 3 8 3 82
14 3 9 3 18
14 3 10 3 18
14 3 11 3 50
14 4 7 3 82
14 4 8 3 2
14 4 9 3 2
14 4 10 3 10
14 4 11 3 42
14 5 7 2 66
14 5 8 2 2
14 5 9 2 34
14 6 6 2 82
14 6 7 2 2
14 6 8 2 2
14 6 9 2 34
14 7 6 2 66
14 7 7 2 2
14 7 8 2 2
14 7 9 2 42
14 8 6 2 74
14 8 7 2 10
14 8 8 2 42
