Qubicle Exchange Format
Version 0.2
www.minddesk.com
16 16 16
3
0.878431 0.313726 0.000000
1.000000 0.627451 0.000000
1.000000 1.000000 1.000000
0 6 2 0 124
0 6 5 0 124
1 4 2 0 84
1 4 3 0 52
1 4 8 0 92
1 4 9 0 62
1 5 2 0 68
1 5 3 0 36
1 5 5 0 116
1 6 2 0 72
1 6 3 0 44
1 6 5 0 72
1 6 6 0 60
1 7 8 0 116
1 8 8 0 78
1 8 9 0 62
2 3 2 0 84
2 3 3 0 20
2 3 4 0 20
2 3 5 0 20
2 3 6 0 20
2 3 7 0 20
2 3 8 0 52
2 4 2 0 64
2 4 3 0 0
2 4 4 0 4
2 4 5 0 4
2 4 6 0 4
2 4 7 0 4
2 4 8 0 32
2 5 2 0 64
2 5 3 0 0
2 5 4 0 4
2 5 5 0 0
2 5 6 0 4
2 5 7 0 4
2 5 8 0 36
2 6 2 0 64
2 6 3 0 8
2 6 4 0 12
2 6 5 0 0
2 6 6 0 0
2 6 7 0 4
2 6 8 0 36
2 7 2 0 110
2 7 5 0 76
2 7 6 0 12
2 7 7 0 12
2 7 8 0 40
2 7 11 0 126
3 2 3 0 84
3 2 4 0 20
3 2 5 0 20
3 2 6 0 20
3 2 7 0 20
3 2 8 0 52
3 3 1 0 84
3 3 2 0 16
3 3 3 0 0
3 3 4 0 0
3 3 5 0 0
3 3 6 2 0
3 3 7 2 0
3 3 8 0 0
3 3 9 0 52
3 4 1 0 76
3 4 2 0 0
3 4 3 0 0
3 4 4 0 0
3 4 5 0 0
3 4 6 2 0
3 4 7 2 0
3 4 8 0 0
3 4 9 0 4
3 4 10 0 52
3 5 2 0 64
3 5 3 0 0
3 5 4 0 0
3 5 5 0 0
3 5 6 2 0
3 5 7 2 0
3 5 8 0 0
3 5 9 0 4
3 5 10 0 36
3 6 2 0 74
3 6 3 0 8
3 6 4 0 0
3 6 5 0 0
3 6 6 2 0
3 6 7 2 0
3 6 8 0 0
3 6 9 0 4
3 6 10 0 12
3 6 11 0 54
3 7 4 0 76
3 7 5 0 8
3 7 6 2 0
3 7 7 2 0
3 7 8 0 0
3 7 9 0 44
3 7 11 0 110
3 8 6 2 76
3 8 7 2 4
3 8 8 0 44
3 9 7 2 108
4 1 3 0 84
4 1 4 0 20
4 1 5 0 20
4 1 6 0 20
4 1 7 0 20
4 1 8 0 52
4 2 2 0 84
4 2 3 0 0
4 2 4 0 0
4 2 5 0 0
4 2 6 0 0
4 2 7 0 0
4 2 8 0 0
4 2 9 0 52
4 3 1 0 80
4 3 2 0 0
4 3 3 0 0
4 3 4 1 0
4 3 5 2 0
4 3 6 2 0
4 3 7 2 0
4 3 8 2 0
4 3 9 2 0
4 3 10 0 52
4 4 1 0 72
4 4 2 0 0
4 4 3 0 0
4 4 4 1 0
4 4 5 2 0
4 4 6 2 0
4 4 7 2 0
4 4 8 2 0
4 4 9 2 0
4 4 10 0 32
4 4 13 0 116
4 5 2 0 72
4 5 3 0 0
4 5 4 1 0
4 5 5 2 0
4 5 6 2 0
4 5 7 2 0
4 5 8 2 0
4 5 9 2 0
4 5 10 0 32
4 5 13 0 108
4 6 3 0 72
4 6 4 1 0
4 6 5 2 0
4 6 6 2 0
4 6 7 2 0
4 6 8 2 0
4 6 9 2 0
4 6 10 0 32
4 7 4 1 64
4 7 5 2 0
4 7 6 2 0
4 7 7 2 0
4 7 8 2 0
4 7 9 2 0
4 7 10 0 44
4 8 4 1 78
4 8 5 2 12
4 8 6 2 0
4 8 7 2 0
4 8 8 2 0
4 8 9 2 44
4 9 6 2 76
4 9 7 2 8
4 9 8 2 44
5 0 4 0 84
5 0 5 0 20
5 0 6 0 20
5 0 7 0 52
5 1 3 0 80
5 1 4 0 0
5 1 5 0 0
5 1 6 0 0
5 1 7 0 0
5 1 8 0 48
5 2 2 0 80
5 2 3 0 0
5 2 4 0 0
5 2 5 0 0
5 2 6 0 0
5 2 7 0 0
5 2 8 0 0
5 2 9 0 16
5 2 10 0 52
5 3 1 0 80
5 3 2 0 0
5 3 3 0 0
5 3 4 0 0
5 3 5 2 0
5 3 6 0 0
5 3 7 0 0
5 3 8 0 0
5 3 9 2 0
5 3 10 0 32
5 3 13 0 116
5 4 0 0 92
5 4 1 1 0
5 4 2 0 0
5 4 3 0 0
5 4 4 0 0
5 4 5 2 0
5 4 6 0 0
5 4 7 0 0
5 4 8 0 0
5 4 9 2 0
5 4 10 0 32
5 4 12 0 92
5 4 13 0 32
5 5 1 0 70
5 5 2 0 8
5 5 3 0 0
5 5 4 0 0
5 5 5 2 0
5 5 6 0 0
5 5 7 0 0
5 5 8 0 0
5 5 9 2 0
5 5 10 0 32
5 5 12 0 76
5 5 13 0 96
5 6 1 1 110
5 6 3 0 72
5 6 4 0 0
5 6 5 2 0
5 6 6 0 0
5 6 7 0 0
5 6 8 0 0
5 6 9 2 0
5 6 10 0 32
5 6 12 0 126
5 6 13 0 108
5 7 4 0 72
5 7 5 2 0
5 7 6 0 0
5 7 7 0 0
5 7 8 0 0
5 7 9 2 0
5 7 10 0 32
5 8 5 2 64
5 8 6 0 0
5 8 7 0 0
5 8 8 0 0
5 8 9 2 0
5 8 10 0 44
5 9 5 2 76
5 9 6 0 8
5 9 7 0 8
5 9 8 0 8
5 9 9 2 44
6 0 4 0 80
6 0 5 0 16
6 0 6 0 16
6 0 7 0 48
6 1 3 0 80
6 1 4 0 0
6 1 5 0 0
6 1 6 0 0
6 1 7 0 0
6 1 8 0 48
6 2 2 0 80
6 2 3 0 0
6 2 4 0 0
6 2 5 0 0
6 2 6 0 0
6 2 7 0 0
6 2 8 0 0
6 2 9 0 16
6 2 10 0 48
6 3 1 0 80
6 3 2 0 0
6 3 3 1 0
6 3 4 0 0
6 3 5 0 0
6 3 6 2 0
6 3 7 0 0
6 3 8 0 0
6 3 9 0 0
6 3 10 2 0
6 3 11 0 20
6 3 12 0 20
6 3 13 0 48
6 4 0 0 88
6 4 1 0 8
6 4 2 0 0
6 4 3 1 0
6 4 4 0 0
6 4 5 0 0
6 4 6 2 0
6 4 7 0 0
6 4 8 0 0
6 4 9 0 0
6 4 10 2 0
6 4 11 0 4
6 4 12 0 0
6 4 13 0 32
6 5 2 0 72
6 5 3 1 0
6 5 4 0 0
6 5 5 0 0
6 5 6 2 0
6 5 7 0 0
6 5 8 0 0
6 5 9 0 0
6 5 10 2 0
6 5 11 0 4
6 5 12 0 4
6 5 13 0 32
6 6 3 1 64
6 6 4 0 0
6 6 5 0 0
6 6 6 2 0
6 6 7 0 0
6 6 8 0 0
6 6 9 0 0
6 6 10 2 0
6 6 11 0 4
6 6 12 0 12
6 6 13 0 40
6 7 3 1 76
6 7 4 0 0
6 7 5 0 0
6 7 6 2 0
6 7 7 0 0
6 7 8 0 0
6 7 9 0 0
6 7 10 2 0
6 7 11 0 44
6 7 12 0 126
6 7 13 0 126
6 8 4 0 76
6 8 5 0 0
6 8 6 2 0
6 8 7 0 0
6 8 8 0 0
6 8 9 0 0
6 8 10 2 40
6 9 5 0 72
6 9 6 2 8
6 9 7 0 8
6 9 8 0 8
6 9 9 0 40
7 0 4 0 80
7 0 5 0 16
7 0 6 0 16
7 0 7 0 48
7 1 3 0 80
7 1 4 0 0
7 1 5 0 0
7 1 6 0 0
7 1 7 0 0
7 1 8 0 48
7 2 2 0 80
7 2 3 0 0
7 2 4 0 0
7 2 5 0 0
7 2 6 0 0
7 2 7 0 0
7 2 8 0 0
7 2 9 0 16
7 2 10 0 48
7 3 1 0 80
7 3 2 0 0
7 3 3 0 0
7 3 4 0 0
7 3 5 0 0
7 3 6 2 0
7 3 7 2 0
7 3 8 2 0
7 3 9 2 0
7 3 10 2 0
7 3 11 0 16
7 3 12 0 16
7 3 13 0 48
7 4 0 0 80
7 4 1 0 0
7 4 2 0 0
7 4 3 0 0
7 4 4 0 0
7 4 5 0 0
7 4 6 2 0
7 4 7 2 0
7 4 8 2 0
7 4 9 2 0
7 4 10 2 0
7 4 11 0 0
7 4 12 0 0
7 4 13 0 32
7 5 0 0 68
7 5 1 0 12
7 5 2 0 0
7 5 3 0 0
7 5 4 0 0
7 5 5 0 0
7 5 6 2 0
7 5 7 2 0
7 5 8 2 0
7 5 9 2 0
7 5 10 2 0
7 5 11 0 0
7 5 12 0 0
7 5 13 0 32
7 6 0 1 108
7 6 2 0 76
7 6 3 0 0
7 6 4 0 0
7 6 5 0 0
7 6 6 2 0
7 6 7 2 0
7 6 8 2 0
7 6 9 2 0
7 6 10 2 0
7 6 11 0 0
7 6 12 0 8
7 6 13 0 40
7 7 3 0 72
7 7 4 0 0
7 7 5 0 0
7 7 6 2 0
7 7 7 2 0
7 7 8 2 0
7 7 9 2 0
7 7 10 2 0
7 7 11 0 40
7 7 12 0 44
7 7 13 0 126
7 8 4 0 72
7 8 5 0 0
7 8 6 2 0
7 8 7 2 0
7 8 8 2 0
7 8 9 2 0
7 8 10 2 40
7 8 11 0 126
7 9 5 0 72
7 9 6 2 8
7 9 7 2 8
7 9 8 2 8
7 9 9 2 40
8 0 4 0 80
8 0 5 0 16
8 0 6 0 16
8 0 7 0 48
8 1 3 0 80
8 1 4 0 0
8 1 5 0 0
8 1 6 0 0
8 1 7 0 0
8 1 8 0 48
8 2 2 0 80
8 2 3 0 0
8 2 4 0 0
8 2 5 0 0
8 2 6 0 0
8 2 7 0 0
8 2 8 0 0
8 2 9 0 16
8 2 10 0 48
8 3 1 0 80
8 3 2 0 0
8 3 3 0 0
8 3 4 0 0
8 3 5 0 0
8 3 6 2 0
8 3 7 2 0
8 3 8 2 0
8 3 9 2 0
8 3 10 2 0
8 3 11 0 16
8 3 12 0 16
8 3 13 0 48
8 4 0 0 80
8 4 1 0 0
8 4 2 0 0
8 4 3 0 0
8 4 4 0 0
8 4 5 0 0
8 4 6 2 0
8 4 7 2 0
8 4 8 2 0
8 4 9 2 0
8 4 10 2 0
8 4 11 0 0
8 4 12 0 0
8 4 13 0 32
8 5 0 0 66
8 5 1 0 10
8 5 2 0 0
8 5 3 0 0
8 5 4 0 0
8 5 5 0 0
8 5 6 2 0
8 5 7 2 0
8 5 8 2 0
8 5 9 2 0
8 5 10 2 0
8 5 11 0 0
8 5 12 0 0
8 5 13 0 32
8 6 0 1 106
8 6 2 0 74
8 6 3 0 0
8 6 4 0 0
8 6 5 0 0
8 6 6 2 0
8 6 7 2 0
8 6 8 2 0
8 6 9 2 0
8 6 10 2 0
8 6 11 0 0
8 6 12 0 8
8 6 13 0 40
8 7 3 0 72
8 7 4 0 0
8 7 5 0 0
8 7 6 2 0
8 7 7 2 0
8 7 8 2 0
8 7 9 2 0
8 7 10 2 0
8 7 11 0 40
8 7 12 0 46
8 7 13 0 126
8 8 4 0 72
8 8 5 0 0
8 8 6 2 0
8 8 7 2 0
8 8 8 2 0
8 8 9 2 0
8 8 10 2 40
8 8 11 0 126
8 9 5 0 72
8 9 6 2 8
8 9 7 2 8
8 9 8 2 8
8 9 9 2 40
9 0 4 0 80
9 0 5 0 16
9 0 6 0 16
9 0 7 0 48
9 1 3 0 80
9 1 4 0 0
9 1 5 0 0
9 1 6 0 0
9 1 7 0 0
9 1 8 0 48
9 2 2 0 80
9 2 3 0 0
9 2 4 0 0
9 2 5 0 0
9 2 6 0 0
9 2 7 0 0
9 2 8 0 0
9 2 9 0 16
9 2 10 0 48
9 3 1 0 80
9 3 2 0 0
9 3 3 1 0
9 3 4 0 0
9 3 5 0 0
9 3 6 2 0
9 3 7 0 0
9 3 8 0 0
9 3 9 0 0
9 3 10 2 0
9 3 11 0 18
9 3 12 0 18
9 3 13 0 48
9 4 0 0 88
9 4 1 0 8
9 4 2 0 0
9 4 3 1 0
9 4 4 0 0
9 4 5 0 0
9 4 6 2 0
9 4 7 0 0
9 4 8 0 0
9 4 9 0 0
9 4 10 2 0
9 4 11 0 2
9 4 12 0 0
9 4 13 0 32
9 5 2 0 72
9 5 3 1 0
9 5 4 0 0
9 5 5 0 0
9 5 6 2 0
9 5 7 0 0
9 5 8 0 0
9 5 9 0 0
9 5 10 2 0
9 5 11 0 2
9 5 12 0 0
9 5 13 0 32
9 6 3 1 64
9 6 4 0 0
9 6 5 0 0
9 6 6 2 0
9 6 7 0 0
9 6 8 0 0
9 6 9 0 0
9 6 10 2 0
9 6 11 0 2
9 6 12 0 10
9 6 13 0 40
9 7 3 1 74
9 7 4 0 0
9 7 5 0 0
9 7 6 2 0
9 7 7 0 0
9 7 8 0 0
9 7 9 0 0
9 7 10 2 0
9 7 11 0 42
9 7 12 0 126
9 7 13 0 126
9 8 4 0 74
9 8 5 0 0
9 8 6 2 0
9 8 7 0 0
9 8 8 0 0
9 8 9 0 0
9 8 10 2 40
9 9 5 0 72
9 9 6 2 8
9 9 7 0 8
9 9 8 0 8
9 9 9 0 40
10 0 4 0 82
10 0 5 0 18
10 0 6 0 18
10 0 7 0 50
10 1 3 0 80
10 1 4 0 0
10 1 5 0 0
10 1 6 0 0
10 1 7 0 0
10 1 8 0 48
10 2 2 0 80
10 2 3 0 0
10 2 4 0 0
10 2 5 0 0
10 2 6 0 0
10 2 7 0 0
10 2 8 0 0
10 2 9 0 16
10 2 10 0 50
10 3 1 0 80
10 3 2 0 0
10 3 3 0 0
10 3 4 0 0
10 3 5 2 0
10 3 6 0 0
10 3 7 0 0
10 3 8 0 0
10 3 9 2 0
10 3 10 0 32
10 3 13 0 114
10 4 0 0 90
10 4 1 1 0
10 4 2 0 0
10 4 3 0 0
10 4 4 0 0
10 4 5 2 0
10 4 6 0 0
10 4 7 0 0
10 4 8 0 0
10 4 9 2 0
10 4 10 0 32
10 4 12 0 82
10 4 13 0 32
10 5 1 0 70
10 5 2 0 8
10 5 3 0 0
10 5 4 0 0
10 5 5 2 0
10 5 6 0 0
10 5 7 0 0
10 5 8 0 0
10 5 9 2 0
10 5 10 0 32
10 5 12 0 74
10 5 13 0 32
10 6 1 1 110
10 6 3 0 72
10 6 4 0 0
10 6 5 2 0
10 6 6 0 0
10 6 7 0 0
10 6 8 0 0
10 6 9 2 0
10 6 10 0 32
10 6 12 0 126
10 6 13 0 106
10 7 4 0 72
10 7 5 2 0
10 7 6 0 0
10 7 7 0 0
10 7 8 0 0
10 7 9 2 0
10 7 10 0 32
10 8 5 2 64
10 8 6 0 0
10 8 7 0 0
10 8 8 0 0
10 8 9 2 0
10 8 10 0 42
10 9 5 2 74
10 9 6 0 8
10 9 7 0 8
10 9 8 0 8
10 9 9 2 42
11 1 3 0 82
11 1 4 0 18
11 1 5 0 18
11 1 6 0 18
11 1 7 0 18
11 1 8 0 50
11 2 2 0 82
11 2 3 0 0
11 2 4 0 0
11 2 5 0 0
11 2 6 0 0
11 2 7 0 0
11 2 8 0 0
11 2 9 0 50
11 3 1 0 80
11 3 2 0 0
11 3 3 0 0
11 3 4 1 0
11 3 5 2 0
11 3 6 2 0
11 3 7 2 0
11 3 8 2 0
11 3 9 2 0
11 3 10 0 50
11 4 1 0 72
11 4 2 0 0
11 4 3 0 0
11 4 4 1 0
11 4 5 2 0
11 4 6 2 0
11 4 7 2 0
11 4 8 2 0
11 4 9 2 0
11 4 10 0 32
11 4 13 0 114
11 5 2 0 72
11 5 3 0 0
11 5 4 1 0
11 5 5 2 0
11 5 6 2 0
11 5 7 2 0
11 5 8 2 0
11 5 9 2 0
11 5 10 0 32
11 5 13 0 106
11 6 3 0 72
11 6 4 1 0
11 6 5 2 0
11 6 6 2 0
11 6 7 2 0
11 6 8 2 0
11 6 9 2 0
11 6 10 0 32
11 7 4 1 64
11 7 5 2 0
11 7 6 2 0
11 7 7 2 0
11 7 8 2 0
11 7 9 2 0
11 7 10 0 42
11 8 4 1 78
11 8 5 2 10
11 8 6 2 0
11 8 7 2 0
11 8 8 2 0
11 8 9 2 42
11 9 6 2 74
11 9 7 2 8
11 9 8 2 42
12 2 3 0 82
12 2 4 0 18
12 2 5 0 18
12 2 6 0 18
12 2 7 0 18
12 2 8 0 50
12 3 1 0 82
12 3 2 0 16
12 3 3 0 0
12 3 4 0 0
12 3 5 0 0
12 3 6 2 0
12 3 7 2 0
12 3 8 0 0
12 3 9 0 50
12 4 1 0 74
12 4 2 0 0
12 4 3 0 0
12 4 4 0 0
12 4 5 0 0
12 4 6 2 0
12 4 7 2 0
12 4 8 0 0
12 4 9 0 2
12 4 10 0 50
12 5 2 0 64
12 5 3 0 0
12 5 4 0 0
12 5 5 0 0
12 5 6 2 0
12 5 7 2 0
12 5 8 0 0
12 5 9 0 2
12 5 10 0 34
12 6 2 0 76
12 6 3 0 8
12 6 4 0 0
12 6 5 0 0
12 6 6 2 0
12 6 7 2 0
12 6 8 0 0
12 6 9 0 2
12 6 10 0 10
12 6 11 0 54
12 7 4 0 74
12 7 5 0 8
12 7 6 2 0
12 7 7 2 0
12 7 8 0 0
12 7 9 0 42
12 7 11 0 110
12 8 6 2 74
12 8 7 2 2
12 8 8 0 42
12 9 7 2 106
13 3 2 0 82
13 3 3 0 18
13 3 4 0 18
13 3 5 0 18
13 3 6 0 18
13 3 7 0 18
13 3 8 0 50
13 4 2 0 64
13 4 3 0 0
13 4 4 0 2
13 4 5 0 2
13 4 6 0 2
13 4 7 0 2
13 4 8 0 32
13 5 2 0 64
13 5 3 0 0
13 5 4 0 2
13 5 5 0 0
13 5 6 0 2
13 5 7 0 2
13 5 8 0 34
13 6 2 0 64
13 6 3 0 8
13 6 4 0 10
13 6 5 0 0
13 6 6 0 0
13 6 7 0 2
13 6 8 0 34
13 7 2 0 110
13 7 5 0 74
13 7 6 0 10
13 7 7 0 10
13 7 8 0 40
13 7 11 0 126
14 4 2 0 82
14 4 3 0 50
14 4 8 0 90
14 4 9 0 62
14 5 2 0 66
14 5 3 0 34
14 5 5 0 114
14 6 2 0 72
14 6 3 0 42
14 6 5 0 72
14 6 6 0 58
14 7 8 0 114
14 8 8 0 78
14 8 9 0 62
15 6 2 0 122
15 6 5 0 122
