Qubicle Exchange Format
Version 0.2
www.minddesk.com
16 16 16
4
0.000000 0.000000 0.000000
0.858824 0.168627 0.000000
1.000000 0.607843 0.231373
1.000000 1.000000 1.000000
0 5 6 2 84
0 5 7 2 20
0 5 8 2 20
0 5 9 2 20
0 5 10 2 20
0 5 11 2 54
0 6 6 2 68
0 6 7 2 4
0 6 8 2 4
0 6 9 2 4
0 6 10 2 4
0 6 11 2 36
0 7 6 2 76
0 7 7 2 12
0 7 8 2 12
0 7 9 2 12
0 7 10 2 12
0 7 11 2 46
1 3 5 1 84
1 3 6 1 20
1 3 7 1 20
1 3 8 1 20
1 3 9 1 20
1 3 10 1 52
1 4 5 1 68
1 4 6 1 4
1 4 7 1 4
1 4 8 1 4
1 4 9 1 4
1 4 10 1 36
1 5 5 1 68
1 5 6 1 0
1 5 7 1 0
1 5 8 1 0
1 5 9 1 0
1 5 10 1 32
1 6 5 1 68
1 6 6 2 0
1 6 7 2 0
1 6 8 2 0
1 6 9 2 0
1 6 10 2 0
1 6 11 2 58
1 7 5 1 76
1 7 6 2 0
1 7 7 2 0
1 7 8 2 0
1 7 9 2 0
1 7 10 2 40
1 8 5 1 76
1 8 6 1 76
1 8 7 1 12
1 8 8 1 12
1 8 9 1 44
2 2 5 1 86
2 2 6 1 22
2 2 7 1 22
2 2 8 1 22
2 2 9 1 22
2 2 10 1 54
2 3 5 1 66
2 3 6 1 2
2 3 7 1 2
2 3 8 1 2
2 3 9 1 2
2 3 10 1 34
2 4 5 1 64
2 4 6 1 0
2 4 7 1 0
2 4 8 1 0
2 4 9 1 0
2 4 10 1 34
2 5 5 1 64
2 5 6 1 0
2 5 7 1 0
2 5 8 1 0
2 5 9 1 0
2 5 10 1 32
2 6 5 1 64
2 6 6 1 0
2 6 7 1 0
2 6 8 1 0
2 6 9 1 0
2 6 10 1 32
2 7 5 1 64
2 7 6 1 0
2 7 7 1 0
2 7 8 1 0
2 7 9 1 0
2 7 10 1 32
2 8 5 1 76
2 8 6 1 0
2 8 7 1 0
2 8 8 1 0
2 8 9 1 0
2 8 10 1 44
2 9 5 1 76
2 9 6 1 76
2 9 7 1 12
2 9 8 1 12
2 9 9 1 44
3 0 4 1 92
3 0 5 1 28
3 0 6 1 28
3 0 7 1 28
3 0 8 1 28
3 0 9 1 28
3 0 10 1 60
3 4 4 1 86
3 4 5 1 18
3 4 6 1 18
3 4 7 1 18
3 4 8 1 18
3 4 9 1 50
3 5 4 1 70
3 5 5 1 2
3 5 6 1 2
3 5 7 1 2
3 5 8 1 2
3 5 9 1 2
3 5 10 1 50
3 6 4 1 68
3 6 5 1 0
3 6 6 1 0
3 6 7 1 0
3 6 8 1 0
3 6 9 1 0
3 6 10 1 32
3 7 4 1 68
3 7 5 3 0
3 7 6 3 0
3 7 7 3 0
3 7 8 3 0
3 7 9 3 0
3 7 10 3 0
3 7 11 3 54
3 8 4 1 68
3 8 5 3 0
3 8 6 3 0
3 8 7 3 0
3 8 8 3 0
3 8 9 3 0
3 8 10 3 0
3 8 11 3 44
3 9 4 1 76
3 9 5 1 12
3 9 6 1 0
3 9 7 1 0
3 9 8 1 0
3 9 9 1 0
3 9 10 1 44
3 10 5 1 76
3 10 6 1 76
3 10 7 1 12
3 10 8 1 12
3 10 9 1 44
3 13 7 2 84
3 13 8 2 20
3 13 9 2 52
3 14 7 2 76
3 14 8 2 12
3 14 9 2 44
4 0 4 1 80
4 0 5 1 16
4 0 6 1 16
4 0 7 1 16
4 0 8 1 16
4 0 9 1 16
4 0 10 1 48
4 1 4 1 68
4 1 5 1 4
4 1 6 1 4
4 1 7 1 4
4 1 8 1 4
4 1 9 1 4
4 1 10 1 44
4 2 4 1 76
4 2 5 1 12
4 2 6 1 12
4 2 7 1 12
4 2 8 1 12
4 2 9 1 44
4 6 4 1 80
4 6 5 1 16
4 6 6 1 16
4 6 7 1 16
4 6 8 1 16
4 6 9 1 16
4 6 10 1 48
4 7 4 1 64
4 7 5 1 0
4 7 6 1 0
4 7 7 1 0
4 7 8 1 0
4 7 9 1 0
4 7 10 1 32
4 8 4 1 64
4 8 5 3 0
4 8 6 3 0
4 8 7 3 0
4 8 8 3 0
4 8 9 3 0
4 8 10 3 0
4 8 11 3 48
4 9 4 1 64
4 9 5 3 0
4 9 6 3 0
4 9 7 3 0
4 9 8 3 0
4 9 9 3 0
4 9 10 3 0
4 9 11 3 36
4 10 4 1 68
4 10 5 3 4
4 10 6 3 0
4 10 7 3 0
4 10 8 3 0
4 10 9 3 0
4 10 10 3 4
4 10 11 3 44
4 11 4 1 68
4 11 5 1 4
4 11 6 1 4
4 11 7 1 4
4 11 8 1 4
4 11 9 1 4
4 11 10 1 36
4 12 4 2 68
4 12 5 2 4
4 12 6 2 4
4 12 7 2 4
4 12 8 2 4
4 12 9 2 4
4 12 10 2 4
4 12 11 2 52
4 13 4 3 76
4 13 5 3 4
4 13 6 3 4
4 13 7 3 0
4 13 8 3 0
4 13 9 3 0
4 13 10 3 4
4 13 11 3 44
4 14 5 3 76
4 14 6 3 12
4 14 7 3 8
4 14 8 3 8
4 14 9 3 8
4 14 10 3 44
5 0 4 1 80
5 0 5 2 16
5 0 6 2 16
5 0 7 2 16
5 0 8 2 16
5 0 9 2 16
5 0 10 2 16
5 0 11 2 60
5 1 4 1 64
5 1 5 1 0
5 1 6 1 0
5 1 7 1 0
5 1 8 1 0
5 1 9 1 0
5 1 10 1 32
5 2 4 1 64
5 2 5 1 0
5 2 6 1 0
5 2 7 1 0
5 2 8 1 0
5 2 9 1 0
5 2 10 1 36
5 3 4 1 68
5 3 5 1 4
5 3 6 1 4
5 3 7 1 4
5 3 8 1 4
5 3 9 1 4
5 3 10 1 36
5 4 4 1 68
5 4 5 1 4
5 4 6 1 4
5 4 7 1 4
5 4 8 1 4
5 4 9 1 4
5 4 10 1 36
5 5 4 1 68
5 5 5 1 4
5 5 6 1 4
5 5 7 1 4
5 5 8 1 4
5 5 9 1 4
5 5 10 1 36
5 6 4 1 64
5 6 5 1 0
5 6 6 1 0
5 6 7 1 0
5 6 8 1 0
5 6 9 1 0
5 6 10 1 32
5 7 4 1 64
5 7 5 1 0
5 7 6 1 0
5 7 7 1 0
5 7 8 1 0
5 7 9 1 0
5 7 10 1 32
5 8 4 1 64
5 8 5 3 0
5 8 6 3 0
5 8 7 3 0
5 8 8 3 0
5 8 9 3 0
5 8 10 3 0
5 8 11 3 48
5 9 4 1 64
5 9 5 3 2
5 9 6 3 2
5 9 7 3 2
5 9 8 3 2
5 9 9 3 2
5 9 10 3 2
5 9 11 3 32
5 10 4 1 64
5 10 5 3 0
5 10 6 3 0
5 10 7 3 0
5 10 8 3 0
5 10 9 3 0
5 10 10 3 0
5 10 11 3 32
5 11 4 1 64
5 11 5 3 0
5 11 6 3 0
5 11 7 3 0
5 11 8 3 0
5 11 9 3 0
5 11 10 3 0
5 11 11 3 36
5 12 4 2 64
5 12 5 2 2
5 12 6 2 2
5 12 7 2 2
5 12 8 2 2
5 12 9 2 2
5 12 10 2 2
5 12 11 2 32
5 13 4 2 64
5 13 5 2 2
5 13 6 2 2
5 13 7 2 2
5 13 8 2 2
5 13 9 2 2
5 13 10 2 2
5 13 11 2 32
5 14 4 2 76
5 14 5 2 0
5 14 6 2 0
5 14 7 2 0
5 14 8 2 0
5 14 9 2 0
5 14 10 2 0
5 14 11 2 44
5 15 5 2 76
5 15 6 2 12
5 15 7 2 12
5 15 8 2 12
5 15 9 2 12
5 15 10 2 44
6 0 4 1 80
6 0 5 2 16
6 0 6 2 16
6 0 7 2 16
6 0 8 2 16
6 0 9 2 16
6 0 10 2 16
6 0 11 2 58
6 1 4 1 64
6 1 5 1 0
6 1 6 1 0
6 1 7 1 0
6 1 8 1 0
6 1 9 1 0
6 1 10 1 32
6 2 4 1 64
6 2 5 1 0
6 2 6 1 0
6 2 7 1 0
6 2 8 1 0
6 2 9 1 0
6 2 10 1 32
6 3 4 1 64
6 3 5 1 0
6 3 6 1 0
6 3 7 1 0
6 3 8 1 0
6 3 9 1 0
6 3 10 1 32
6 4 4 1 64
6 4 5 1 0
6 4 6 1 0
6 4 7 1 0
6 4 8 1 0
6 4 9 1 0
6 4 10 1 32
6 5 4 1 64
6 5 5 1 0
6 5 6 1 0
6 5 7 1 0
6 5 8 1 0
6 5 9 1 0
6 5 10 1 32
6 6 4 1 64
6 6 5 3 0
6 6 6 3 0
6 6 7 3 0
6 6 8 3 0
6 6 9 3 0
6 6 10 3 0
6 6 11 3 52
6 7 4 1 64
6 7 5 3 0
6 7 6 3 0
6 7 7 3 0
6 7 8 3 0
6 7 9 3 0
6 7 10 3 0
6 7 11 3 36
6 8 4 1 64
6 8 5 3 8
6 8 6 3 8
6 8 7 3 8
6 8 8 3 8
6 8 9 3 8
6 8 10 3 8
6 8 11 3 32
6 9 4 1 96
6 9 11 0 96
6 10 4 1 64
6 10 5 3 16
6 10 6 3 16
6 10 7 3 16
6 10 8 3 16
6 10 9 3 16
6 10 10 3 16
6 10 11 3 32
6 11 4 2 64
6 11 5 2 8
6 11 6 2 8
6 11 7 2 8
6 11 8 2 8
6 11 9 2 8
6 11 10 2 8
6 11 11 2 32
6 12 4 2 96
6 12 11 0 96
6 13 4 2 96
6 13 11 0 96
6 14 4 2 64
6 14 5 3 16
6 14 6 3 16
6 14 7 3 16
6 14 8 3 16
6 14 9 3 16
6 14 10 3 16
6 14 11 3 32
6 15 4 2 76
6 15 5 2 8
6 15 6 2 8
6 15 7 2 8
6 15 8 2 8
6 15 9 2 8
6 15 10 2 8
6 15 11 2 44
7 0 4 1 80
7 0 5 1 16
7 0 6 1 16
7 0 7 1 16
7 0 8 1 16
7 0 9 1 16
7 0 10 1 48
7 1 4 1 64
7 1 5 1 0
7 1 6 1 0
7 1 7 1 0
7 1 8 1 0
7 1 9 1 0
7 1 10 1 32
7 2 4 1 64
7 2 5 1 0
7 2 6 1 0
7 2 7 1 0
7 2 8 1 0
7 2 9 1 0
7 2 10 1 32
7 3 4 1 64
7 3 5 1 0
7 3 6 1 0
7 3 7 1 0
7 3 8 1 0
7 3 9 1 0
7 3 10 1 32
7 4 4 1 64
7 4 5 1 0
7 4 6 1 0
7 4 7 1 0
7 4 8 1 0
7 4 9 1 0
7 4 10 1 32
7 5 4 1 64
7 5 5 3 0
7 5 6 3 0
7 5 7 3 0
7 5 8 3 0
7 5 9 3 0
7 5 10 3 0
7 5 11 3 52
7 6 4 1 64
7 6 5 3 0
7 6 6 3 0
7 6 7 3 0
7 6 8 3 0
7 6 9 3 0
7 6 10 3 0
7 6 11 3 32
7 7 4 1 64
7 7 5 3 0
7 7 6 3 0
7 7 7 3 0
7 7 8 3 0
7 7 9 3 0
7 7 10 3 0
7 7 11 3 32
7 8 4 1 64
7 8 5 3 8
7 8 6 3 8
7 8 7 3 8
7 8 8 3 8
7 8 9 3 8
7 8 10 3 8
7 8 11 3 32
7 9 4 1 96
7 9 11 0 96
7 10 4 1 64
7 10 5 3 16
7 10 6 3 16
7 10 7 3 16
7 10 8 3 16
7 10 9 3 16
7 10 10 3 16
7 10 11 3 32
7 11 4 2 64
7 11 5 2 0
7 11 6 2 0
7 11 7 2 0
7 11 8 2 0
7 11 9 2 0
7 11 10 2 0
7 11 11 2 32
7 12 4 2 64
7 12 5 2 4
7 12 6 2 4
7 12 7 2 4
7 12 8 2 4
7 12 9 2 4
7 12 10 2 4
7 12 11 2 32
7 13 4 2 64
7 13 5 2 4
7 13 6 2 4
7 13 7 2 4
7 13 8 2 4
7 13 9 2 4
7 13 10 2 4
7 13 11 2 32
7 14 4 2 64
7 14 5 2 0
7 14 6 2 0
7 14 7 2 0
7 14 8 2 0
7 14 9 2 0
7 14 10 2 0
7 14 11 2 32
7 15 4 2 72
7 15 5 2 8
7 15 6 2 8
7 15 7 2 8
7 15 8 2 8
7 15 9 2 8
7 15 10 2 8
7 15 11 2 40
8 0 4 1 80
8 0 5 1 16
8 0 6 1 16
8 0 7 1 16
8 0 8 1 16
8 0 9 1 16
8 0 10 1 48
8 1 4 1 64
8 1 5 1 0
8 1 6 1 0
8 1 7 1 0
8 1 8 1 0
8 1 9 1 0
8 1 10 1 32
8 2 4 1 64
8 2 5 1 0
8 2 6 1 0
8 2 7 1 0
8 2 8 1 0
8 2 9 1 0
8 2 10 1 32
8 3 4 1 64
8 3 5 1 0
8 3 6 1 0
8 3 7 1 0
8 3 8 1 0
8 3 9 1 0
8 3 10 1 32
8 4 4 1 64
8 4 5 1 0
8 4 6 1 0
8 4 7 1 0
8 4 8 1 0
8 4 9 1 0
8 4 10 1 32
8 5 4 1 64
8 5 5 3 0
8 5 6 3 0
8 5 7 3 0
8 5 8 3 0
8 5 9 3 0
8 5 10 3 0
8 5 11 3 50
8 6 4 1 64
8 6 5 3 0
8 6 6 3 0
8 6 7 3 0
8 6 8 3 0
8 6 9 3 0
8 6 10 3 0
8 6 11 3 32
8 7 4 1 64
8 7 5 3 0
8 7 6 3 0
8 7 7 3 0
8 7 8 3 0
8 7 9 3 0
8 7 10 3 0
8 7 11 3 32
8 8 4 1 64
8 8 5 3 8
8 8 6 3 8
8 8 7 3 8
8 8 8 3 8
8 8 9 3 8
8 8 10 3 8
8 8 11 3 32
8 9 4 1 96
8 9 11 0 96
8 10 4 1 64
8 10 5 3 16
8 10 6 3 16
8 10 7 3 16
8 10 8 3 16
8 10 9 3 16
8 10 10 3 16
8 10 11 3 32
8 11 4 2 64
8 11 5 2 0
8 11 6 2 0
8 11 7 2 0
8 11 8 2 0
8 11 9 2 0
8 11 10 2 0
8 11 11 2 32
8 12 4 2 64
8 12 5 2 2
8 12 6 2 2
8 12 7 2 2
8 12 8 2 2
8 12 9 2 2
8 12 10 2 2
8 12 11 2 32
8 13 4 2 64
8 13 5 2 2
8 13 6 2 2
8 13 7 2 2
8 13 8 2 2
8 13 9 2 2
8 13 10 2 2
8 13 11 2 32
8 14 4 2 64
8 14 5 2 0
8 14 6 2 0
8 14 7 2 0
8 14 8 2 0
8 14 9 2 0
8 14 10 2 0
8 14 11 2 32
8 15 4 2 72
8 15 5 2 8
8 15 6 2 8
8 15 7 2 8
8 15 8 2 8
8 15 9 2 8
8 15 10 2 8
8 15 11 2 40
9 0 4 1 80
9 0 5 2 16
9 0 6 2 16
9 0 7 2 16
9 0 8 2 16
9 0 9 2 16
9 0 10 2 16
9 0 11 2 60
9 1 4 1 64
9 1 5 1 0
9 1 6 1 0
9 1 7 1 0
9 1 8 1 0
9 1 9 1 0
9 1 10 1 32
9 2 4 1 64
9 2 5 1 0
9 2 6 1 0
9 2 7 1 0
9 2 8 1 0
9 2 9 1 0
9 2 10 1 32
9 3 4 1 64
9 3 5 1 0
9 3 6 1 0
9 3 7 1 0
9 3 8 1 0
9 3 9 1 0
9 3 10 1 32
9 4 4 1 64
9 4 5 1 0
9 4 6 1 0
9 4 7 1 0
9 4 8 1 0
9 4 9 1 0
9 4 10 1 32
9 5 4 1 64
9 5 5 1 0
9 5 6 1 0
9 5 7 1 0
9 5 8 1 0
9 5 9 1 0
9 5 10 1 32
9 6 4 1 64
9 6 5 3 0
9 6 6 3 0
9 6 7 3 0
9 6 8 3 0
9 6 9 3 0
9 6 10 3 0
9 6 11 3 50
9 7 4 1 64
9 7 5 3 0
9 7 6 3 0
9 7 7 3 0
9 7 8 3 0
9 7 9 3 0
9 7 10 3 0
9 7 11 3 34
9 8 4 1 64
9 8 5 3 8
9 8 6 3 8
9 8 7 3 8
9 8 8 3 8
9 8 9 3 8
9 8 10 3 8
9 8 11 3 32
9 9 4 1 96
9 9 11 0 96
9 10 4 1 64
9 10 5 3 16
9 10 6 3 16
9 10 7 3 16
9 10 8 3 16
9 10 9 3 16
9 10 10 3 16
9 10 11 3 32
9 11 4 2 64
9 11 5 2 8
9 11 6 2 8
9 11 7 2 8
9 11 8 2 8
9 11 9 2 8
9 11 10 2 8
9 11 11 2 32
9 12 4 2 96
9 12 11 0 96
9 13 4 2 96
9 13 11 0 96
9 14 4 2 64
9 14 5 3 16
9 14 6 3 16
9 14 7 3 16
9 14 8 3 16
9 14 9 3 16
9 14 10 3 16
9 14 11 3 32
9 15 4 2 74
9 15 5 2 8
9 15 6 2 8
9 15 7 2 8
9 15 8 2 8
9 15 9 2 8
9 15 10 2 8
9 15 11 2 42
10 0 4 1 80
10 0 5 2 16
10 0 6 2 16
10 0 7 2 16
10 0 8 2 16
10 0 9 2 16
10 0 10 2 16
10 0 11 2 58
10 1 4 1 64
10 1 5 1 0
10 1 6 1 0
10 1 7 1 0
10 1 8 1 0
10 1 9 1 0
10 1 10 1 32
10 2 4 1 64
10 2 5 1 0
10 2 6 1 0
10 2 7 1 0
10 2 8 1 0
10 2 9 1 0
10 2 10 1 34
10 3 4 1 66
10 3 5 1 2
10 3 6 1 2
10 3 7 1 2
10 3 8 1 2
10 3 9 1 2
10 3 10 1 34
10 4 4 1 66
10 4 5 1 2
10 4 6 1 2
10 4 7 1 2
10 4 8 1 2
10 4 9 1 2
10 4 10 1 34
10 5 4 1 66
10 5 5 1 2
10 5 6 1 2
10 5 7 1 2
10 5 8 1 2
10 5 9 1 2
10 5 10 1 34
10 6 4 1 64
10 6 5 1 0
10 6 6 1 0
10 6 7 1 0
10 6 8 1 0
10 6 9 1 0
10 6 10 1 32
10 7 4 1 64
10 7 5 1 0
10 7 6 1 0
10 7 7 1 0
10 7 8 1 0
10 7 9 1 0
10 7 10 1 32
10 8 4 1 64
10 8 5 3 0
10 8 6 3 0
10 8 7 3 0
10 8 8 3 0
10 8 9 3 0
10 8 10 3 0
10 8 11 3 48
10 9 4 1 64
10 9 5 3 4
10 9 6 3 4
10 9 7 3 4
10 9 8 3 4
10 9 9 3 4
10 9 10 3 4
10 9 11 3 32
10 10 4 1 64
10 10 5 3 0
10 10 6 3 0
10 10 7 3 0
10 10 8 3 0
10 10 9 3 0
10 10 10 3 0
10 10 11 3 32
10 11 4 1 64
10 11 5 3 0
10 11 6 3 0
10 11 7 3 0
10 11 8 3 0
10 11 9 3 0
10 11 10 3 0
10 11 11 3 34
10 12 4 2 64
10 12 5 2 4
10 12 6 2 4
10 12 7 2 4
10 12 8 2 4
10 12 9 2 4
10 12 10 2 4
10 12 11 2 32
10 13 4 2 64
10 13 5 2 4
10 13 6 2 4
10 13 7 2 4
10 13 8 2 4
10 13 9 2 4
10 13 10 2 4
10 13 11 2 32
10 14 4 2 74
10 14 5 2 0
10 14 6 2 0
10 14 7 2 0
10 14 8 2 0
10 14 9 2 0
10 14 10 2 0
10 14 11 2 42
10 15 5 2 74
10 15 6 2 10
10 15 7 2 10
10 15 8 2 10
10 15 9 2 10
10 15 10 2 42
11 0 4 1 80
11 0 5 1 16
11 0 6 1 16
11 0 7 1 16
11 0 8 1 16
11 0 9 1 16
11 0 10 1 48
11 1 4 1 66
11 1 5 1 2
11 1 6 1 2
11 1 7 1 2
11 1 8 1 2
11 1 9 1 2
11 1 10 1 42
11 2 4 1 74
11 2 5 1 10
11 2 6 1 10
11 2 7 1 10
11 2 8 1 10
11 2 9 1 42
11 6 4 1 80
11 6 5 1 16
11 6 6 1 16
11 6 7 1 16
11 6 8 1 16
11 6 9 1 16
11 6 10 1 48
11 7 4 1 64
11 7 5 1 0
11 7 6 1 0
11 7 7 1 0
11 7 8 1 0
11 7 9 1 0
11 7 10 1 32
11 8 4 1 64
11 8 5 3 0
11 8 6 3 0
11 8 7 3 0
11 8 8 3 0
11 8 9 3 0
11 8 10 3 0
11 8 11 3 48
11 9 4 1 64
11 9 5 3 0
11 9 6 3 0
11 9 7 3 0
11 9 8 3 0
11 9 9 3 0
11 9 10 3 0
11 9 11 3 34
11 10 4 1 66
11 10 5 3 0
11 10 6 3 0
11 10 7 3 0
11 10 8 3 0
11 10 9 3 0
11 10 10 3 2
11 10 11 3 42
11 11 4 1 66
11 11 5 1 2
11 11 6 1 2
11 11 7 1 2
11 11 8 1 2
11 11 9 1 2
11 11 10 1 34
11 12 4 2 66
11 12 5 2 2
11 12 6 2 2
11 12 7 2 2
11 12 8 2 2
11 12 9 2 2
11 12 10 2 2
11 12 11 2 50
11 13 4 3 74
11 13 5 3 2
11 13 6 3 2
11 13 7 3 0
11 13 8 3 0
11 13 9 3 0
11 13 10 3 2
11 13 11 3 42
11 14 5 3 74
11 14 6 3 10
11 14 7 3 8
11 14 8 3 8
11 14 9 3 8
11 14 10 3 42
12 0 4 1 90
12 0 5 1 26
12 0 6 1 26
12 0 7 1 26
12 0 8 1 26
12 0 9 1 26
12 0 10 1 58
12 4 4 1 86
12 4 5 1 20
12 4 6 1 20
12 4 7 1 20
12 4 8 1 20
12 4 9 1 52
12 5 4 1 70
12 5 5 1 4
12 5 6 1 4
12 5 7 1 4
12 5 8 1 4
12 5 9 1 4
12 5 10 1 52
12 6 4 1 66
12 6 5 1 0
12 6 6 1 0
12 6 7 1 0
12 6 8 1 0
12 6 9 1 0
12 6 10 1 32
12 7 4 1 66
12 7 5 3 0
12 7 6 3 0
12 7 7 3 0
12 7 8 3 0
12 7 9 3 0
12 7 10 3 0
12 7 11 3 54
12 8 4 1 66
12 8 5 3 0
12 8 6 3 0
12 8 7 3 0
12 8 8 3 0
12 8 9 3 0
12 8 10 3 0
12 8 11 3 42
12 9 4 1 74
12 9 5 1 0
12 9 6 1 0
12 9 7 1 0
12 9 8 1 0
12 9 9 1 0
12 9 10 1 42
12 10 5 1 74
12 10 6 1 10
12 10 7 1 10
12 10 8 1 10
12 10 9 1 42
12 13 7 2 82
12 13 8 2 18
12 13 9 2 50
12 14 7 2 74
12 14 8 2 10
12 14 9 2 42
13 2 5 1 86
13 2 6 1 22
13 2 7 1 22
13 2 8 1 22
13 2 9 1 22
13 2 10 1 54
13 3 5 1 68
13 3 6 1 4
13 3 7 1 4
13 3 8 1 4
13 3 9 1 4
13 3 10 1 36
13 4 5 1 64
13 4 6 1 0
13 4 7 1 0
13 4 8 1 0
13 4 9 1 0
13 4 10 1 36
13 5 5 1 64
13 5 6 1 0
13 5 7 1 0
13 5 8 1 0
13 5 9 1 0
13 5 10 1 32
13 6 5 1 64
13 6 6 1 0
13 6 7 1 0
13 6 8 1 0
13 6 9 1 0
13 6 10 1 32
13 7 5 1 64
13 7 6 1 0
13 7 7 1 0
13 7 8 1 0
13 7 9 1 0
13 7 10 1 32
13 8 5 1 64
13 8 6 1 0
13 8 7 1 0
13 8 8 1 0
13 8 9 1 0
13 8 10 1 42
13 9 5 1 74
13 9 6 1 10
13 9 7 1 10
13 9 8 1 10
13 9 9 1 42
14 3 5 1 82
14 3 6 1 18
14 3 7 1 18
14 3 8 1 18
14 3 9 1 18
14 3 10 1 50
14 4 5 1 66
14 4 6 1 2
14 4 7 1 2
14 4 8 1 2
14 4 9 1 2
14 4 10 1 34
14 5 5 1 66
14 5 6 1 0
14 5 7 1 0
14 5 8 1 0
14 5 9 1 0
14 5 10 1 32
14 6 5 1 66
14 6 6 2 0
14 6 7 2 0
14 6 8 2 0
14 6 9 2 0
14 6 10 2 0
14 6 11 2 60
14 7 5 1 66
14 7 6 2 0
14 7 7 2 0
14 7 8 2 0
14 7 9 2 0
14 7 10 2 40
14 8 5 1 74
14 8 6 1 10
14 8 7 1 10
14 8 8 1 10
14 8 9 1 42
15 5 6 2 82
15 5 7 2 18
15 5 8 2 18
15 5 9 2 18
15 5 10 2 18
15 5 11 2 54
15 6 6 2 66
15 6 7 2 2
15 6 8 2 2
15 6 9 2 2
15 6 10 2 2
15 6 11 2 34
15 7 6 2 74
15 7 7 2 10
15 7 8 2 10
15 7 9 2 10
15 7 10 2 10
15 7 11 2 46
