Qubicle Exchange Format
Version 0.2
www.minddesk.com
16 16 16
3
0.878431 0.313726 0.000000
1.000000 0.627451 0.000000
1.000000 1.000000 1.000000
0 2 7 2 92
0 2 8 2 60
0 6 8 2 116
0 7 7 2 92
0 7 8 2 36
0 8 8 2 108
1 2 7 2 88
1 2 8 2 56
1 5 8 2 84
1 5 9 2 52
1 6 7 2 84
1 6 8 0 0
1 6 9 2 4
1 6 10 2 20
1 6 11 0 52
1 7 6 2 126
1 7 7 2 64
1 7 8 0 0
1 7 9 2 12
1 7 10 2 12
1 7 11 0 36
1 8 7 2 68
1 8 8 2 40
1 8 11 0 108
1 9 7 2 108
1 9 8 2 126
2 2 7 2 80
2 2 8 2 48
2 3 7 2 76
2 3 8 2 44
2 5 7 2 84
2 5 8 2 16
2 5 9 2 48
2 5 11 0 116
2 6 6 2 126
2 6 7 2 64
2 6 8 1 0
2 6 9 2 0
2 6 10 2 18
2 6 11 1 32
2 7 6 2 126
2 7 7 2 64
2 7 8 1 2
2 7 9 2 10
2 7 10 2 10
2 7 11 1 32
2 8 6 2 126
2 8 7 2 64
2 8 8 2 32
2 8 11 0 104
2 9 7 2 72
2 9 8 2 44
3 2 7 2 82
3 2 8 2 50
3 3 7 2 74
3 3 8 2 42
3 5 7 2 82
3 5 8 0 18
3 5 9 2 48
3 5 11 0 114
3 6 6 2 126
3 6 7 2 66
3 6 8 2 10
3 6 9 2 40
3 6 11 0 98
3 7 6 2 126
3 7 7 2 98
3 7 11 1 98
3 8 6 2 126
3 8 7 2 66
3 8 8 2 50
3 8 11 1 104
3 9 7 2 74
3 9 8 2 42
3 12 6 2 86
3 12 7 2 22
3 12 8 2 54
3 13 6 2 70
3 13 7 2 6
3 13 8 2 46
3 14 6 2 78
3 14 7 2 46
4 4 5 2 116
4 4 6 2 126
4 4 7 2 126
4 4 8 2 126
4 4 9 2 116
4 5 5 2 110
4 5 6 2 126
4 5 9 2 98
4 6 5 2 126
4 6 9 2 104
4 7 5 2 126
4 8 5 2 126
4 8 9 2 124
4 8 11 1 114
4 9 6 2 126
4 9 8 2 126
4 9 11 1 108
4 10 6 2 86
4 10 7 2 86
4 10 8 2 118
4 11 6 2 94
4 11 7 2 30
4 11 8 2 62
4 11 9 2 126
4 12 5 2 116
4 12 9 2 116
4 13 5 2 108
4 13 9 0 100
4 14 6 2 126
4 14 8 0 94
4 14 9 0 44
4 15 7 2 124
5 4 5 2 120
5 4 9 2 120
5 6 5 2 124
5 6 9 2 120
5 8 5 2 116
5 8 9 2 112
5 9 5 2 100
5 9 9 2 100
5 9 11 1 114
5 10 5 2 100
5 10 9 2 100
5 10 11 1 108
5 11 5 2 100
5 11 9 2 100
5 12 5 2 96
5 12 9 2 96
5 13 5 2 96
5 13 9 2 96
5 14 5 2 108
5 14 9 0 104
5 15 6 2 92
5 15 7 2 24
5 15 8 2 60
6 4 5 2 112
6 4 9 2 112
6 5 5 2 102
6 5 9 2 102
6 6 5 2 96
6 6 9 2 96
6 7 5 2 102
6 7 9 2 102
6 8 5 2 96
6 8 9 2 96
6 9 5 2 98
6 9 9 2 98
6 10 5 2 96
6 10 9 2 96
6 10 11 1 122
6 11 5 2 96
6 11 9 2 96
6 12 5 2 96
6 12 9 0 96
6 13 5 2 96
6 13 9 2 96
6 14 5 2 104
6 14 9 2 104
6 15 6 2 88
6 15 7 2 24
6 15 8 2 56
7 4 5 2 122
7 4 6 2 126
7 4 7 2 126
7 4 8 2 126
7 4 9 2 122
7 6 5 2 122
7 6 9 2 120
7 8 5 2 122
7 8 9 2 122
7 10 5 2 114
7 10 9 2 114
7 11 5 2 98
7 11 9 2 98
7 12 5 2 96
7 12 9 2 96
7 13 5 2 96
7 13 9 2 96
7 14 5 2 106
7 14 9 0 104
7 15 6 2 90
7 15 7 2 24
7 15 8 2 58
8 3 7 2 92
8 3 8 2 60
8 5 5 2 94
8 5 6 2 22
8 5 7 2 22
8 5 8 2 22
8 5 9 2 54
8 6 5 2 126
8 6 6 2 78
8 6 7 2 14
8 6 8 2 14
8 6 9 2 42
8 7 5 2 126
8 8 5 2 126
8 8 6 2 86
8 8 7 2 22
8 8 8 2 54
8 8 9 2 58
8 9 6 2 70
8 9 7 2 4
8 9 8 2 38
8 10 6 2 70
8 10 7 2 6
8 10 8 2 38
8 11 6 2 70
8 11 7 2 6
8 11 8 2 38
8 11 9 2 126
8 12 5 2 82
8 12 6 2 4
8 12 7 2 4
8 12 8 2 4
8 12 9 2 50
8 13 5 2 74
8 13 6 0 4
8 13 7 0 4
8 13 8 0 4
8 13 9 0 34
8 14 6 2 126
8 14 7 0 4
8 14 8 0 14
8 14 9 0 42
8 15 7 2 106
9 0 7 2 84
9 0 8 2 52
9 1 7 2 68
9 1 8 2 36
9 2 7 2 68
9 2 8 2 36
9 3 7 2 74
9 3 8 2 42
9 9 7 2 120
9 12 6 2 82
9 12 7 2 18
9 12 8 2 50
9 13 6 2 66
9 13 7 2 2
9 13 8 2 42
9 14 6 2 74
9 14 7 2 42
10 0 7 2 80
10 0 8 2 48
10 1 7 2 66
10 1 8 2 34
10 2 7 2 74
10 2 8 2 42
10 8 7 2 116
10 9 7 2 104
11 0 7 2 88
11 0 8 2 56
11 8 7 2 112
11 9 6 0 92
11 9 7 0 8
11 9 8 0 60
12 0 7 2 90
12 0 8 2 58
12 6 7 0 116
12 7 7 2 100
12 8 7 2 96
12 9 6 0 88
12 9 7 0 0
12 9 8 0 56
12 10 7 1 100
12 11 7 1 100
12 12 7 1 100
12 13 7 1 100
12 14 7 1 100
12 15 7 1 110
13 6 7 0 114
13 7 7 2 98
13 8 7 2 98
13 9 6 0 88
13 9 7 0 0
13 9 8 0 56
13 10 7 1 98
13 11 7 1 98
13 12 7 1 98
13 13 7 1 98
13 14 7 1 106
14 9 6 0 90
14 9 7 0 26
14 9 8 0 58
