Qubicle Exchange Format
Version 0.2
www.minddesk.com
16 16 16
4
0.000000 0.000000 0.000000
0.078431 0.070588 0.654902
0.258824 0.250980 1.000000
0.572549 0.564706 1.000000
1 10 1 3 84
1 10 2 3 60
1 11 0 3 92
1 11 1 3 44
2 0 4 0 92
2 0 5 0 20
2 0 6 0 28
2 0 7 0 28
2 0 8 0 60
2 1 3 0 124
2 1 5 0 108
2 2 4 0 116
2 2 6 0 116
2 3 4 0 108
2 3 6 0 108
2 4 7 0 124
2 5 6 0 124
2 5 9 0 92
2 5 10 0 60
2 6 8 0 124
2 7 5 0 84
2 7 6 0 60
2 8 2 3 92
2 8 3 3 20
2 8 4 3 20
2 8 5 0 36
2 9 3 3 68
2 9 4 3 4
2 9 5 0 36
2 10 1 3 80
2 10 2 3 16
2 10 3 3 4
2 10 4 3 12
2 10 5 1 4
2 10 6 0 20
2 10 7 0 20
2 10 8 0 52
2 11 0 3 90
2 11 1 3 8
2 11 2 3 12
2 11 3 3 36
2 11 5 1 68
2 11 6 0 4
2 11 7 3 4
2 11 8 3 36
2 12 3 1 68
2 12 4 1 28
2 12 5 1 12
2 12 6 0 12
2 12 7 3 4
2 12 8 3 4
2 12 9 0 60
2 13 2 1 84
2 13 3 1 44
2 13 7 0 76
2 13 8 3 44
2 14 1 1 94
2 14 2 1 44
3 0 3 1 84
3 0 4 0 16
3 0 5 0 16
3 0 6 0 16
3 0 7 0 16
3 0 8 0 16
3 0 9 1 20
3 0 10 1 52
3 1 3 0 64
3 1 4 1 4
3 1 5 0 0
3 1 6 1 4
3 1 7 1 4
3 1 8 1 4
3 1 9 1 4
3 1 10 1 4
3 1 11 1 52
3 2 3 1 68
3 2 4 0 0
3 2 5 1 4
3 2 6 0 0
3 2 7 1 4
3 2 8 1 4
3 2 9 1 4
3 2 10 1 4
3 2 11 1 36
3 3 3 1 68
3 3 4 0 0
3 3 5 1 4
3 3 6 0 0
3 3 7 1 4
3 3 8 1 4
3 3 9 1 4
3 3 10 1 4
3 3 11 0 36
3 4 3 0 68
3 4 4 1 4
3 4 5 1 4
3 4 6 1 4
3 4 7 0 0
3 4 8 1 4
3 4 9 1 4
3 4 10 3 4
3 4 11 3 44
3 5 3 1 68
3 5 4 1 4
3 5 5 1 4
3 5 6 0 0
3 5 7 1 4
3 5 8 1 4
3 5 9 0 0
3 5 10 0 32
3 6 3 1 68
3 6 4 1 4
3 6 5 1 4
3 6 6 1 4
3 6 7 1 4
3 6 8 0 0
3 6 9 1 4
3 6 10 1 4
3 6 11 1 52
3 7 3 1 68
3 7 4 1 4
3 7 5 0 0
3 7 6 0 0
3 7 7 1 4
3 7 8 1 4
3 7 9 1 4
3 7 10 1 4
3 7 11 2 44
3 8 2 3 90
3 8 3 3 2
3 8 4 3 2
3 8 5 0 0
3 8 6 1 4
3 8 7 1 4
3 8 8 2 4
3 8 9 2 4
3 8 10 2 44
3 9 3 3 66
3 9 4 3 2
3 9 5 0 0
3 9 6 1 4
3 9 7 1 4
3 9 8 0 4
3 9 9 2 36
3 10 1 3 82
3 10 2 3 18
3 10 3 3 2
3 10 4 3 2
3 10 5 1 0
3 10 6 0 0
3 10 7 0 0
3 10 8 0 0
3 10 9 1 4
3 10 10 2 52
3 11 1 3 74
3 11 2 3 2
3 11 3 3 2
3 11 4 1 4
3 11 5 1 0
3 11 6 0 0
3 11 7 3 0
3 11 8 3 0
3 11 9 1 4
3 11 10 1 4
3 11 11 2 60
3 12 2 1 68
3 12 3 1 0
3 12 4 1 0
3 12 5 1 8
3 12 6 0 0
3 12 7 3 0
3 12 8 3 0
3 12 9 0 0
3 12 10 1 44
3 13 1 1 94
3 13 2 1 0
3 13 3 1 0
3 13 4 1 44
3 13 6 1 76
3 13 7 0 8
3 13 8 3 8
3 13 9 3 44
3 14 2 1 74
3 14 3 1 44
4 0 2 1 84
4 0 3 1 16
4 0 4 0 16
4 0 5 0 16
4 0 6 0 16
4 0 7 0 16
4 0 8 0 16
4 0 9 1 16
4 0 10 1 16
4 0 11 1 52
4 1 2 1 68
4 1 3 0 0
4 1 4 1 0
4 1 5 0 0
4 1 6 1 0
4 1 7 1 0
4 1 8 1 0
4 1 9 1 0
4 1 10 1 0
4 1 11 1 0
4 1 12 0 52
4 2 2 1 68
4 2 3 1 0
4 2 4 0 0
4 2 5 1 0
4 2 6 0 0
4 2 7 1 0
4 2 8 1 0
4 2 9 1 0
4 2 10 1 0
4 2 11 1 0
4 2 12 3 36
4 3 2 1 68
4 3 3 1 0
4 3 4 0 0
4 3 5 1 0
4 3 6 0 0
4 3 7 1 0
4 3 8 1 0
4 3 9 1 0
4 3 10 1 0
4 3 11 0 0
4 3 12 0 36
4 4 2 0 68
4 4 3 0 0
4 4 4 1 0
4 4 5 1 0
4 4 6 1 0
4 4 7 0 0
4 4 8 1 0
4 4 9 1 0
4 4 10 3 0
4 4 11 3 0
4 4 12 3 44
4 5 2 1 68
4 5 3 1 0
4 5 4 1 0
4 5 5 1 0
4 5 6 0 0
4 5 7 1 0
4 5 8 1 0
4 5 9 0 0
4 5 10 0 0
4 5 11 0 36
4 6 2 1 68
4 6 3 1 0
4 6 4 1 0
4 6 5 1 0
4 6 6 1 0
4 6 7 1 0
4 6 8 0 0
4 6 9 1 0
4 6 10 1 0
4 6 11 1 0
4 6 12 1 52
4 7 2 1 76
4 7 3 1 8
4 7 4 1 8
4 7 5 0 0
4 7 6 0 0
4 7 7 1 0
4 7 8 1 0
4 7 9 1 0
4 7 10 1 0
4 7 11 2 0
4 7 12 2 44
4 8 5 0 64
4 8 6 1 0
4 8 7 1 0
4 8 8 2 0
4 8 9 2 0
4 8 10 2 0
4 8 11 2 44
4 9 5 0 64
4 9 6 1 0
4 9 7 1 0
4 9 8 0 0
4 9 9 2 0
4 9 10 0 36
4 10 5 1 64
4 10 6 0 0
4 10 7 0 0
4 10 8 0 0
4 10 9 1 0
4 10 10 2 0
4 10 11 2 52
4 11 4 1 80
4 11 5 1 0
4 11 6 0 0
4 11 7 3 0
4 11 8 3 0
4 11 9 1 0
4 11 10 1 0
4 11 11 2 32
4 12 2 1 82
4 12 3 1 18
4 12 4 1 2
4 12 5 1 8
4 12 6 0 0
4 12 7 3 0
4 12 8 3 0
4 12 9 0 0
4 12 10 1 0
4 12 11 2 4
4 12 12 2 20
4 12 13 2 60
4 13 2 1 74
4 13 3 1 2
4 13 4 1 42
4 13 6 1 72
4 13 7 0 8
4 13 8 3 0
4 13 9 0 8
4 13 10 1 12
4 13 11 1 12
4 13 12 2 44
4 14 3 1 106
4 14 8 1 108
5 0 1 1 92
5 0 2 1 16
5 0 3 1 16
5 0 4 0 16
5 0 5 0 16
5 0 6 0 16
5 0 7 0 16
5 0 8 0 16
5 0 9 1 16
5 0 10 1 16
5 0 11 1 16
5 0 12 3 52
5 1 2 1 64
5 1 3 0 0
5 1 4 1 0
5 1 5 0 0
5 1 6 1 0
5 1 7 1 0
5 1 8 1 0
5 1 9 1 0
5 1 10 1 0
5 1 11 1 0
5 1 12 0 0
5 1 13 0 52
5 2 2 1 64
5 2 3 1 0
5 2 4 0 0
5 2 5 1 0
5 2 6 0 0
5 2 7 1 0
5 2 8 1 0
5 2 9 1 0
5 2 10 1 0
5 2 11 1 0
5 2 12 3 0
5 2 13 3 36
5 3 2 1 64
5 3 3 1 0
5 3 4 0 0
5 3 5 1 0
5 3 6 0 0
5 3 7 1 0
5 3 8 1 0
5 3 9 1 0
5 3 10 1 0
5 3 11 0 0
5 3 12 0 0
5 3 13 0 44
5 4 2 0 64
5 4 3 0 0
5 4 4 1 0
5 4 5 1 0
5 4 6 1 0
5 4 7 0 0
5 4 8 1 0
5 4 9 1 0
5 4 10 3 0
5 4 11 3 0
5 4 12 3 32
5 5 1 1 84
5 5 2 1 0
5 5 3 1 0
5 5 4 1 0
5 5 5 1 0
5 5 6 0 0
5 5 7 1 0
5 5 8 1 0
5 5 9 0 0
5 5 10 0 0
5 5 11 0 0
5 5 12 0 36
5 6 1 1 68
5 6 2 1 0
5 6 3 1 0
5 6 4 1 0
5 6 5 1 0
5 6 6 1 0
5 6 7 1 0
5 6 8 0 0
5 6 9 1 0
5 6 10 1 0
5 6 11 1 0
5 6 12 1 0
5 6 13 2 60
5 7 1 1 76
5 7 2 1 0
5 7 3 1 0
5 7 4 1 0
5 7 5 0 0
5 7 6 0 0
5 7 7 1 0
5 7 8 1 0
5 7 9 1 0
5 7 10 1 0
5 7 11 2 0
5 7 12 2 32
5 8 2 1 76
5 8 3 1 12
5 8 4 1 12
5 8 5 0 0
5 8 6 1 0
5 8 7 1 0
5 8 8 2 0
5 8 9 2 0
5 8 10 2 0
5 8 11 2 0
5 8 12 0 44
5 9 5 0 64
5 9 6 1 0
5 9 7 1 0
5 9 8 0 0
5 9 9 2 0
5 9 10 0 0
5 9 11 0 36
5 10 5 1 64
5 10 6 0 0
5 10 7 0 0
5 10 8 0 0
5 10 9 1 0
5 10 10 2 0
5 10 11 2 32
5 11 4 1 88
5 11 5 1 0
5 11 6 0 0
5 11 7 3 0
5 11 8 3 0
5 11 9 1 0
5 11 10 1 0
5 11 11 2 0
5 11 12 2 52
5 12 5 1 72
5 12 6 0 0
5 12 7 3 0
5 12 8 3 0
5 12 9 0 0
5 12 10 1 0
5 12 11 2 0
5 12 12 2 0
5 12 13 2 16
5 12 14 3 52
5 13 6 1 72
5 13 7 0 0
5 13 8 3 0
5 13 9 3 0
5 13 10 1 8
5 13 11 1 8
5 13 12 2 0
5 13 13 2 12
5 13 14 2 44
5 14 7 1 76
5 14 8 1 8
5 14 9 1 44
5 14 12 1 108
6 0 1 1 80
6 0 2 1 16
6 0 3 1 16
6 0 4 0 16
6 0 5 0 16
6 0 6 0 16
6 0 7 0 16
6 0 8 0 16
6 0 9 1 16
6 0 10 1 16
6 0 11 1 16
6 0 12 3 16
6 0 13 3 52
6 1 1 1 76
6 1 2 1 0
6 1 3 0 0
6 1 4 1 0
6 1 5 0 0
6 1 6 1 0
6 1 7 1 0
6 1 8 1 0
6 1 9 1 0
6 1 10 1 0
6 1 11 1 0
6 1 12 0 0
6 1 13 0 0
6 1 14 0 52
6 2 2 1 64
6 2 3 1 0
6 2 4 0 0
6 2 5 1 0
6 2 6 0 0
6 2 7 1 0
6 2 8 1 0
6 2 9 1 0
6 2 10 1 0
6 2 11 1 0
6 2 12 3 0
6 2 13 3 0
6 2 14 3 44
6 3 2 1 64
6 3 3 1 0
6 3 4 0 0
6 3 5 1 0
6 3 6 0 0
6 3 7 1 0
6 3 8 1 0
6 3 9 1 0
6 3 10 1 0
6 3 11 0 0
6 3 12 0 0
6 3 13 0 40
6 4 1 1 84
6 4 2 0 0
6 4 3 0 0
6 4 4 1 0
6 4 5 1 0
6 4 6 1 0
6 4 7 0 0
6 4 8 1 0
6 4 9 1 0
6 4 10 3 0
6 4 11 3 0
6 4 12 3 32
6 5 1 1 64
6 5 2 1 0
6 5 3 1 0
6 5 4 1 0
6 5 5 1 0
6 5 6 0 0
6 5 7 1 0
6 5 8 1 0
6 5 9 0 0
6 5 10 0 0
6 5 11 0 0
6 5 12 0 0
6 5 13 0 52
6 6 1 1 64
6 6 2 1 0
6 6 3 1 0
6 6 4 1 0
6 6 5 1 0
6 6 6 1 0
6 6 7 1 0
6 6 8 0 0
6 6 9 1 0
6 6 10 1 0
6 6 11 1 0
6 6 12 1 0
6 6 13 2 0
6 6 14 2 60
6 7 1 1 64
6 7 2 1 0
6 7 3 1 0
6 7 4 1 0
6 7 5 0 0
6 7 6 0 0
6 7 7 1 0
6 7 8 1 0
6 7 9 1 0
6 7 10 1 0
6 7 11 2 0
6 7 12 2 0
6 7 13 2 44
6 8 1 1 76
6 8 2 1 8
6 8 3 1 0
6 8 4 1 0
6 8 5 0 0
6 8 6 1 0
6 8 7 1 0
6 8 8 2 0
6 8 9 2 0
6 8 10 2 0
6 8 11 2 0
6 8 12 0 40
6 9 3 1 76
6 9 4 1 12
6 9 5 0 0
6 9 6 1 0
6 9 7 1 0
6 9 8 0 0
6 9 9 2 0
6 9 10 0 0
6 9 11 0 32
6 10 5 1 64
6 10 6 0 0
6 10 7 0 0
6 10 8 0 0
6 10 9 1 0
6 10 10 2 0
6 10 11 2 32
6 11 4 1 88
6 11 5 1 0
6 11 6 0 0
6 11 7 3 0
6 11 8 3 0
6 11 9 1 0
6 11 10 1 0
6 11 11 2 0
6 11 12 2 48
6 11 14 3 116
6 12 5 1 72
6 12 6 0 0
6 12 7 3 0
6 12 8 3 0
6 12 9 0 0
6 12 10 1 0
6 12 11 2 0
6 12 12 2 0
6 12 13 2 16
6 12 14 3 32
6 13 6 1 72
6 13 7 0 0
6 13 8 3 0
6 13 9 3 0
6 13 10 1 0
6 13 11 1 8
6 13 12 2 0
6 13 13 2 0
6 13 14 2 40
6 14 7 1 72
6 14 8 1 8
6 14 9 1 8
6 14 10 1 44
6 14 12 1 72
6 14 13 2 44
7 0 1 1 80
7 0 2 1 16
7 0 3 1 16
7 0 4 0 16
7 0 5 0 16
7 0 6 0 16
7 0 7 0 16
7 0 8 0 16
7 0 9 1 16
7 0 10 1 16
7 0 11 1 16
7 0 12 3 16
7 0 13 3 16
7 0 14 3 52
7 1 1 1 72
7 1 2 1 0
7 1 3 0 0
7 1 4 1 0
7 1 5 0 0
7 1 6 1 0
7 1 7 1 0
7 1 8 1 0
7 1 9 1 0
7 1 10 1 0
7 1 11 1 0
7 1 12 0 0
7 1 13 0 0
7 1 14 0 32
7 2 2 1 64
7 2 3 1 0
7 2 4 0 0
7 2 5 1 0
7 2 6 0 0
7 2 7 1 0
7 2 8 1 0
7 2 9 1 0
7 2 10 1 0
7 2 11 1 0
7 2 12 3 0
7 2 13 3 0
7 2 14 3 40
7 3 2 1 64
7 3 3 1 0
7 3 4 0 0
7 3 5 1 0
7 3 6 0 0
7 3 7 1 0
7 3 8 1 0
7 3 9 1 0
7 3 10 1 0
7 3 11 0 0
7 3 12 0 0
7 3 13 0 40
7 4 1 1 80
7 4 2 0 0
7 4 3 0 0
7 4 4 1 0
7 4 5 1 0
7 4 6 1 0
7 4 7 0 0
7 4 8 1 0
7 4 9 1 0
7 4 10 3 0
7 4 11 3 0
7 4 12 3 32
7 5 1 1 64
7 5 2 1 0
7 5 3 1 0
7 5 4 1 0
7 5 5 1 0
7 5 6 0 0
7 5 7 1 0
7 5 8 1 0
7 5 9 0 0
7 5 10 0 0
7 5 11 0 0
7 5 12 0 0
7 5 13 0 48
7 6 1 1 64
7 6 2 1 0
7 6 3 1 0
7 6 4 1 0
7 6 5 1 0
7 6 6 1 0
7 6 7 1 0
7 6 8 0 0
7 6 9 1 0
7 6 10 1 0
7 6 11 1 0
7 6 12 1 0
7 6 13 2 0
7 6 14 2 56
7 7 1 1 64
7 7 2 1 0
7 7 3 1 0
7 7 4 1 0
7 7 5 0 0
7 7 6 0 0
7 7 7 1 0
7 7 8 1 0
7 7 9 1 0
7 7 10 1 0
7 7 11 2 0
7 7 12 2 0
7 7 13 2 40
7 8 1 1 72
7 8 2 1 0
7 8 3 1 0
7 8 4 1 0
7 8 5 0 0
7 8 6 1 0
7 8 7 1 0
7 8 8 2 0
7 8 9 2 0
7 8 10 2 0
7 8 11 2 0
7 8 12 0 40
7 9 2 1 76
7 9 3 1 0
7 9 4 1 0
7 9 5 0 0
7 9 6 1 0
7 9 7 1 0
7 9 8 0 0
7 9 9 2 0
7 9 10 0 0
7 9 11 0 32
7 10 3 1 76
7 10 4 1 4
7 10 5 1 0
7 10 6 0 0
7 10 7 0 0
7 10 8 0 0
7 10 9 1 0
7 10 10 2 0
7 10 11 2 32
7 11 4 1 72
7 11 5 1 0
7 11 6 0 0
7 11 7 3 0
7 11 8 3 0
7 11 9 1 0
7 11 10 1 0
7 11 11 2 0
7 11 12 2 48
7 11 14 3 112
7 12 5 1 72
7 12 6 0 0
7 12 7 3 0
7 12 8 3 0
7 12 9 0 0
7 12 10 1 0
7 12 11 2 0
7 12 12 2 0
7 12 13 2 16
7 12 14 3 32
7 13 6 1 72
7 13 7 0 0
7 13 8 3 0
7 13 9 3 0
7 13 10 1 0
7 13 11 1 0
7 13 12 2 0
7 13 13 2 0
7 13 14 2 32
7 14 7 1 72
7 14 8 1 8
7 14 9 1 8
7 14 10 1 8
7 14 11 1 12
7 14 12 1 8
7 14 13 2 8
7 14 14 2 44
8 0 1 1 80
8 0 2 1 16
8 0 3 1 16
8 0 4 0 16
8 0 5 0 16
8 0 6 0 16
8 0 7 0 16
8 0 8 0 16
8 0 9 1 16
8 0 10 1 16
8 0 11 1 16
8 0 12 3 16
8 0 13 3 16
8 0 14 3 50
8 1 1 1 72
8 1 2 1 0
8 1 3 0 0
8 1 4 1 0
8 1 5 0 0
8 1 6 1 0
8 1 7 1 0
8 1 8 1 0
8 1 9 1 0
8 1 10 1 0
8 1 11 1 0
8 1 12 0 0
8 1 13 0 0
8 1 14 0 32
8 2 2 1 64
8 2 3 1 0
8 2 4 0 0
8 2 5 1 0
8 2 6 0 0
8 2 7 1 0
8 2 8 1 0
8 2 9 1 0
8 2 10 1 0
8 2 11 1 0
8 2 12 3 0
8 2 13 3 0
8 2 14 3 40
8 3 2 1 64
8 3 3 1 0
8 3 4 0 0
8 3 5 1 0
8 3 6 0 0
8 3 7 1 0
8 3 8 1 0
8 3 9 1 0
8 3 10 1 0
8 3 11 0 0
8 3 12 0 0
8 3 13 0 40
8 4 1 1 80
8 4 2 0 0
8 4 3 0 0
8 4 4 1 0
8 4 5 1 0
8 4 6 1 0
8 4 7 0 0
8 4 8 1 0
8 4 9 1 0
8 4 10 3 0
8 4 11 3 0
8 4 12 3 32
8 5 1 1 64
8 5 2 1 0
8 5 3 1 0
8 5 4 1 0
8 5 5 1 0
8 5 6 0 0
8 5 7 1 0
8 5 8 1 0
8 5 9 0 0
8 5 10 0 0
8 5 11 0 0
8 5 12 0 0
8 5 13 0 48
8 6 1 1 64
8 6 2 1 0
8 6 3 1 0
8 6 4 1 0
8 6 5 1 0
8 6 6 1 0
8 6 7 1 0
8 6 8 0 0
8 6 9 1 0
8 6 10 1 0
8 6 11 1 0
8 6 12 1 0
8 6 13 2 0
8 6 14 2 56
8 7 1 1 64
8 7 2 1 0
8 7 3 1 0
8 7 4 1 0
8 7 5 0 0
8 7 6 0 0
8 7 7 1 0
8 7 8 1 0
8 7 9 1 0
8 7 10 1 0
8 7 11 2 0
8 7 12 2 0
8 7 13 2 40
8 8 1 1 72
8 8 2 1 0
8 8 3 1 0
8 8 4 1 0
8 8 5 0 0
8 8 6 1 0
8 8 7 1 0
8 8 8 2 0
8 8 9 2 0
8 8 10 2 0
8 8 11 2 0
8 8 12 0 40
8 9 2 1 74
8 9 3 1 0
8 9 4 1 0
8 9 5 0 0
8 9 6 1 0
8 9 7 1 0
8 9 8 0 0
8 9 9 2 0
8 9 10 0 0
8 9 11 0 32
8 10 3 1 74
8 10 4 1 2
8 10 5 1 0
8 10 6 0 0
8 10 7 0 0
8 10 8 0 0
8 10 9 1 0
8 10 10 2 0
8 10 11 2 32
8 11 4 1 72
8 11 5 1 0
8 11 6 0 0
8 11 7 3 0
8 11 8 3 0
8 11 9 1 0
8 11 10 1 0
8 11 11 2 0
8 11 12 2 48
8 11 14 3 112
8 12 5 1 72
8 12 6 0 0
8 12 7 3 0
8 12 8 3 0
8 12 9 0 0
8 12 10 1 0
8 12 11 2 0
8 12 12 2 0
8 12 13 2 16
8 12 14 3 32
8 13 6 1 72
8 13 7 0 0
8 13 8 3 0
8 13 9 3 0
8 13 10 1 0
8 13 11 1 0
8 13 12 2 0
8 13 13 2 0
8 13 14 2 32
8 14 7 1 72
8 14 8 1 8
8 14 9 1 8
8 14 10 1 8
8 14 11 1 10
8 14 12 1 8
8 14 13 2 8
8 14 14 2 42
9 0 1 1 80
9 0 2 1 16
9 0 3 1 16
9 0 4 0 16
9 0 5 0 16
9 0 6 0 16
9 0 7 0 16
9 0 8 0 16
9 0 9 1 16
9 0 10 1 16
9 0 11 1 16
9 0 12 3 16
9 0 13 3 50
9 1 1 1 74
9 1 2 1 0
9 1 3 0 0
9 1 4 1 0
9 1 5 0 0
9 1 6 1 0
9 1 7 1 0
9 1 8 1 0
9 1 9 1 0
9 1 10 1 0
9 1 11 1 0
9 1 12 0 0
9 1 13 0 0
9 1 14 0 50
9 2 2 1 64
9 2 3 1 0
9 2 4 0 0
9 2 5 1 0
9 2 6 0 0
9 2 7 1 0
9 2 8 1 0
9 2 9 1 0
9 2 10 1 0
9 2 11 1 0
9 2 12 3 0
9 2 13 3 0
9 2 14 3 42
9 3 2 1 64
9 3 3 1 0
9 3 4 0 0
9 3 5 1 0
9 3 6 0 0
9 3 7 1 0
9 3 8 1 0
9 3 9 1 0
9 3 10 1 0
9 3 11 0 0
9 3 12 0 0
9 3 13 0 40
9 4 1 1 82
9 4 2 0 0
9 4 3 0 0
9 4 4 1 0
9 4 5 1 0
9 4 6 1 0
9 4 7 0 0
9 4 8 1 0
9 4 9 1 0
9 4 10 3 0
9 4 11 3 0
9 4 12 3 32
9 5 1 1 64
9 5 2 1 0
9 5 3 1 0
9 5 4 1 0
9 5 5 1 0
9 5 6 0 0
9 5 7 1 0
9 5 8 1 0
9 5 9 0 0
9 5 10 0 0
9 5 11 0 0
9 5 12 0 0
9 5 13 0 50
9 6 1 1 64
9 6 2 1 0
9 6 3 1 0
9 6 4 1 0
9 6 5 1 0
9 6 6 1 0
9 6 7 1 0
9 6 8 0 0
9 6 9 1 0
9 6 10 1 0
9 6 11 1 0
9 6 12 1 0
9 6 13 2 0
9 6 14 2 58
9 7 1 1 64
9 7 2 1 0
9 7 3 1 0
9 7 4 1 0
9 7 5 0 0
9 7 6 0 0
9 7 7 1 0
9 7 8 1 0
9 7 9 1 0
9 7 10 1 0
9 7 11 2 0
9 7 12 2 0
9 7 13 2 42
9 8 1 1 74
9 8 2 1 8
9 8 3 1 0
9 8 4 1 0
9 8 5 0 0
9 8 6 1 0
9 8 7 1 0
9 8 8 2 0
9 8 9 2 0
9 8 10 2 0
9 8 11 2 0
9 8 12 0 40
9 9 3 1 74
9 9 4 1 10
9 9 5 0 0
9 9 6 1 0
9 9 7 1 0
9 9 8 0 0
9 9 9 2 0
9 9 10 0 0
9 9 11 0 32
9 10 5 1 64
9 10 6 0 0
9 10 7 0 0
9 10 8 0 0
9 10 9 1 0
9 10 10 2 0
9 10 11 2 32
9 11 4 1 88
9 11 5 1 0
9 11 6 0 0
9 11 7 3 0
9 11 8 3 0
9 11 9 1 0
9 11 10 1 0
9 11 11 2 0
9 11 12 2 48
9 11 14 3 114
9 12 5 1 72
9 12 6 0 0
9 12 7 3 0
9 12 8 3 0
9 12 9 0 0
9 12 10 1 0
9 12 11 2 0
9 12 12 2 0
9 12 13 2 16
9 12 14 3 32
9 13 6 1 72
9 13 7 0 0
9 13 8 3 0
9 13 9 3 0
9 13 10 1 0
9 13 11 1 8
9 13 12 2 0
9 13 13 2 0
9 13 14 2 40
9 14 7 1 72
9 14 8 1 8
9 14 9 1 8
9 14 10 1 42
9 14 12 1 72
9 14 13 2 42
10 0 1 1 90
10 0 2 1 16
10 0 3 1 16
10 0 4 0 16
10 0 5 0 16
10 0 6 0 16
10 0 7 0 16
10 0 8 0 16
10 0 9 1 16
10 0 10 1 16
10 0 11 1 16
10 0 12 3 50
10 1 2 1 64
10 1 3 0 0
10 1 4 1 0
10 1 5 0 0
10 1 6 1 0
10 1 7 1 0
10 1 8 1 0
10 1 9 1 0
10 1 10 1 0
10 1 11 1 0
10 1 12 0 0
10 1 13 0 50
10 2 2 1 64
10 2 3 1 0
10 2 4 0 0
10 2 5 1 0
10 2 6 0 0
10 2 7 1 0
10 2 8 1 0
10 2 9 1 0
10 2 10 1 0
10 2 11 1 0
10 2 12 3 0
10 2 13 3 34
10 3 2 1 64
10 3 3 1 0
10 3 4 0 0
10 3 5 1 0
10 3 6 0 0
10 3 7 1 0
10 3 8 1 0
10 3 9 1 0
10 3 10 1 0
10 3 11 0 0
10 3 12 0 0
10 3 13 0 42
10 4 2 0 64
10 4 3 0 0
10 4 4 1 0
10 4 5 1 0
10 4 6 1 0
10 4 7 0 0
10 4 8 1 0
10 4 9 1 0
10 4 10 3 0
10 4 11 3 0
10 4 12 3 32
10 5 1 1 82
10 5 2 1 0
10 5 3 1 0
10 5 4 1 0
10 5 5 1 0
10 5 6 0 0
10 5 7 1 0
10 5 8 1 0
10 5 9 0 0
10 5 10 0 0
10 5 11 0 0
10 5 12 0 34
10 6 1 1 66
10 6 2 1 0
10 6 3 1 0
10 6 4 1 0
10 6 5 1 0
10 6 6 1 0
10 6 7 1 0
10 6 8 0 0
10 6 9 1 0
10 6 10 1 0
10 6 11 1 0
10 6 12 1 0
10 6 13 2 58
10 7 1 1 74
10 7 2 1 0
10 7 3 1 0
10 7 4 1 0
10 7 5 0 0
10 7 6 0 0
10 7 7 1 0
10 7 8 1 0
10 7 9 1 0
10 7 10 1 0
10 7 11 2 0
10 7 12 2 32
10 8 2 1 74
10 8 3 1 10
10 8 4 1 10
10 8 5 0 0
10 8 6 1 0
10 8 7 1 0
10 8 8 2 0
10 8 9 2 0
10 8 10 2 0
10 8 11 2 0
10 8 12 0 42
10 9 5 0 64
10 9 6 1 0
10 9 7 1 0
10 9 8 0 0
10 9 9 2 0
10 9 10 0 0
10 9 11 0 34
10 10 5 1 64
10 10 6 0 0
10 10 7 0 0
10 10 8 0 0
10 10 9 1 0
10 10 10 2 0
10 10 11 2 32
10 11 4 1 88
10 11 5 1 0
10 11 6 0 0
10 11 7 3 0
10 11 8 3 0
10 11 9 1 0
10 11 10 1 0
10 11 11 2 0
10 11 12 2 50
10 12 5 1 72
10 12 6 0 0
10 12 7 3 0
10 12 8 3 0
10 12 9 0 0
10 12 10 1 0
10 12 11 2 0
10 12 12 2 0
10 12 13 2 16
10 12 14 3 50
10 13 6 1 72
10 13 7 0 0
10 13 8 3 0
10 13 9 3 0
10 13 10 1 8
10 13 11 1 8
10 13 12 2 0
10 13 13 2 10
10 13 14 2 42
10 14 7 1 74
10 14 8 1 8
10 14 9 1 42
10 14 12 1 106
11 0 2 1 80
11 0 3 1 16
11 0 4 0 16
11 0 5 0 16
11 0 6 0 16
11 0 7 0 16
11 0 8 0 16
11 0 9 1 16
11 0 10 1 16
11 0 11 1 50
11 1 2 1 64
11 1 3 0 0
11 1 4 1 0
11 1 5 0 0
11 1 6 1 0
11 1 7 1 0
11 1 8 1 0
11 1 9 1 0
11 1 10 1 0
11 1 11 1 0
11 1 12 0 50
11 2 2 1 64
11 2 3 1 0
11 2 4 0 0
11 2 5 1 0
11 2 6 0 0
11 2 7 1 0
11 2 8 1 0
11 2 9 1 0
11 2 10 1 0
11 2 11 1 0
11 2 12 3 34
11 3 2 1 64
11 3 3 1 0
11 3 4 0 0
11 3 5 1 0
11 3 6 0 0
11 3 7 1 0
11 3 8 1 0
11 3 9 1 0
11 3 10 1 0
11 3 11 0 0
11 3 12 0 34
11 4 2 0 64
11 4 3 0 0
11 4 4 1 0
11 4 5 1 0
11 4 6 1 0
11 4 7 0 0
11 4 8 1 0
11 4 9 1 0
11 4 10 3 0
11 4 11 3 0
11 4 12 3 42
11 5 2 1 64
11 5 3 1 0
11 5 4 1 0
11 5 5 1 0
11 5 6 0 0
11 5 7 1 0
11 5 8 1 0
11 5 9 0 0
11 5 10 0 0
11 5 11 0 34
11 6 2 1 64
11 6 3 1 0
11 6 4 1 0
11 6 5 1 0
11 6 6 1 0
11 6 7 1 0
11 6 8 0 0
11 6 9 1 0
11 6 10 1 0
11 6 11 1 0
11 6 12 1 50
11 7 2 1 72
11 7 3 1 8
11 7 4 1 8
11 7 5 0 0
11 7 6 0 0
11 7 7 1 0
11 7 8 1 0
11 7 9 1 0
11 7 10 1 0
11 7 11 2 0
11 7 12 2 42
11 8 5 0 64
11 8 6 1 0
11 8 7 1 0
11 8 8 2 0
11 8 9 2 0
11 8 10 2 0
11 8 11 2 42
11 9 5 0 64
11 9 6 1 0
11 9 7 1 0
11 9 8 0 0
11 9 9 2 0
11 9 10 0 34
11 10 5 1 64
11 10 6 0 0
11 10 7 0 0
11 10 8 0 0
11 10 9 1 0
11 10 10 2 0
11 10 11 2 50
11 11 4 1 80
11 11 5 1 0
11 11 6 0 0
11 11 7 3 0
11 11 8 3 0
11 11 9 1 0
11 11 10 1 0
11 11 11 2 32
11 12 2 1 84
11 12 3 1 20
11 12 4 1 4
11 12 5 1 8
11 12 6 0 0
11 12 7 3 0
11 12 8 3 0
11 12 9 0 0
11 12 10 1 0
11 12 11 2 2
11 12 12 2 18
11 12 13 2 58
11 13 2 1 76
11 13 3 1 4
11 13 4 1 44
11 13 6 1 72
11 13 7 0 8
11 13 8 3 0
11 13 9 0 8
11 13 10 1 10
11 13 11 1 10
11 13 12 2 42
11 14 3 1 108
11 14 8 1 106
12 0 2 1 82
12 0 3 1 18
12 0 4 0 16
12 0 5 0 16
12 0 6 0 16
12 0 7 0 16
12 0 8 0 16
12 0 9 1 18
12 0 10 1 50
12 1 2 1 66
12 1 3 0 0
12 1 4 1 2
12 1 5 0 0
12 1 6 1 2
12 1 7 1 2
12 1 8 1 2
12 1 9 1 2
12 1 10 1 2
12 1 11 1 50
12 2 2 1 66
12 2 3 1 2
12 2 4 0 0
12 2 5 1 2
12 2 6 0 0
12 2 7 1 2
12 2 8 1 2
12 2 9 1 2
12 2 10 1 2
12 2 11 1 34
12 3 2 1 66
12 3 3 1 2
12 3 4 0 0
12 3 5 1 2
12 3 6 0 0
12 3 7 1 2
12 3 8 1 2
12 3 9 1 2
12 3 10 1 2
12 3 11 0 34
12 4 2 0 64
12 4 3 0 0
12 4 4 1 2
12 4 5 1 2
12 4 6 1 2
12 4 7 0 0
12 4 8 1 2
12 4 9 1 2
12 4 10 3 2
12 4 11 3 42
12 5 2 1 66
12 5 3 1 2
12 5 4 1 2
12 5 5 1 2
12 5 6 0 0
12 5 7 1 2
12 5 8 1 2
12 5 9 0 0
12 5 10 0 32
12 6 2 1 66
12 6 3 1 2
12 6 4 1 2
12 6 5 1 2
12 6 6 1 2
12 6 7 1 2
12 6 8 0 0
12 6 9 1 2
12 6 10 1 2
12 6 11 1 50
12 7 2 1 66
12 7 3 1 2
12 7 4 1 2
12 7 5 0 0
12 7 6 0 0
12 7 7 1 2
12 7 8 1 2
12 7 9 1 2
12 7 10 1 2
12 7 11 2 42
12 8 2 3 76
12 8 3 3 4
12 8 4 3 4
12 8 5 0 0
12 8 6 1 2
12 8 7 1 2
12 8 8 2 2
12 8 9 2 2
12 8 10 2 42
12 9 3 3 68
12 9 4 3 4
12 9 5 0 0
12 9 6 1 2
12 9 7 1 2
12 9 8 0 2
12 9 9 2 34
12 10 1 3 84
12 10 2 3 20
12 10 3 3 4
12 10 4 3 4
12 10 5 1 0
12 10 6 0 0
12 10 7 0 0
12 10 8 0 0
12 10 9 1 2
12 10 10 2 50
12 11 1 3 76
12 11 2 3 4
12 11 3 3 4
12 11 4 1 2
12 11 5 1 0
12 11 6 0 0
12 11 7 3 0
12 11 8 3 0
12 11 9 1 2
12 11 10 1 2
12 11 11 2 58
12 12 2 1 66
12 12 3 1 0
12 12 4 1 0
12 12 5 1 8
12 12 6 0 0
12 12 7 3 0
12 12 8 3 0
12 12 9 0 0
12 12 10 1 42
12 13 1 1 94
12 13 2 1 0
12 13 3 1 0
12 13 4 1 42
12 13 6 1 74
12 13 7 0 8
12 13 8 3 8
12 13 9 3 42
12 14 2 1 76
12 14 3 1 42
13 0 4 0 90
13 0 5 0 18
13 0 6 0 26
13 0 7 0 26
13 0 8 0 58
13 1 3 0 122
13 1 5 0 106
13 2 4 0 114
13 2 6 0 114
13 3 4 0 106
13 3 6 0 106
13 4 2 0 90
13 4 3 0 58
13 4 7 0 122
13 5 6 0 122
13 5 9 0 90
13 5 10 0 58
13 6 8 0 122
13 7 5 0 82
13 7 6 0 58
13 8 2 3 90
13 8 3 3 18
13 8 4 3 18
13 8 5 0 34
13 9 3 3 66
13 9 4 3 2
13 9 5 0 34
13 10 1 3 80
13 10 2 3 16
13 10 3 3 2
13 10 4 3 10
13 10 5 1 2
13 10 6 0 18
13 10 7 0 18
13 10 8 0 50
13 11 0 3 92
13 11 1 3 8
13 11 2 3 10
13 11 3 3 34
13 11 5 1 66
13 11 6 0 2
13 11 7 3 2
13 11 8 3 34
13 12 3 1 66
13 12 4 1 26
13 12 5 1 10
13 12 6 0 10
13 12 7 3 2
13 12 8 3 2
13 12 9 0 58
13 13 2 1 82
13 13 3 1 42
13 13 7 0 74
13 13 8 3 42
13 14 1 1 94
13 14 2 1 42
14 10 1 3 82
14 10 2 3 58
14 11 0 3 90
14 11 1 3 42
