Qubicle Exchange Format
Version 0.2
www.minddesk.com
16 16 16
4
0.000000 0.000000 0.000000
0.078431 0.070588 0.654902
0.258824 0.250980 1.000000
0.572549 0.564706 1.000000
2 1 7 3 84
2 1 8 0 60
2 2 5 3 84
2 2 6 3 20
2 2 7 0 36
2 3 4 3 92
2 3 5 3 4
2 3 6 3 4
2 3 7 0 36
2 4 5 3 68
2 4 6 3 4
2 4 7 0 36
2 5 4 3 84
2 5 5 3 4
2 5 6 3 4
2 5 7 0 44
2 6 4 3 68
2 6 5 1 4
2 6 6 3 36
2 6 8 0 116
2 7 3 1 84
2 7 4 1 12
2 7 5 1 12
2 7 6 1 36
2 7 8 0 68
2 7 9 0 52
2 8 3 1 100
2 8 6 1 68
2 8 7 0 20
2 8 8 3 4
2 8 9 3 36
2 9 3 1 108
2 9 6 1 68
2 9 7 0 4
2 9 8 3 4
2 9 9 3 4
2 9 10 0 20
2 9 11 0 52
2 10 2 1 116
2 10 6 1 76
2 10 7 0 12
2 10 8 3 4
2 10 9 3 4
2 10 10 0 4
2 10 11 3 36
2 11 2 1 100
2 11 5 1 124
2 11 8 0 76
2 11 9 3 4
2 11 10 3 4
2 11 11 0 44
2 12 1 1 84
2 12 2 1 36
2 12 4 1 124
2 12 9 0 76
2 12 10 0 44
2 13 1 1 68
2 13 2 1 12
2 13 3 1 60
2 14 1 1 110
3 0 4 1 84
3 0 5 1 20
3 0 6 1 20
3 0 7 1 20
3 0 8 1 20
3 0 9 2 20
3 0 10 2 20
3 0 11 1 52
3 1 3 1 84
3 1 4 1 4
3 1 5 1 4
3 1 6 1 4
3 1 7 3 0
3 1 8 0 0
3 1 9 1 12
3 1 10 1 12
3 1 11 2 4
3 1 12 2 52
3 2 3 0 68
3 2 4 1 4
3 2 5 3 0
3 2 6 3 0
3 2 7 0 0
3 2 8 1 36
3 2 11 1 76
3 2 12 1 36
3 3 3 1 68
3 3 4 3 0
3 3 5 3 0
3 3 6 3 0
3 3 7 0 0
3 3 8 1 36
3 3 12 1 108
3 4 3 1 68
3 4 4 1 4
3 4 5 3 0
3 4 6 3 0
3 4 7 0 0
3 4 8 1 36
3 5 3 1 68
3 5 4 3 0
3 5 5 3 0
3 5 6 3 0
3 5 7 0 0
3 5 8 1 4
3 5 9 1 52
3 6 3 0 68
3 6 4 3 0
3 6 5 1 0
3 6 6 3 0
3 6 7 1 4
3 6 8 0 0
3 6 9 1 36
3 7 2 1 92
3 7 3 1 0
3 7 4 1 0
3 7 5 1 0
3 7 6 1 0
3 7 7 1 4
3 7 8 0 0
3 7 9 0 0
3 7 10 1 52
3 8 3 1 64
3 8 4 2 4
3 8 5 2 4
3 8 6 1 0
3 8 7 0 0
3 8 8 3 0
3 8 9 3 0
3 8 10 1 4
3 8 11 1 52
3 9 2 1 86
3 9 3 1 0
3 9 4 2 4
3 9 5 0 4
3 9 6 1 0
3 9 7 0 0
3 9 8 3 0
3 9 9 3 0
3 9 10 0 0
3 9 11 0 32
3 10 2 1 64
3 10 3 2 4
3 10 4 0 4
3 10 5 0 4
3 10 6 1 0
3 10 7 0 0
3 10 8 3 0
3 10 9 3 0
3 10 10 0 0
3 10 11 3 32
3 11 1 1 86
3 11 2 1 0
3 11 3 2 4
3 11 4 0 4
3 11 5 1 0
3 11 6 0 4
3 11 7 1 4
3 11 8 0 0
3 11 9 3 0
3 11 10 3 0
3 11 11 0 32
3 12 1 1 64
3 12 2 1 0
3 12 3 0 4
3 12 4 1 8
3 12 5 0 4
3 12 6 0 4
3 12 7 1 4
3 12 8 1 4
3 12 9 0 0
3 12 10 0 0
3 12 11 1 4
3 12 12 1 52
3 13 1 1 74
3 13 2 1 2
3 13 3 1 42
3 13 5 3 70
3 13 6 3 6
3 13 7 1 6
3 13 8 3 6
3 13 9 1 6
3 13 10 3 6
3 13 11 1 6
3 13 12 3 38
3 14 2 1 110
3 14 5 3 78
3 14 6 1 14
3 14 7 3 6
3 14 8 3 6
3 14 9 1 6
3 14 10 3 6
3 14 11 1 6
3 14 12 3 6
3 14 13 3 54
3 15 7 3 78
3 15 8 3 14
3 15 9 1 14
3 15 10 3 14
3 15 11 3 14
3 15 12 1 14
3 15 13 3 14
3 15 14 3 62
4 0 4 1 80
4 0 5 1 16
4 0 6 1 16
4 0 7 1 16
4 0 8 1 126
4 0 9 1 126
4 0 10 1 126
4 0 11 1 16
4 0 12 1 52
4 1 3 1 80
4 1 4 1 0
4 1 5 1 0
4 1 6 1 0
4 1 7 3 0
4 1 8 0 0
4 1 9 1 0
4 1 10 1 0
4 1 11 2 0
4 1 12 2 0
4 1 13 2 52
4 2 2 0 84
4 2 3 0 0
4 2 4 1 0
4 2 5 3 0
4 2 6 3 0
4 2 7 0 0
4 2 8 1 0
4 2 9 0 4
4 2 10 0 12
4 2 11 1 0
4 2 12 1 0
4 2 13 1 36
4 3 2 1 68
4 3 3 1 0
4 3 4 3 0
4 3 5 3 0
4 3 6 3 0
4 3 7 0 0
4 3 8 1 0
4 3 9 0 36
4 3 11 0 76
4 3 12 1 0
4 3 13 1 44
4 4 2 1 68
4 4 3 1 0
4 4 4 1 0
4 4 5 3 0
4 4 6 3 0
4 4 7 0 0
4 4 8 1 0
4 4 9 0 36
4 4 12 0 108
4 5 2 1 68
4 5 3 1 0
4 5 4 3 0
4 5 5 3 0
4 5 6 3 0
4 5 7 0 0
4 5 8 1 0
4 5 9 1 32
4 6 2 0 68
4 6 3 0 0
4 6 4 3 0
4 6 5 1 0
4 6 6 3 0
4 6 7 1 0
4 6 8 0 0
4 6 9 1 32
4 7 2 1 72
4 7 3 1 0
4 7 4 1 0
4 7 5 1 0
4 7 6 1 0
4 7 7 1 0
4 7 8 0 0
4 7 9 0 0
4 7 10 1 48
4 8 3 1 64
4 8 4 2 0
4 8 5 2 0
4 8 6 1 0
4 8 7 0 0
4 8 8 3 0
4 8 9 3 0
4 8 10 1 0
4 8 11 1 16
4 8 12 1 52
4 9 3 1 64
4 9 4 2 0
4 9 5 0 0
4 9 6 1 0
4 9 7 0 0
4 9 8 3 0
4 9 9 3 0
4 9 10 0 0
4 9 11 0 0
4 9 12 1 36
4 10 2 1 82
4 10 3 2 0
4 10 4 0 0
4 10 5 0 0
4 10 6 1 0
4 10 7 0 0
4 10 8 3 0
4 10 9 3 0
4 10 10 0 0
4 10 11 3 0
4 10 12 1 4
4 10 13 1 60
4 11 2 1 66
4 11 3 2 0
4 11 4 0 0
4 11 5 1 0
4 11 6 0 0
4 11 7 1 0
4 11 8 0 0
4 11 9 3 0
4 11 10 3 0
4 11 11 0 0
4 11 12 1 36
4 12 1 1 90
4 12 2 1 10
4 12 3 0 8
4 12 4 1 8
4 12 5 0 8
4 12 6 0 8
4 12 7 1 8
4 12 8 1 8
4 12 9 0 8
4 12 10 0 8
4 12 11 1 8
4 12 12 1 40
5 0 4 1 80
5 0 5 1 16
5 0 6 1 16
5 0 7 1 16
5 0 8 1 126
5 0 9 1 126
5 0 10 1 126
5 0 11 1 126
5 0 12 1 16
5 0 13 1 52
5 1 3 1 80
5 1 4 1 0
5 1 5 1 0
5 1 6 1 0
5 1 7 3 0
5 1 8 0 0
5 1 9 1 0
5 1 10 1 0
5 1 11 2 0
5 1 12 2 0
5 1 13 2 0
5 1 14 2 52
5 2 2 0 80
5 2 3 0 0
5 2 4 1 0
5 2 5 3 0
5 2 6 3 0
5 2 7 0 0
5 2 8 1 0
5 2 9 0 0
5 2 10 0 8
5 2 11 1 0
5 2 12 1 0
5 2 13 1 0
5 2 14 1 44
5 3 2 1 64
5 3 3 1 0
5 3 4 3 0
5 3 5 3 0
5 3 6 3 0
5 3 7 0 0
5 3 8 1 0
5 3 9 0 32
5 3 11 0 72
5 3 12 1 0
5 3 13 1 40
5 4 2 1 64
5 4 3 1 0
5 4 4 1 0
5 4 5 3 0
5 4 6 3 0
5 4 7 0 0
5 4 8 1 0
5 4 9 0 32
5 4 12 0 104
5 5 2 1 64
5 5 3 1 0
5 5 4 3 0
5 5 5 3 0
5 5 6 3 0
5 5 7 0 0
5 5 8 1 0
5 5 9 1 32
5 6 2 0 64
5 6 3 0 0
5 6 4 3 0
5 6 5 1 0
5 6 6 3 0
5 6 7 1 0
5 6 8 0 0
5 6 9 1 32
5 7 2 1 72
5 7 3 1 0
5 7 4 1 0
5 7 5 1 0
5 7 6 1 0
5 7 7 1 0
5 7 8 0 0
5 7 9 0 0
5 7 10 1 48
5 7 13 3 118
5 8 3 1 64
5 8 4 2 0
5 8 5 2 0
5 8 6 1 0
5 8 7 0 0
5 8 8 3 0
5 8 9 3 0
5 8 10 1 0
5 8 11 1 16
5 8 12 1 16
5 8 13 3 36
5 9 3 1 64
5 9 4 2 0
5 9 5 0 0
5 9 6 1 0
5 9 7 0 0
5 9 8 3 0
5 9 9 3 0
5 9 10 0 0
5 9 11 0 0
5 9 12 1 0
5 9 13 1 36
5 10 3 1 126
5 10 4 0 0
5 10 5 0 0
5 10 6 1 0
5 10 7 0 0
5 10 8 3 0
5 10 9 3 0
5 10 10 0 0
5 10 11 3 0
5 10 12 1 0
5 10 13 1 0
5 10 14 1 60
5 11 3 1 126
5 11 4 0 0
5 11 5 1 0
5 11 6 0 0
5 11 7 1 0
5 11 8 0 0
5 11 9 3 0
5 11 10 3 0
5 11 11 0 0
5 11 12 1 0
5 11 13 1 44
5 12 3 1 126
5 12 4 1 8
5 12 5 0 0
5 12 6 0 0
5 12 7 1 0
5 12 8 1 0
5 12 9 0 0
5 12 10 0 0
5 12 11 1 0
5 12 12 1 32
5 13 5 3 70
5 13 6 3 6
5 13 7 1 6
5 13 8 3 6
5 13 9 1 6
5 13 10 3 6
5 13 11 1 6
5 13 12 3 38
5 14 5 3 78
5 14 6 1 14
5 14 7 3 6
5 14 8 3 6
5 14 9 1 6
5 14 10 3 6
5 14 11 1 6
5 14 12 3 6
5 14 13 3 54
5 15 7 3 78
5 15 8 3 14
5 15 9 1 14
5 15 10 3 14
5 15 11 3 14
5 15 12 1 14
5 15 13 3 14
5 15 14 3 62
6 0 4 1 80
6 0 5 1 16
6 0 6 1 16
6 0 7 1 16
6 0 8 1 126
6 0 9 1 126
6 0 10 1 126
6 0 11 1 126
6 0 12 1 16
6 0 13 1 48
6 1 3 1 80
6 1 4 1 0
6 1 5 1 0
6 1 6 1 0
6 1 7 3 0
6 1 8 0 0
6 1 9 1 0
6 1 10 1 0
6 1 11 2 0
6 1 12 2 0
6 1 13 2 0
6 1 14 2 48
6 2 2 0 126
6 2 3 0 0
6 2 4 1 0
6 2 5 3 0
6 2 6 3 0
6 2 7 0 0
6 2 8 1 0
6 2 9 0 0
6 2 10 0 8
6 2 11 1 0
6 2 12 1 0
6 2 13 1 0
6 2 14 1 40
6 3 2 1 64
6 3 3 1 0
6 3 4 3 0
6 3 5 3 0
6 3 6 3 0
6 3 7 0 0
6 3 8 1 0
6 3 9 0 32
6 3 11 0 72
6 3 12 1 0
6 3 13 1 40
6 4 2 1 64
6 4 3 1 0
6 4 4 1 0
6 4 5 3 0
6 4 6 3 0
6 4 7 0 0
6 4 8 1 0
6 4 9 0 32
6 4 12 0 104
6 5 2 1 64
6 5 3 1 0
6 5 4 3 0
6 5 5 3 0
6 5 6 3 0
6 5 7 0 0
6 5 8 1 0
6 5 9 1 32
6 6 2 0 64
6 6 3 0 0
6 6 4 3 0
6 6 5 1 0
6 6 6 3 0
6 6 7 1 0
6 6 8 0 0
6 6 9 1 32
6 7 2 1 72
6 7 3 1 0
6 7 4 1 0
6 7 5 1 0
6 7 6 1 0
6 7 7 1 0
6 7 8 0 0
6 7 9 0 0
6 7 10 1 48
6 8 3 1 64
6 8 4 2 0
6 8 5 2 0
6 8 6 1 0
6 8 7 0 0
6 8 8 3 0
6 8 9 3 0
6 8 10 1 0
6 8 11 1 16
6 8 12 1 16
6 8 13 3 48
6 9 3 1 64
6 9 4 2 0
6 9 5 0 0
6 9 6 1 0
6 9 7 0 0
6 9 8 3 0
6 9 9 3 0
6 9 10 0 0
6 9 11 0 0
6 9 12 1 0
6 9 13 1 32
6 10 3 1 126
6 10 4 0 0
6 10 5 0 0
6 10 6 1 0
6 10 7 0 0
6 10 8 3 0
6 10 9 3 0
6 10 10 0 0
6 10 11 3 0
6 10 12 1 0
6 10 13 1 0
6 10 14 1 48
6 11 3 1 126
6 11 4 0 0
6 11 5 1 0
6 11 6 0 0
6 11 7 1 0
6 11 8 0 0
6 11 9 3 0
6 11 10 3 0
6 11 11 0 0
6 11 12 1 0
6 11 13 1 8
6 11 14 1 44
6 12 3 1 126
6 12 4 1 8
6 12 5 0 8
6 12 6 0 8
6 12 7 1 8
6 12 8 1 8
6 12 9 0 8
6 12 10 0 8
6 12 11 1 8
6 12 12 1 40
7 0 4 1 80
7 0 5 1 16
7 0 6 1 16
7 0 7 1 16
7 0 8 1 126
7 0 9 1 126
7 0 10 1 126
7 0 11 1 16
7 0 12 1 16
7 0 13 1 48
7 1 3 1 80
7 1 4 1 0
7 1 5 1 0
7 1 6 1 0
7 1 7 3 0
7 1 8 0 0
7 1 9 1 0
7 1 10 1 0
7 1 11 2 0
7 1 12 2 0
7 1 13 2 0
7 1 14 2 48
7 2 2 0 126
7 2 3 0 0
7 2 4 1 0
7 2 5 3 0
7 2 6 3 0
7 2 7 0 0
7 2 8 1 0
7 2 9 0 0
7 2 10 0 8
7 2 11 1 0
7 2 12 1 0
7 2 13 1 0
7 2 14 1 40
7 3 2 1 64
7 3 3 1 0
7 3 4 3 0
7 3 5 3 0
7 3 6 3 0
7 3 7 0 0
7 3 8 1 0
7 3 9 0 32
7 3 11 0 72
7 3 12 1 0
7 3 13 1 40
7 4 2 1 64
7 4 3 1 0
7 4 4 1 0
7 4 5 3 0
7 4 6 3 0
7 4 7 0 0
7 4 8 1 0
7 4 9 0 32
7 4 12 0 104
7 5 2 1 64
7 5 3 1 0
7 5 4 3 0
7 5 5 3 0
7 5 6 3 0
7 5 7 0 0
7 5 8 1 0
7 5 9 1 32
7 6 2 0 64
7 6 3 0 0
7 6 4 3 0
7 6 5 1 0
7 6 6 3 0
7 6 7 1 0
7 6 8 0 0
7 6 9 1 32
7 7 2 1 72
7 7 3 1 0
7 7 4 1 0
7 7 5 1 0
7 7 6 1 0
7 7 7 1 0
7 7 8 0 0
7 7 9 0 0
7 7 10 1 48
7 7 13 3 116
7 8 3 1 64
7 8 4 2 0
7 8 5 2 0
7 8 6 1 0
7 8 7 0 0
7 8 8 3 0
7 8 9 3 0
7 8 10 1 0
7 8 11 1 16
7 8 12 1 16
7 8 13 3 32
7 9 3 1 64
7 9 4 2 0
7 9 5 0 0
7 9 6 1 0
7 9 7 0 0
7 9 8 3 0
7 9 9 3 0
7 9 10 0 0
7 9 11 0 0
7 9 12 1 0
7 9 13 1 32
7 10 3 1 126
7 10 4 0 0
7 10 5 0 0
7 10 6 1 0
7 10 7 0 0
7 10 8 3 0
7 10 9 3 0
7 10 10 0 0
7 10 11 3 0
7 10 12 1 0
7 10 13 1 0
7 10 14 1 48
7 11 3 1 126
7 11 4 0 0
7 11 5 1 0
7 11 6 0 0
7 11 7 1 0
7 11 8 0 0
7 11 9 3 0
7 11 10 3 0
7 11 11 0 0
7 11 12 1 0
7 11 13 1 8
7 11 14 1 40
7 12 3 1 126
7 12 4 1 8
7 12 5 0 0
7 12 6 0 0
7 12 7 1 0
7 12 8 1 0
7 12 9 0 0
7 12 10 0 0
7 12 11 1 0
7 12 12 1 32
7 13 5 3 68
7 13 6 3 4
7 13 7 1 4
7 13 8 3 4
7 13 9 1 4
7 13 10 3 4
7 13 11 1 4
7 13 12 3 36
7 14 5 3 76
7 14 6 1 12
7 14 7 3 4
7 14 8 3 4
7 14 9 1 4
7 14 10 3 4
7 14 11 1 4
7 14 12 3 4
7 14 13 3 52
7 15 7 3 76
7 15 8 3 12
7 15 9 1 12
7 15 10 3 12
7 15 11 3 12
7 15 12 1 12
7 15 13 3 12
7 15 14 3 60
8 0 4 1 80
8 0 5 1 16
8 0 6 1 16
8 0 7 1 16
8 0 8 1 126
8 0 9 1 126
8 0 10 1 126
8 0 11 1 16
8 0 12 1 16
8 0 13 1 48
8 1 3 1 80
8 1 4 1 0
8 1 5 1 0
8 1 6 1 0
8 1 7 3 0
8 1 8 0 0
8 1 9 1 0
8 1 10 1 0
8 1 11 2 0
8 1 12 2 0
8 1 13 2 0
8 1 14 2 48
8 2 2 0 126
8 2 3 0 0
8 2 4 1 0
8 2 5 3 0
8 2 6 3 0
8 2 7 0 0
8 2 8 1 0
8 2 9 0 0
8 2 10 0 8
8 2 11 1 0
8 2 12 1 0
8 2 13 1 0
8 2 14 1 40
8 3 2 1 64
8 3 3 1 0
8 3 4 3 0
8 3 5 3 0
8 3 6 3 0
8 3 7 0 0
8 3 8 1 0
8 3 9 0 32
8 3 11 0 72
8 3 12 1 0
8 3 13 1 40
8 4 2 1 64
8 4 3 1 0
8 4 4 1 0
8 4 5 3 0
8 4 6 3 0
8 4 7 0 0
8 4 8 1 0
8 4 9 0 32
8 4 12 0 104
8 5 2 1 64
8 5 3 1 0
8 5 4 3 0
8 5 5 3 0
8 5 6 3 0
8 5 7 0 0
8 5 8 1 0
8 5 9 1 32
8 6 2 0 64
8 6 3 0 0
8 6 4 3 0
8 6 5 1 0
8 6 6 3 0
8 6 7 1 0
8 6 8 0 0
8 6 9 1 32
8 7 2 1 72
8 7 3 1 0
8 7 4 1 0
8 7 5 1 0
8 7 6 1 0
8 7 7 1 0
8 7 8 0 0
8 7 9 0 0
8 7 10 1 48
8 7 13 3 114
8 8 3 1 64
8 8 4 2 0
8 8 5 2 0
8 8 6 1 0
8 8 7 0 0
8 8 8 3 0
8 8 9 3 0
8 8 10 1 0
8 8 11 1 16
8 8 12 1 16
8 8 13 3 32
8 9 3 1 64
8 9 4 2 0
8 9 5 0 0
8 9 6 1 0
8 9 7 0 0
8 9 8 3 0
8 9 9 3 0
8 9 10 0 0
8 9 11 0 0
8 9 12 1 0
8 9 13 1 32
8 10 3 1 126
8 10 4 0 0
8 10 5 0 0
8 10 6 1 0
8 10 7 0 0
8 10 8 3 0
8 10 9 3 0
8 10 10 0 0
8 10 11 3 0
8 10 12 1 0
8 10 13 1 0
8 10 14 1 48
8 11 3 1 126
8 11 4 0 0
8 11 5 1 0
8 11 6 0 0
8 11 7 1 0
8 11 8 0 0
8 11 9 3 0
8 11 10 3 0
8 11 11 0 0
8 11 12 1 0
8 11 13 1 8
8 11 14 1 40
8 12 3 1 126
8 12 4 1 8
8 12 5 0 0
8 12 6 0 0
8 12 7 1 0
8 12 8 1 0
8 12 9 0 0
8 12 10 0 0
8 12 11 1 0
8 12 12 1 32
8 13 5 3 66
8 13 6 3 2
8 13 7 1 2
8 13 8 3 2
8 13 9 1 2
8 13 10 3 2
8 13 11 1 2
8 13 12 3 34
8 14 5 3 74
8 14 6 1 10
8 14 7 3 2
8 14 8 3 2
8 14 9 1 2
8 14 10 3 2
8 14 11 1 2
8 14 12 3 2
8 14 13 3 50
8 15 7 3 74
8 15 8 3 10
8 15 9 1 10
8 15 10 3 10
8 15 11 3 10
8 15 12 1 10
8 15 13 3 10
8 15 14 3 58
9 0 4 1 80
9 0 5 1 16
9 0 6 1 16
9 0 7 1 16
9 0 8 1 126
9 0 9 1 126
9 0 10 1 126
9 0 11 1 16
9 0 12 1 16
9 0 13 1 48
9 1 3 1 80
9 1 4 1 0
9 1 5 1 0
9 1 6 1 0
9 1 7 3 0
9 1 8 0 0
9 1 9 1 0
9 1 10 1 0
9 1 11 2 0
9 1 12 2 0
9 1 13 2 0
9 1 14 2 48
9 2 2 0 126
9 2 3 0 0
9 2 4 1 0
9 2 5 3 0
9 2 6 3 0
9 2 7 0 0
9 2 8 1 0
9 2 9 0 0
9 2 10 0 8
9 2 11 1 0
9 2 12 1 0
9 2 13 1 0
9 2 14 1 40
9 3 2 1 64
9 3 3 1 0
9 3 4 3 0
9 3 5 3 0
9 3 6 3 0
9 3 7 0 0
9 3 8 1 0
9 3 9 0 32
9 3 11 0 72
9 3 12 1 0
9 3 13 1 40
9 4 2 1 64
9 4 3 1 0
9 4 4 1 0
9 4 5 3 0
9 4 6 3 0
9 4 7 0 0
9 4 8 1 0
9 4 9 0 32
9 4 12 0 104
9 5 2 1 64
9 5 3 1 0
9 5 4 3 0
9 5 5 3 0
9 5 6 3 0
9 5 7 0 0
9 5 8 1 0
9 5 9 1 32
9 6 2 0 64
9 6 3 0 0
9 6 4 3 0
9 6 5 1 0
9 6 6 3 0
9 6 7 1 0
9 6 8 0 0
9 6 9 1 32
9 7 2 1 72
9 7 3 1 0
9 7 4 1 0
9 7 5 1 0
9 7 6 1 0
9 7 7 1 0
9 7 8 0 0
9 7 9 0 0
9 7 10 1 48
9 8 3 1 64
9 8 4 2 0
9 8 5 2 0
9 8 6 1 0
9 8 7 0 0
9 8 8 3 0
9 8 9 3 0
9 8 10 1 0
9 8 11 1 16
9 8 12 1 16
9 8 13 3 48
9 9 3 1 64
9 9 4 2 0
9 9 5 0 0
9 9 6 1 0
9 9 7 0 0
9 9 8 3 0
9 9 9 3 0
9 9 10 0 0
9 9 11 0 0
9 9 12 1 0
9 9 13 1 32
9 10 3 1 126
9 10 4 0 0
9 10 5 0 0
9 10 6 1 0
9 10 7 0 0
9 10 8 3 0
9 10 9 3 0
9 10 10 0 0
9 10 11 3 0
9 10 12 1 0
9 10 13 1 0
9 10 14 1 48
9 11 3 1 126
9 11 4 0 0
9 11 5 1 0
9 11 6 0 0
9 11 7 1 0
9 11 8 0 0
9 11 9 3 0
9 11 10 3 0
9 11 11 0 0
9 11 12 1 0
9 11 13 1 8
9 11 14 1 42
9 12 3 1 126
9 12 4 1 8
9 12 5 0 8
9 12 6 0 8
9 12 7 1 8
9 12 8 1 8
9 12 9 0 8
9 12 10 0 8
9 12 11 1 8
9 12 12 1 40
10 0 4 1 80
10 0 5 1 16
10 0 6 1 16
10 0 7 1 16
10 0 8 1 126
10 0 9 1 126
10 0 10 1 126
10 0 11 1 126
10 0 12 1 16
10 0 13 1 50
10 1 3 1 80
10 1 4 1 0
10 1 5 1 0
10 1 6 1 0
10 1 7 3 0
10 1 8 0 0
10 1 9 1 0
10 1 10 1 0
10 1 11 2 0
10 1 12 2 0
10 1 13 2 0
10 1 14 2 50
10 2 2 0 80
10 2 3 0 0
10 2 4 1 0
10 2 5 3 0
10 2 6 3 0
10 2 7 0 0
10 2 8 1 0
10 2 9 0 0
10 2 10 0 8
10 2 11 1 0
10 2 12 1 0
10 2 13 1 0
10 2 14 1 42
10 3 2 1 64
10 3 3 1 0
10 3 4 3 0
10 3 5 3 0
10 3 6 3 0
10 3 7 0 0
10 3 8 1 0
10 3 9 0 32
10 3 11 0 72
10 3 12 1 0
10 3 13 1 40
10 4 2 1 64
10 4 3 1 0
10 4 4 1 0
10 4 5 3 0
10 4 6 3 0
10 4 7 0 0
10 4 8 1 0
10 4 9 0 32
10 4 12 0 104
10 5 2 1 64
10 5 3 1 0
10 5 4 3 0
10 5 5 3 0
10 5 6 3 0
10 5 7 0 0
10 5 8 1 0
10 5 9 1 32
10 6 2 0 64
10 6 3 0 0
10 6 4 3 0
10 6 5 1 0
10 6 6 3 0
10 6 7 1 0
10 6 8 0 0
10 6 9 1 32
10 7 2 1 72
10 7 3 1 0
10 7 4 1 0
10 7 5 1 0
10 7 6 1 0
10 7 7 1 0
10 7 8 0 0
10 7 9 0 0
10 7 10 1 48
10 7 13 3 118
10 8 3 1 64
10 8 4 2 0
10 8 5 2 0
10 8 6 1 0
10 8 7 0 0
10 8 8 3 0
10 8 9 3 0
10 8 10 1 0
10 8 11 1 16
10 8 12 1 16
10 8 13 3 34
10 9 3 1 64
10 9 4 2 0
10 9 5 0 0
10 9 6 1 0
10 9 7 0 0
10 9 8 3 0
10 9 9 3 0
10 9 10 0 0
10 9 11 0 0
10 9 12 1 0
10 9 13 1 34
10 10 3 1 126
10 10 4 0 0
10 10 5 0 0
10 10 6 1 0
10 10 7 0 0
10 10 8 3 0
10 10 9 3 0
10 10 10 0 0
10 10 11 3 0
10 10 12 1 0
10 10 13 1 0
10 10 14 1 58
10 11 3 1 126
10 11 4 0 0
10 11 5 1 0
10 11 6 0 0
10 11 7 1 0
10 11 8 0 0
10 11 9 3 0
10 11 10 3 0
10 11 11 0 0
10 11 12 1 0
10 11 13 1 42
10 12 3 1 126
10 12 4 1 8
10 12 5 0 0
10 12 6 0 0
10 12 7 1 0
10 12 8 1 0
10 12 9 0 0
10 12 10 0 0
10 12 11 1 0
10 12 12 1 32
10 13 5 3 70
10 13 6 3 6
10 13 7 1 6
10 13 8 3 6
10 13 9 1 6
10 13 10 3 6
10 13 11 1 6
10 13 12 3 38
10 14 5 3 78
10 14 6 1 14
10 14 7 3 6
10 14 8 3 6
10 14 9 1 6
10 14 10 3 6
10 14 11 1 6
10 14 12 3 6
10 14 13 3 54
10 15 7 3 78
10 15 8 3 14
10 15 9 1 14
10 15 10 3 14
10 15 11 3 14
10 15 12 1 14
10 15 13 3 14
10 15 14 3 62
11 0 4 1 80
11 0 5 1 16
11 0 6 1 16
11 0 7 1 16
11 0 8 1 16
11 0 9 1 126
11 0 10 1 126
11 0 11 1 16
11 0 12 1 50
11 1 3 1 80
11 1 4 1 0
11 1 5 1 0
11 1 6 1 0
11 1 7 3 0
11 1 8 0 0
11 1 9 1 0
11 1 10 1 0
11 1 11 2 0
11 1 12 2 0
11 1 13 2 50
11 2 2 0 82
11 2 3 0 0
11 2 4 1 0
11 2 5 3 0
11 2 6 3 0
11 2 7 0 0
11 2 8 1 0
11 2 9 0 2
11 2 10 0 10
11 2 11 1 0
11 2 12 1 0
11 2 13 1 34
11 3 2 1 66
11 3 3 1 0
11 3 4 3 0
11 3 5 3 0
11 3 6 3 0
11 3 7 0 0
11 3 8 1 0
11 3 9 0 34
11 3 11 0 74
11 3 12 1 0
11 3 13 1 42
11 4 2 1 66
11 4 3 1 0
11 4 4 1 0
11 4 5 3 0
11 4 6 3 0
11 4 7 0 0
11 4 8 1 0
11 4 9 0 34
11 4 12 0 106
11 5 2 1 66
11 5 3 1 0
11 5 4 3 0
11 5 5 3 0
11 5 6 3 0
11 5 7 0 0
11 5 8 1 0
11 5 9 1 32
11 6 2 0 66
11 6 3 0 0
11 6 4 3 0
11 6 5 1 0
11 6 6 3 0
11 6 7 1 0
11 6 8 0 0
11 6 9 1 32
11 7 2 1 72
11 7 3 1 0
11 7 4 1 0
11 7 5 1 0
11 7 6 1 0
11 7 7 1 0
11 7 8 0 0
11 7 9 0 0
11 7 10 1 48
11 8 3 1 64
11 8 4 2 0
11 8 5 2 0
11 8 6 1 0
11 8 7 0 0
11 8 8 3 0
11 8 9 3 0
11 8 10 1 0
11 8 11 1 16
11 8 12 1 50
11 9 3 1 64
11 9 4 2 0
11 9 5 0 0
11 9 6 1 0
11 9 7 0 0
11 9 8 3 0
11 9 9 3 0
11 9 10 0 0
11 9 11 0 0
11 9 12 1 34
11 10 2 1 84
11 10 3 2 0
11 10 4 0 0
11 10 5 0 0
11 10 6 1 0
11 10 7 0 0
11 10 8 3 0
11 10 9 3 0
11 10 10 0 0
11 10 11 3 0
11 10 12 1 2
11 10 13 1 58
11 11 2 1 68
11 11 3 2 0
11 11 4 0 0
11 11 5 1 0
11 11 6 0 0
11 11 7 1 0
11 11 8 0 0
11 11 9 3 0
11 11 10 3 0
11 11 11 0 0
11 11 12 1 34
11 12 1 1 92
11 12 2 1 4
11 12 3 0 0
11 12 4 1 8
11 12 5 0 8
11 12 6 0 8
11 12 7 1 8
11 12 8 1 8
11 12 9 0 8
11 12 10 0 8
11 12 11 1 8
11 12 12 1 40
11 13 2 1 76
11 13 3 1 44
12 0 4 1 82
12 0 5 1 18
12 0 6 1 18
12 0 7 1 18
12 0 8 1 18
12 0 9 2 18
12 0 10 2 18
12 0 11 1 50
12 1 3 1 82
12 1 4 1 2
12 1 5 1 2
12 1 6 1 2
12 1 7 3 0
12 1 8 0 0
12 1 9 1 10
12 1 10 1 10
12 1 11 2 2
12 1 12 2 50
12 2 3 0 66
12 2 4 1 2
12 2 5 3 0
12 2 6 3 0
12 2 7 0 0
12 2 8 1 34
12 2 11 1 74
12 2 12 1 34
12 3 3 1 66
12 3 4 3 0
12 3 5 3 0
12 3 6 3 0
12 3 7 0 0
12 3 8 1 34
12 3 12 1 106
12 4 3 1 66
12 4 4 1 2
12 4 5 3 0
12 4 6 3 0
12 4 7 0 0
12 4 8 1 34
12 5 3 1 66
12 5 4 3 0
12 5 5 3 0
12 5 6 3 0
12 5 7 0 0
12 5 8 1 2
12 5 9 1 50
12 6 3 0 66
12 6 4 3 0
12 6 5 1 0
12 6 6 3 0
12 6 7 1 2
12 6 8 0 0
12 6 9 1 34
12 7 2 1 90
12 7 3 1 0
12 7 4 1 0
12 7 5 1 0
12 7 6 1 0
12 7 7 1 2
12 7 8 0 0
12 7 9 0 0
12 7 10 1 50
12 8 3 1 64
12 8 4 2 2
12 8 5 2 2
12 8 6 1 0
12 8 7 0 0
12 8 8 3 0
12 8 9 3 0
12 8 10 1 2
12 8 11 1 50
12 9 2 1 86
12 9 3 1 0
12 9 4 2 2
12 9 5 0 2
12 9 6 1 0
12 9 7 0 0
12 9 8 3 0
12 9 9 3 0
12 9 10 0 0
12 9 11 0 32
12 10 2 1 64
12 10 3 2 2
12 10 4 0 2
12 10 5 0 2
12 10 6 1 0
12 10 7 0 0
12 10 8 3 0
12 10 9 3 0
12 10 10 0 0
12 10 11 3 32
12 11 1 1 86
12 11 2 1 0
12 11 3 2 2
12 11 4 0 2
12 11 5 1 0
12 11 6 0 2
12 11 7 1 2
12 11 8 0 0
12 11 9 3 0
12 11 10 3 0
12 11 11 0 32
12 12 1 1 64
12 12 2 1 0
12 12 3 0 2
12 12 4 1 8
12 12 5 0 2
12 12 6 0 2
12 12 7 1 2
12 12 8 1 2
12 12 9 0 0
12 12 10 0 0
12 12 11 1 2
12 12 12 1 50
12 13 1 1 76
12 13 2 1 0
12 13 3 1 40
12 13 5 3 70
12 13 6 3 6
12 13 7 1 6
12 13 8 3 6
12 13 9 1 6
12 13 10 3 6
12 13 11 1 6
12 13 12 3 38
12 14 2 1 110
12 14 5 3 78
12 14 6 1 14
12 14 7 3 6
12 14 8 3 6
12 14 9 1 6
12 14 10 3 6
12 14 11 1 6
12 14 12 3 6
12 14 13 3 54
12 15 7 3 78
12 15 8 3 14
12 15 9 1 14
12 15 10 3 14
12 15 11 3 14
12 15 12 1 14
12 15 13 3 14
12 15 14 3 62
13 1 7 3 82
13 1 8 0 58
13 2 5 3 82
13 2 6 3 18
13 2 7 0 34
13 3 4 3 90
13 3 5 3 2
13 3 6 3 2
13 3 7 0 34
13 4 5 3 66
13 4 6 3 2
13 4 7 0 34
13 5 4 3 82
13 5 5 3 2
13 5 6 3 2
13 5 7 0 42
13 6 4 3 66
13 6 5 1 2
13 6 6 3 34
13 6 8 0 114
13 7 3 1 82
13 7 4 1 10
13 7 5 1 10
13 7 6 1 34
13 7 8 0 66
13 7 9 0 50
13 8 3 1 98
13 8 6 1 66
13 8 7 0 18
13 8 8 3 2
13 8 9 3 34
13 9 3 1 106
13 9 6 1 66
13 9 7 0 2
13 9 8 3 2
13 9 9 3 2
13 9 10 0 18
13 9 11 0 50
13 10 2 1 114
13 10 6 1 74
13 10 7 0 10
13 10 8 3 2
13 10 9 3 2
13 10 10 0 2
13 10 11 3 34
13 11 2 1 98
13 11 5 1 122
13 11 8 0 74
13 11 9 3 2
13 11 10 3 2
13 11 11 0 42
13 12 1 1 82
13 12 2 1 34
13 12 4 1 122
13 12 9 0 74
13 12 10 0 42
13 13 1 1 66
13 13 2 1 10
13 13 3 1 58
13 14 1 1 110
