Qubicle Exchange Format
Version 0.2
www.minddesk.com
16 16 16
3
0.156863 0.000000 0.721569
0.313726 0.501961 1.000000
1.000000 1.000000 1.000000
0 1 7 1 84
0 1 8 1 20
0 1 9 1 20
0 1 10 1 20
0 1 11 2 60
0 2 7 1 68
0 2 8 1 4
0 2 9 1 4
0 2 10 1 44
0 3 7 2 76
0 3 8 1 12
0 3 9 1 44
1 0 4 1 84
1 0 5 1 20
1 0 6 1 20
1 0 7 1 20
1 0 8 1 20
1 0 9 2 20
1 0 10 1 20
1 0 11 1 20
1 0 12 1 20
1 0 13 1 60
1 1 4 1 68
1 1 5 1 4
1 1 6 1 4
1 1 7 1 0
1 1 8 1 0
1 1 9 2 0
1 1 10 1 0
1 1 11 1 0
1 1 12 1 44
1 2 4 1 68
1 2 5 1 4
1 2 6 1 4
1 2 7 1 0
1 2 8 1 0
1 2 9 2 0
1 2 10 1 0
1 2 11 1 44
1 3 4 1 76
1 3 5 2 14
1 3 6 1 12
1 3 7 1 8
1 3 8 1 8
1 3 9 2 8
1 3 10 1 44
2 0 2 1 84
2 0 3 1 20
2 0 4 1 16
2 0 5 0 16
2 0 6 1 16
2 0 7 1 16
2 0 8 1 16
2 0 9 1 16
2 0 10 1 16
2 0 11 1 16
2 0 12 1 16
2 0 13 1 48
2 0 14 1 126
2 1 2 1 68
2 1 3 1 4
2 1 4 1 0
2 1 5 0 0
2 1 6 1 0
2 1 7 1 0
2 1 8 1 0
2 1 9 1 0
2 1 10 1 0
2 1 11 1 0
2 1 12 1 0
2 1 13 2 44
2 2 2 1 76
2 2 3 1 4
2 2 4 1 0
2 2 5 0 8
2 2 6 1 0
2 2 7 1 0
2 2 8 1 0
2 2 9 1 0
2 2 10 1 0
2 2 11 1 0
2 2 12 1 44
2 3 3 1 78
2 3 4 1 42
2 3 6 1 72
2 3 7 1 8
2 3 8 1 8
2 3 9 1 8
2 3 10 1 8
2 3 11 1 44
3 0 2 1 80
3 0 3 0 16
3 0 4 0 16
3 0 5 1 16
3 0 6 1 16
3 0 7 2 16
3 0 8 1 16
3 0 9 1 16
3 0 10 1 16
3 0 11 2 16
3 0 12 1 16
3 0 13 1 48
3 0 14 1 126
3 1 1 1 84
3 1 2 1 0
3 1 3 0 0
3 1 4 0 0
3 1 5 1 0
3 1 6 1 0
3 1 7 2 0
3 1 8 1 0
3 1 9 1 0
3 1 10 1 0
3 1 11 2 0
3 1 12 1 0
3 1 13 1 32
3 1 14 1 126
3 2 1 1 76
3 2 2 1 0
3 2 3 0 8
3 2 4 0 8
3 2 5 1 8
3 2 6 1 0
3 2 7 2 0
3 2 8 1 0
3 2 9 1 0
3 2 10 1 0
3 2 11 2 0
3 2 12 1 0
3 2 13 1 44
3 3 2 1 110
3 3 6 1 72
3 3 7 2 8
3 3 8 1 8
3 3 9 1 8
3 3 10 1 8
3 3 11 2 8
3 3 12 1 44
4 0 2 0 80
4 0 3 1 16
4 0 4 1 16
4 0 5 1 16
4 0 6 1 16
4 0 7 1 16
4 0 8 1 16
4 0 9 2 16
4 0 10 1 16
4 0 11 1 16
4 0 12 1 16
4 0 13 1 48
4 0 14 0 126
4 1 1 1 82
4 1 2 0 0
4 1 3 1 0
4 1 4 1 0
4 1 5 1 0
4 1 6 1 0
4 1 7 1 0
4 1 8 1 0
4 1 9 2 0
4 1 10 1 0
4 1 11 1 0
4 1 12 1 0
4 1 13 1 0
4 1 14 1 52
4 1 15 1 126
4 2 1 1 66
4 2 2 0 8
4 2 3 1 8
4 2 4 1 0
4 2 5 1 0
4 2 6 1 0
4 2 7 1 0
4 2 8 1 0
4 2 9 2 0
4 2 10 1 0
4 2 11 1 0
4 2 12 1 0
4 2 13 1 0
4 2 14 1 44
4 3 1 1 110
4 3 4 1 76
4 3 5 1 12
4 3 6 1 8
4 3 7 1 8
4 3 8 1 8
4 3 9 2 8
4 3 10 1 8
4 3 11 1 8
4 3 12 1 8
4 3 13 1 44
5 0 2 1 80
5 0 3 1 16
5 0 4 1 16
5 0 5 1 16
5 0 6 1 16
5 0 7 1 16
5 0 8 1 16
5 0 9 1 16
5 0 10 1 16
5 0 11 2 16
5 0 12 1 16
5 0 13 1 48
5 0 14 0 126
5 1 2 1 64
5 1 3 1 0
5 1 4 1 0
5 1 5 1 0
5 1 6 1 0
5 1 7 1 0
5 1 8 1 0
5 1 9 1 0
5 1 10 1 0
5 1 11 2 0
5 1 12 1 0
5 1 13 1 0
5 1 14 1 48
5 1 15 0 126
5 2 2 1 72
5 2 3 1 0
5 2 4 1 0
5 2 5 1 0
5 2 6 1 0
5 2 7 1 0
5 2 8 1 0
5 2 9 1 0
5 2 10 1 0
5 2 11 2 0
5 2 12 1 0
5 2 13 1 0
5 2 14 1 32
5 3 3 1 76
5 3 4 1 8
5 3 5 1 10
5 3 6 1 10
5 3 7 1 10
5 3 8 1 8
5 3 9 1 10
5 3 10 1 8
5 3 11 2 8
5 3 12 1 8
5 3 13 1 8
5 3 14 2 44
6 0 2 1 80
6 0 3 1 16
6 0 4 1 16
6 0 5 0 16
6 0 6 2 16
6 0 7 1 16
6 0 8 1 16
6 0 9 1 16
6 0 10 1 16
6 0 11 1 16
6 0 12 1 16
6 0 13 1 48
6 0 14 0 126
6 1 1 1 84
6 1 2 1 0
6 1 3 1 0
6 1 4 1 0
6 1 5 0 0
6 1 6 2 0
6 1 7 1 0
6 1 8 1 0
6 1 9 1 0
6 1 10 1 0
6 1 11 1 0
6 1 12 1 0
6 1 13 1 0
6 1 14 1 48
6 1 15 0 126
6 2 1 1 76
6 2 2 1 0
6 2 3 1 0
6 2 4 1 0
6 2 5 0 8
6 2 6 2 8
6 2 7 1 8
6 2 8 1 0
6 2 9 1 8
6 2 10 1 0
6 2 11 1 0
6 2 12 1 0
6 2 13 1 0
6 2 14 1 32
6 3 2 1 76
6 3 3 1 10
6 3 4 1 42
6 3 8 1 104
6 3 9 1 126
6 3 10 1 74
6 3 11 1 8
6 3 12 1 8
6 3 13 1 8
6 3 14 1 42
7 0 2 1 80
7 0 3 0 16
7 0 4 0 16
7 0 5 1 16
7 0 6 1 16
7 0 7 1 16
7 0 8 1 16
7 0 9 1 16
7 0 10 0 16
7 0 11 1 16
7 0 12 1 16
7 0 13 2 48
7 0 14 0 126
7 1 1 1 80
7 1 2 1 0
7 1 3 0 0
7 1 4 0 0
7 1 5 1 0
7 1 6 1 0
7 1 7 1 0
7 1 8 1 0
7 1 9 1 0
7 1 10 0 0
7 1 11 1 0
7 1 12 1 0
7 1 13 2 0
7 1 14 1 48
7 1 15 0 126
7 2 1 1 64
7 2 2 1 0
7 2 3 0 8
7 2 4 0 8
7 2 5 1 8
7 2 6 1 0
7 2 7 1 0
7 2 8 1 0
7 2 9 1 0
7 2 10 0 8
7 2 11 1 0
7 2 12 1 0
7 2 13 2 0
7 2 14 1 42
7 3 1 1 78
7 3 2 1 40
7 3 6 1 76
7 3 7 1 12
7 3 8 1 8
7 3 9 1 44
7 3 11 1 72
7 3 12 1 8
7 3 13 2 40
8 0 2 1 80
8 0 3 0 16
8 0 4 1 16
8 0 5 1 16
8 0 6 1 16
8 0 7 1 16
8 0 8 1 16
8 0 9 1 16
8 0 10 0 16
8 0 11 1 16
8 0 12 1 16
8 0 13 1 48
8 0 14 0 126
8 1 1 1 82
8 1 2 1 0
8 1 3 0 0
8 1 4 1 0
8 1 5 1 0
8 1 6 1 0
8 1 7 1 0
8 1 8 1 0
8 1 9 1 0
8 1 10 0 0
8 1 11 1 0
8 1 12 1 0
8 1 13 1 0
8 1 14 0 56
8 2 1 1 74
8 2 2 1 0
8 2 3 0 8
8 2 4 1 8
8 2 5 1 0
8 2 6 1 0
8 2 7 1 0
8 2 8 1 0
8 2 9 1 0
8 2 10 0 8
8 2 11 1 0
8 2 12 1 0
8 2 13 1 32
8 3 2 1 106
8 3 5 1 76
8 3 6 1 8
8 3 7 1 8
8 3 8 1 10
8 3 9 1 42
8 3 11 1 72
8 3 12 1 8
8 3 13 1 42
9 0 2 0 80
9 0 3 1 16
9 0 4 1 16
9 0 5 1 16
9 0 6 1 16
9 0 7 1 16
9 0 8 0 16
9 0 9 0 16
9 0 10 1 16
9 0 11 1 16
9 0 12 1 16
9 0 13 1 48
9 0 14 0 126
9 1 2 0 64
9 1 3 1 0
9 1 4 1 0
9 1 5 1 0
9 1 6 1 0
9 1 7 1 0
9 1 8 0 0
9 1 9 0 0
9 1 10 1 0
9 1 11 1 0
9 1 12 1 0
9 1 13 1 0
9 1 14 0 58
9 2 2 0 72
9 2 3 1 8
9 2 4 1 0
9 2 5 1 0
9 2 6 1 0
9 2 7 1 0
9 2 8 0 8
9 2 9 0 8
9 2 10 1 8
9 2 11 1 0
9 2 12 1 0
9 2 13 1 42
9 3 4 1 76
9 3 5 1 8
9 3 6 1 10
9 3 7 1 42
9 3 11 1 72
9 3 12 1 42
10 0 2 1 80
10 0 3 1 16
10 0 4 1 16
10 0 5 1 16
10 0 6 0 16
10 0 7 0 16
10 0 8 0 16
10 0 9 1 16
10 0 10 1 16
10 0 11 1 16
10 0 12 1 16
10 0 13 0 50
10 1 2 1 64
10 1 3 1 0
10 1 4 1 0
10 1 5 1 0
10 1 6 0 0
10 1 7 0 0
10 1 8 0 0
10 1 9 1 0
10 1 10 1 0
10 1 11 1 0
10 1 12 1 0
10 1 13 0 42
10 2 2 1 72
10 2 3 1 0
10 2 4 1 0
10 2 5 1 0
10 2 6 0 8
10 2 7 0 8
10 2 8 0 8
10 2 9 1 8
10 2 10 1 0
10 2 11 1 0
10 2 12 1 42
10 3 2 1 126
10 3 3 1 76
10 3 4 1 8
10 3 5 1 42
10 3 10 1 76
10 3 11 1 42
11 0 2 1 82
11 0 3 1 16
11 0 4 1 16
11 0 5 0 16
11 0 6 0 16
11 0 7 1 16
11 0 8 1 16
11 0 9 1 16
11 0 10 1 16
11 0 11 1 16
11 0 12 0 50
11 1 2 1 66
11 1 3 1 0
11 1 4 1 0
11 1 5 0 0
11 1 6 0 0
11 1 7 1 0
11 1 8 1 0
11 1 9 1 0
11 1 10 1 0
11 1 11 1 0
11 1 12 0 42
11 2 2 1 74
11 2 3 1 0
11 2 4 1 0
11 2 5 0 8
11 2 6 0 8
11 2 7 1 8
11 2 8 1 0
11 2 9 1 0
11 2 10 1 2
11 2 11 1 42
11 3 3 1 74
11 3 4 1 40
11 3 8 1 76
11 3 9 1 14
11 3 10 1 42
12 0 3 1 82
12 0 4 1 18
12 0 5 0 18
12 0 6 1 18
12 0 7 1 18
12 0 8 1 18
12 0 9 1 18
12 0 10 0 18
12 0 11 0 50
12 1 3 1 66
12 1 4 1 0
12 1 5 0 0
12 1 6 1 0
12 1 7 1 0
12 1 8 1 0
12 1 9 1 0
12 1 10 0 10
12 1 11 0 42
12 2 3 1 74
12 2 4 1 0
12 2 5 0 8
12 2 6 1 8
12 2 7 1 0
12 2 8 1 2
12 2 9 1 42
12 3 4 1 106
12 3 7 1 78
12 3 8 1 42
13 1 4 1 82
13 1 5 1 18
13 1 6 0 18
13 1 7 0 18
13 1 8 0 26
13 1 9 0 58
13 2 4 1 74
13 2 5 1 10
13 2 6 0 10
13 2 7 0 42
13 3 5 1 126
